Workbook

Sheet Final
A1: SKU | B1: Description | C1: Collection | D1: Vendor Number | E1: From Ilsy | F1: Manual by Vendor | G1: Gartman Default | H1: Shipping Days | I1: FINAL | J1: SF per Pallet | K1: Pallets per Container
A2: ABBO1027 | B2: =IFERROR(VLOOKUP(A2,'From Ilsy'!$A$2:$C$1406,3,FALSE),"") | C2: =IFERROR(VLOOKUP(A2,'From Ilsy'!$A$2:$B$1406,2,FALSE),"") | D2: 216 | E2: =IFERROR(VLOOKUP(A2,'From Ilsy'!$A$2:$D$1406,4,FALSE),999999) -> 999999 | F2: =IF(E2=999999,VLOOKUP(D2,'Manual by Vendor'!$A$2:$C$295,3,FALSE),E2) -> 84 | G2: =VLOOKUP(A2,Query2[[00001]:[IMLT]],2,FALSE) -> 14 | I2: =IF(E2=999999,IF(F2=999999,G2,F2),E2) -> 84
A3: ABBO1028 | B3: =IFERROR(VLOOKUP(A3,'From Ilsy'!$A$2:$C$1406,3,FALSE),"") | C3: =IFERROR(VLOOKUP(A3,'From Ilsy'!$A$2:$B$1406,2,FALSE),"") | D3: 216 | E3: =IFERROR(VLOOKUP(A3,'From Ilsy'!$A$2:$D$1406,4,FALSE),999999) -> 999999 | F3: =IF(E3=999999,VLOOKUP(D3,'Manual by Vendor'!$A$2:$C$295,3,FALSE),E3) -> 84 | G3: =VLOOKUP(A3,Query2[[00001]:[IMLT]],2,FALSE) -> 36 | I3: =IF(E3=999999,IF(F3=999999,G3,F3),E3) -> 84
A4: ABGS88561 | B4: =IFERROR(VLOOKUP(A4,'From Ilsy'!$A$2:$C$1406,3,FALSE),"") | C4: =IFERROR(VLOOKUP(A4,'From Ilsy'!$A$2:$B$1406,2,FALSE),"") | D4: 3 | E4: =IFERROR(VLOOKUP(A4,'From Ilsy'!$A$2:$D$1406,4,FALSE),999999) -> 999999 | F4: =IF(E4=999999,VLOOKUP(D4,'Manual by Vendor'!$A$2:$C$295,3,FALSE),E4) -> 14 | G4: =VLOOKUP(A4,Query2[[00001]:[IMLT]],2,FALSE) -> 0 | I4: =IF(E4=999999,IF(F4=999999,G4,F4),E4) -> 14
A5: ABGS88562 | B5: =IFERROR(VLOOKUP(A5,'From Ilsy'!$A$2:$C$1406,3,FALSE),"") | C5: =IFERROR(VLOOKUP(A5,'From Ilsy'!$A$2:$B$1406,2,FALSE),"") | D5: 3 | E5: =IFERROR(VLOOKUP(A5,'From Ilsy'!$A$2:$D$1406,4,FALSE),999999) -> 999999 | F5: =IF(E5=999999,VLOOKUP(D5,'Manual by Vendor'!$A$2:$C$295,3,FALSE),E5) -> 14 | G5: =VLOOKUP(A5,Query2[[00001]:[IMLT]],2,FALSE) -> 7 | I5: =IF(E5=999999,IF(F5=999999,G5,F5),E5) -> 14
A6: ABGS88638 | B6: =IFERROR(VLOOKUP(A6,'From Ilsy'!$A$2:$C$1406,3,FALSE),"") | C6: =IFERROR(VLOOKUP(A6,'From Ilsy'!$A$2:$B$1406,2,FALSE),"") | D6: 3 | E6: =IFERROR(VLOOKUP(A6,'From Ilsy'!$A$2:$D$1406,4,FALSE),999999) -> 999999 | F6: =IF(E6=999999,VLOOKUP(D6,'Manual by Vendor'!$A$2:$C$295,3,FALSE),E6) -> 14 | G6: =VLOOKUP(A6,Query2[[00001]:[IMLT]],2,FALSE) -> 21 | I6: =IF(E6=999999,IF(F6=999999,G6,F6),E6) -> 14
A7: ABGS88639 | B7: =IFERROR(VLOOKUP(A7,'From Ilsy'!$A$2:$C$1406,3,FALSE),"") | C7: =IFERROR(VLOOKUP(A7,'From Ilsy'!$A$2:$B$1406,2,FALSE),"") | D7: 3 | E7: =IFERROR(VLOOKUP(A7,'From Ilsy'!$A$2:$D$1406,4,FALSE),999999) -> 999999 | F7: =IF(E7=999999,VLOOKUP(D7,'Manual by Vendor'!$A$2:$C$295,3,FALSE),E7) -> 14 | G7: =VLOOKUP(A7,Query2[[00001]:[IMLT]],2,FALSE) -> 18 | I7: =IF(E7=999999,IF(F7=999999,G7,F7),E7) -> 14
A8: ACBUP809 | B8: =IFERROR(VLOOKUP(A8,'From Ilsy'!$A$2:$C$1406,3,FALSE),"") | C8: =IFERROR(VLOOKUP(A8,'From Ilsy'!$A$2:$B$1406,2,FALSE),"") | D8: 272 | E8: =IFERROR(VLOOKUP(A8,'From Ilsy'!$A$2:$D$1406,4,FALSE),999999) -> 999999 | F8: =IF(E8=999999,VLOOKUP(D8,'Manual by Vendor'!$A$2:$C$295,3,FALSE),E8) -> 14 | G8: =VLOOKUP(A8,Query2[[00001]:[IMLT]],2,FALSE) -> 25 | I8: =IF(E8=999999,IF(F8=999999,G8,F8),E8) -> 14
A9: ACBU13000U | B9: =IFERROR(VLOOKUP(A9,'From Ilsy'!$A$2:$C$1406,3,FALSE),"") | C9: =IFERROR(VLOOKUP(A9,'From Ilsy'!$A$2:$B$1406,2,FALSE),"") | D9: 3 | E9: =IFERROR(VLOOKUP(A9,'From Ilsy'!$A$2:$D$1406,4,FALSE),999999) -> 999999 | F9: =IF(E9=999999,VLOOKUP(D9,'Manual by Vendor'!$A$2:$C$295,3,FALSE),E9) -> 14 | G9: =VLOOKUP(A9,Query2[[00001]:[IMLT]],2,FALSE) -> 0 | I9: =IF(E9=999999,IF(F9=999999,G9,F9),E9) -> 14
A10: ACBU16000U | B10: =IFERROR(VLOOKUP(A10,'From Ilsy'!$A$2:$C$1406,3,FALSE),"") | C10: =IFERROR(VLOOKUP(A10,'From Ilsy'!$A$2:$B$1406,2,FALSE),"") | D10: 1677 | E10: =IFERROR(VLOOKUP(A10,'From Ilsy'!$A$2:$D$1406,4,FALSE),999999) -> 999999 | F10: =IF(E10=999999,VLOOKUP(D10,'Manual by Vendor'!$A$2:$C$295,3,FALSE),E10) -> 14 | G10: =VLOOKUP(A10,Query2[[00001]:[IMLT]],2,FALSE) -> 0 | I10: =IF(E10=999999,IF(F10=999999,G10,F10),E10) -> 14
A11: ACCVPBPVO7M | B11: =IFERROR(VLOOKUP(A11,'From Ilsy'!$A$2:$C$1406,3,FALSE),"") | C11: =IFERROR(VLOOKUP(A11,'From Ilsy'!$A$2:$B$1406,2,FALSE),"") | D11: 0 | E11: =IFERROR(VLOOKUP(A11,'From Ilsy'!$A$2:$D$1406,4,FALSE),999999) -> 999999 | F11: =IF(E11=999999,VLOOKUP(D11,'Manual by Vendor'!$A$2:$C$295,3,FALSE),E11) -> 999999 | G11: =VLOOKUP(A11,Query2[[00001]:[IMLT]],2,FALSE) -> 0 | I11: =IF(E11=999999,IF(F11=999999,G11,F11),E11) -> 0
A12: ACCVPBPVO8 | B12: =IFERROR(VLOOKUP(A12,'From Ilsy'!$A$2:$C$1406,3,FALSE),"") | C12: =IFERROR(VLOOKUP(A12,'From Ilsy'!$A$2:$B$1406,2,FALSE),"") | D12: 0 | E12: =IFERROR(VLOOKUP(A12,'From Ilsy'!$A$2:$D$1406,4,FALSE),999999) -> 999999 | F12: =IF(E12=999999,VLOOKUP(D12,'Manual by Vendor'!$A$2:$C$295,3,FALSE),E12) -> 999999 | G12: =VLOOKUP(A12,Query2[[00001]:[IMLT]],2,FALSE) -> 0 | I12: =IF(E12=999999,IF(F12=999999,G12,F12),E12) -> 0
A13: ACCV100713 | B13: =IFERROR(VLOOKUP(A13,'From Ilsy'!$A$2:$C$1406,3,FALSE),"") | C13: =IFERROR(VLOOKUP(A13,'From Ilsy'!$A$2:$B$1406,2,FALSE),"") | D13: 608 | E13: =IFERROR(VLOOKUP(A13,'From Ilsy'!$A$2:$D$1406,4,FALSE),999999) -> 999999 | F13: =IF(E13=999999,VLOOKUP(D13,'Manual by Vendor'!$A$2:$C$295,3,FALSE),E13) -> 999999 | G13: =VLOOKUP(A13,Query2[[00001]:[IMLT]],2,FALSE) -> 0 | I13: =IF(E13=999999,IF(F13=999999,G13,F13),E13) -> 0
... A260: CLST47804 | B260: =IFERROR(VLOOKUP(A260,'From Ilsy'!$A$2:$C$1406,3,FALSE),"") | C260: =IFERROR(VLOOKUP(A260,'From Ilsy'!$A$2:$B$1406,2,FALSE),"") | D260: 1929 | E260: =IFERROR(VLOOKUP(A260,'From Ilsy'!$A$2:$D$1406,4,FALSE),999999) -> 999999 | F260: =IF(E260=999999,VLOOKUP(D260,'Manual by Vendor'!$A$2:$C$295,3,FALSE),E260) -> 21 | G260: =VLOOKUP(A260,Query2[[00001]:[IMLT]],2,FALSE) -> 0 | I260: =IF(E260=999999,IF(F260=999999,G260,F260),E260) -> 21
A261: CWO314 SG | B261: =IFERROR(VLOOKUP(A261,'From Ilsy'!$A$2:$C$1406,3,FALSE),"") | C261: =IFERROR(VLOOKUP(A261,'From Ilsy'!$A$2:$B$1406,2,FALSE),"") | D261: 999999 | E261: =IFERROR(VLOOKUP(A261,'From Ilsy'!$A$2:$D$1406,4,FALSE),999999) -> 999999 | F261: 999999 | G261: =VLOOKUP(A261,Query2[[00001]:[IMLT]],2,FALSE) -> #N/A | I261: =IF(E261=999999,IF(F261=999999,G261,F261),E261) -> #N/A
A262: CWPO105F | B262: =IFERROR(VLOOKUP(A262,'From Ilsy'!$A$2:$C$1406,3,FALSE),"") | C262: =IFERROR(VLOOKUP(A262,'From Ilsy'!$A$2:$B$1406,2,FALSE),"") | D262: 359 | E262: =IFERROR(VLOOKUP(A262,'From Ilsy'!$A$2:$D$1406,4,FALSE),999999) -> 999999 | F262: =IF(E262=999999,VLOOKUP(D262,'Manual by Vendor'!$A$2:$C$295,3,FALSE),E262) -> 999999 | G262: =VLOOKUP(A262,Query2[[00001]:[IMLT]],2,FALSE) -> 2 | I262: =IF(E262=999999,IF(F262=999999,G262,F262),E262) -> 2
A263: CWSO035 HS | B263: =IFERROR(VLOOKUP(A263,'From Ilsy'!$A$2:$C$1406,3,FALSE),"") | C263: =IFERROR(VLOOKUP(A263,'From Ilsy'!$A$2:$B$1406,2,FALSE),"") | D263: 359 | E263: =IFERROR(VLOOKUP(A263,'From Ilsy'!$A$2:$D$1406,4,FALSE),999999) -> 999999 | F263: =IF(E263=999999,VLOOKUP(D263,'Manual by Vendor'!$A$2:$C$295,3,FALSE),E263) -> 999999 | G263: =VLOOKUP(A263,Query2[[00001]:[IMLT]],2,FALSE) -> 2 | I263: =IF(E263=999999,IF(F263=999999,G263,F263),E263) -> 2
A264: DM3M8210 | B264: =IFERROR(VLOOKUP(A264,'From Ilsy'!$A$2:$C$1406,3,FALSE),"") | C264: =IFERROR(VLOOKUP(A264,'From Ilsy'!$A$2:$B$1406,2,FALSE),"") | D264: 3 | E264: =IFERROR(VLOOKUP(A264,'From Ilsy'!$A$2:$D$1406,4,FALSE),999999) -> 999999 | F264: =IF(E264=999999,VLOOKUP(D264,'Manual by Vendor'!$A$2:$C$295,3,FALSE),E264) -> 14 | G264: =VLOOKUP(A264,Query2[[00001]:[IMLT]],2,FALSE) -> 6 | I264: =IF(E264=999999,IF(F264=999999,G264,F264),E264) -> 14
A265: DM3M8500 | B265: =IFERROR(VLOOKUP(A265,'From Ilsy'!$A$2:$C$1406,3,FALSE),"") | C265: =IFERROR(VLOOKUP(A265,'From Ilsy'!$A$2:$B$1406,2,FALSE),"") | D265: 3 | E265: =IFERROR(VLOOKUP(A265,'From Ilsy'!$A$2:$D$1406,4,FALSE),999999) -> 999999 | F265: =IF(E265=999999,VLOOKUP(D265,'Manual by Vendor'!$A$2:$C$295,3,FALSE),E265) -> 14 | G265: =VLOOKUP(A265,Query2[[00001]:[IMLT]],2,FALSE) -> 3 | I265: =IF(E265=999999,IF(F265=999999,G265,F265),E265) -> 14
A266: DM3M8511 | B266: =IFERROR(VLOOKUP(A266,'From Ilsy'!$A$2:$C$1406,3,FALSE),"") | C266: =IFERROR(VLOOKUP(A266,'From Ilsy'!$A$2:$B$1406,2,FALSE),"") | D266: 3 | E266: =IFERROR(VLOOKUP(A266,'From Ilsy'!$A$2:$D$1406,4,FALSE),999999) -> 999999 | F266: =IF(E266=999999,VLOOKUP(D266,'Manual by Vendor'!$A$2:$C$295,3,FALSE),E266) -> 14 | G266: =VLOOKUP(A266,Query2[[00001]:[IMLT]],2,FALSE) -> 0 | I266: =IF(E266=999999,IF(F266=999999,G266,F266),E266) -> 14
A267: DP3M12100 | B267: =IFERROR(VLOOKUP(A267,'From Ilsy'!$A$2:$C$1406,3,FALSE),"") | C267: =IFERROR(VLOOKUP(A267,'From Ilsy'!$A$2:$B$1406,2,FALSE),"") | D267: 3 | E267: =IFERROR(VLOOKUP(A267,'From Ilsy'!$A$2:$D$1406,4,FALSE),999999) -> 999999 | F267: =IF(E267=999999,VLOOKUP(D267,'Manual by Vendor'!$A$2:$C$295,3,FALSE),E267) -> 14 | G267: =VLOOKUP(A267,Query2[[00001]:[IMLT]],2,FALSE) -> 18 | I267: =IF(E267=999999,IF(F267=999999,G267,F267),E267) -> 14
A268: DP3M1212 | B268: =IFERROR(VLOOKUP(A268,'From Ilsy'!$A$2:$C$1406,3,FALSE),"") | C268: =IFERROR(VLOOKUP(A268,'From Ilsy'!$A$2:$B$1406,2,FALSE),"") | D268: 3 | E268: =IFERROR(VLOOKUP(A268,'From Ilsy'!$A$2:$D$1406,4,FALSE),999999) -> 999999 | F268: =IF(E268=999999,VLOOKUP(D268,'Manual by Vendor'!$A$2:$C$295,3,FALSE),E268) -> 14 | G268: =VLOOKUP(A268,Query2[[00001]:[IMLT]],2,FALSE) -> 14 | I268: =IF(E268=999999,IF(F268=999999,G268,F268),E268) -> 14
A269: DP3M12120 | B269: =IFERROR(VLOOKUP(A269,'From Ilsy'!$A$2:$C$1406,3,FALSE),"") | C269: =IFERROR(VLOOKUP(A269,'From Ilsy'!$A$2:$B$1406,2,FALSE),"") | D269: 3 | E269: =IFERROR(VLOOKUP(A269,'From Ilsy'!$A$2:$D$1406,4,FALSE),999999) -> 999999 | F269: =IF(E269=999999,VLOOKUP(D269,'Manual by Vendor'!$A$2:$C$295,3,FALSE),E269) -> 14 | G269: =VLOOKUP(A269,Query2[[00001]:[IMLT]],2,FALSE) -> 28 | I269: =IF(E269=999999,IF(F269=999999,G269,F269),E269) -> 14
A270: DP3M12150 | B270: =IFERROR(VLOOKUP(A270,'From Ilsy'!$A$2:$C$1406,3,FALSE),"") | C270: =IFERROR(VLOOKUP(A270,'From Ilsy'!$A$2:$B$1406,2,FALSE),"") | D270: 3 | E270: =IFERROR(VLOOKUP(A270,'From Ilsy'!$A$2:$D$1406,4,FALSE),999999) -> 999999 | F270: =IF(E270=999999,VLOOKUP(D270,'Manual by Vendor'!$A$2:$C$295,3,FALSE),E270) -> 14 | G270: =VLOOKUP(A270,Query2[[00001]:[IMLT]],2,FALSE) -> 9 | I270: =IF(E270=999999,IF(F270=999999,G270,F270),E270) -> 14
A271: DP3M1216 | B271: =IFERROR(VLOOKUP(A271,'From Ilsy'!$A$2:$C$1406,3,FALSE),"") | C271: =IFERROR(VLOOKUP(A271,'From Ilsy'!$A$2:$B$1406,2,FALSE),"") | D271: 3 | E271: =IFERROR(VLOOKUP(A271,'From Ilsy'!$A$2:$D$1406,4,FALSE),999999) -> 999999 | F271: =IF(E271=999999,VLOOKUP(D271,'Manual by Vendor'!$A$2:$C$295,3,FALSE),E271) -> 14 | G271: =VLOOKUP(A271,Query2[[00001]:[IMLT]],2,FALSE) -> 29 | I271: =IF(E271=999999,IF(F271=999999,G271,F271),E271) -> 14
A272: DP3M1230 | B272: =IFERROR(VLOOKUP(A272,'From Ilsy'!$A$2:$C$1406,3,FALSE),"") | C272: =IFERROR(VLOOKUP(A272,'From Ilsy'!$A$2:$B$1406,2,FALSE),"") | D272: 3 | E272: =IFERROR(VLOOKUP(A272,'From Ilsy'!$A$2:$D$1406,4,FALSE),999999) -> 999999 | F272: =IF(E272=999999,VLOOKUP(D272,'Manual by Vendor'!$A$2:$C$295,3,FALSE),E272) -> 14 | G272: =VLOOKUP(A272,Query2[[00001]:[IMLT]],2,FALSE) -> 32 | I272: =IF(E272=999999,IF(F272=999999,G272,F272),E272) -> 14
A273: DP3M1236 | B273: =IFERROR(VLOOKUP(A273,'From Ilsy'!$A$2:$C$1406,3,FALSE),"") | C273: =IFERROR(VLOOKUP(A273,'From Ilsy'!$A$2:$B$1406,2,FALSE),"") | D273: 3 | E273: =IFERROR(VLOOKUP(A273,'From Ilsy'!$A$2:$D$1406,4,FALSE),999999) -> 999999 | F273: =IF(E273=999999,VLOOKUP(D273,'Manual by Vendor'!$A$2:$C$295,3,FALSE),E273) -> 14 | G273: =VLOOKUP(A273,Query2[[00001]:[IMLT]],2,FALSE) -> 6 | I273: =IF(E273=999999,IF(F273=999999,G273,F273),E273) -> 14
... A765: GCRACK | B765: =IFERROR(VLOOKUP(A765,'From Ilsy'!$A$2:$C$1406,3,FALSE),"") | C765: =IFERROR(VLOOKUP(A765,'From Ilsy'!$A$2:$B$1406,2,FALSE),"") | D765: 0 | E765: =IFERROR(VLOOKUP(A765,'From Ilsy'!$A$2:$D$1406,4,FALSE),999999) -> 999999 | F765: =IF(E765=999999,VLOOKUP(D765,'Manual by Vendor'!$A$2:$C$295,3,FALSE),E765) -> 999999 | G765: =VLOOKUP(A765,Query2[[00001]:[IMLT]],2,FALSE) -> 25 | I765: =IF(E765=999999,IF(F765=999999,G765,F765),E765) -> 25
A766: GCRACK B | B766: =IFERROR(VLOOKUP(A766,'From Ilsy'!$A$2:$C$1406,3,FALSE),"") | C766: =IFERROR(VLOOKUP(A766,'From Ilsy'!$A$2:$B$1406,2,FALSE),"") | D766: 999999 | E766: =IFERROR(VLOOKUP(A766,'From Ilsy'!$A$2:$D$1406,4,FALSE),999999) -> 999999 | F766: 999999 | G766: =VLOOKUP(A766,Query2[[00001]:[IMLT]],2,FALSE) -> #N/A | I766: =IF(E766=999999,IF(F766=999999,G766,F766),E766) -> #N/A
A767: GCRACK HB | B767: =IFERROR(VLOOKUP(A767,'From Ilsy'!$A$2:$C$1406,3,FALSE),"") | C767: =IFERROR(VLOOKUP(A767,'From Ilsy'!$A$2:$B$1406,2,FALSE),"") | D767: 999999 | E767: =IFERROR(VLOOKUP(A767,'From Ilsy'!$A$2:$D$1406,4,FALSE),999999) -> 999999 | F767: 999999 | G767: =VLOOKUP(A767,Query2[[00001]:[IMLT]],2,FALSE) -> #N/A | I767: =IF(E767=999999,IF(F767=999999,G767,F767),E767) -> #N/A
A768: GCREBN00 | B768: =IFERROR(VLOOKUP(A768,'From Ilsy'!$A$2:$C$1406,3,FALSE),"") | C768: =IFERROR(VLOOKUP(A768,'From Ilsy'!$A$2:$B$1406,2,FALSE),"") | D768: 0 | E768: =IFERROR(VLOOKUP(A768,'From Ilsy'!$A$2:$D$1406,4,FALSE),999999) -> 999999 | F768: =IF(E768=999999,VLOOKUP(D768,'Manual by Vendor'!$A$2:$C$295,3,FALSE),E768) -> 999999 | G768: =VLOOKUP(A768,Query2[[00001]:[IMLT]],2,FALSE) -> 0 | I768: =IF(E768=999999,IF(F768=999999,G768,F768),E768) -> 0
A769: GCRECH03 | B769: =IFERROR(VLOOKUP(A769,'From Ilsy'!$A$2:$C$1406,3,FALSE),"") | C769: =IFERROR(VLOOKUP(A769,'From Ilsy'!$A$2:$B$1406,2,FALSE),"") | D769: 1611 | E769: =IFERROR(VLOOKUP(A769,'From Ilsy'!$A$2:$D$1406,4,FALSE),999999) -> 999999 | F769: =IF(E769=999999,VLOOKUP(D769,'Manual by Vendor'!$A$2:$C$295,3,FALSE),E769) -> 8 | G769: =VLOOKUP(A769,Query2[[00001]:[IMLT]],2,FALSE) -> 80 | I769: =IF(E769=999999,IF(F769=999999,G769,F769),E769) -> 8
A770: GCRECH05 | B770: =IFERROR(VLOOKUP(A770,'From Ilsy'!$A$2:$C$1406,3,FALSE),"") | C770: =IFERROR(VLOOKUP(A770,'From Ilsy'!$A$2:$B$1406,2,FALSE),"") | D770: 1611 | E770: =IFERROR(VLOOKUP(A770,'From Ilsy'!$A$2:$D$1406,4,FALSE),999999) -> 999999 | F770: =IF(E770=999999,VLOOKUP(D770,'Manual by Vendor'!$A$2:$C$295,3,FALSE),E770) -> 8 | G770: =VLOOKUP(A770,Query2[[00001]:[IMLT]],2,FALSE) -> 3 | I770: =IF(E770=999999,IF(F770=999999,G770,F770),E770) -> 8
A771: GCRECH11 | B771: =IFERROR(VLOOKUP(A771,'From Ilsy'!$A$2:$C$1406,3,FALSE),"") | C771: =IFERROR(VLOOKUP(A771,'From Ilsy'!$A$2:$B$1406,2,FALSE),"") | D771: 1611 | E771: =IFERROR(VLOOKUP(A771,'From Ilsy'!$A$2:$D$1406,4,FALSE),999999) -> 999999 | F771: =IF(E771=999999,VLOOKUP(D771,'Manual by Vendor'!$A$2:$C$295,3,FALSE),E771) -> 8 | G771: =VLOOKUP(A771,Query2[[00001]:[IMLT]],2,FALSE) -> 80 | I771: =IF(E771=999999,IF(F771=999999,G771,F771),E771) -> 8
A772: GCRECH18 | B772: =IFERROR(VLOOKUP(A772,'From Ilsy'!$A$2:$C$1406,3,FALSE),"") | C772: =IFERROR(VLOOKUP(A772,'From Ilsy'!$A$2:$B$1406,2,FALSE),"") | D772: 1611 | E772: =IFERROR(VLOOKUP(A772,'From Ilsy'!$A$2:$D$1406,4,FALSE),999999) -> 999999 | F772: =IF(E772=999999,VLOOKUP(D772,'Manual by Vendor'!$A$2:$C$295,3,FALSE),E772) -> 8 | G772: =VLOOKUP(A772,Query2[[00001]:[IMLT]],2,FALSE) -> 0 | I772: =IF(E772=999999,IF(F772=999999,G772,F772),E772) -> 8
A773: GCRECH24 | B773: =IFERROR(VLOOKUP(A773,'From Ilsy'!$A$2:$C$1406,3,FALSE),"") | C773: =IFERROR(VLOOKUP(A773,'From Ilsy'!$A$2:$B$1406,2,FALSE),"") | D773: 1611 | E773: =IFERROR(VLOOKUP(A773,'From Ilsy'!$A$2:$D$1406,4,FALSE),999999) -> 999999 | F773: =IF(E773=999999,VLOOKUP(D773,'Manual by Vendor'!$A$2:$C$295,3,FALSE),E773) -> 8 | G773: =VLOOKUP(A773,Query2[[00001]:[IMLT]],2,FALSE) -> 6 | I773: =IF(E773=999999,IF(F773=999999,G773,F773),E773) -> 8
A774: GCRECH30 | B774: =IFERROR(VLOOKUP(A774,'From Ilsy'!$A$2:$C$1406,3,FALSE),"") | C774: =IFERROR(VLOOKUP(A774,'From Ilsy'!$A$2:$B$1406,2,FALSE),"") | D774: 1611 | E774: =IFERROR(VLOOKUP(A774,'From Ilsy'!$A$2:$D$1406,4,FALSE),999999) -> 999999 | F774: =IF(E774=999999,VLOOKUP(D774,'Manual by Vendor'!$A$2:$C$295,3,FALSE),E774) -> 8 | G774: =VLOOKUP(A774,Query2[[00001]:[IMLT]],2,FALSE) -> 0 | I774: =IF(E774=999999,IF(F774=999999,G774,F774),E774) -> 8
A775: GCRECH38 | B775: =IFERROR(VLOOKUP(A775,'From Ilsy'!$A$2:$C$1406,3,FALSE),"") | C775: =IFERROR(VLOOKUP(A775,'From Ilsy'!$A$2:$B$1406,2,FALSE),"") | D775: 1611 | E775: =IFERROR(VLOOKUP(A775,'From Ilsy'!$A$2:$D$1406,4,FALSE),999999) -> 999999 | F775: =IF(E775=999999,VLOOKUP(D775,'Manual by Vendor'!$A$2:$C$295,3,FALSE),E775) -> 8 | G775: =VLOOKUP(A775,Query2[[00001]:[IMLT]],2,FALSE) -> 13 | I775: =IF(E775=999999,IF(F775=999999,G775,F775),E775) -> 8
A776: GCRECH99 | B776: =IFERROR(VLOOKUP(A776,'From Ilsy'!$A$2:$C$1406,3,FALSE),"") | C776: =IFERROR(VLOOKUP(A776,'From Ilsy'!$A$2:$B$1406,2,FALSE),"") | D776: 1611 | E776: =IFERROR(VLOOKUP(A776,'From Ilsy'!$A$2:$D$1406,4,FALSE),999999) -> 999999 | F776: =IF(E776=999999,VLOOKUP(D776,'Manual by Vendor'!$A$2:$C$295,3,FALSE),E776) -> 8 | G776: =VLOOKUP(A776,Query2[[00001]:[IMLT]],2,FALSE) -> 9 | I776: =IF(E776=999999,IF(F776=999999,G776,F776),E776) -> 8
A777: GCREHH12 | B777: =IFERROR(VLOOKUP(A777,'From Ilsy'!$A$2:$C$1406,3,FALSE),"") | C777: =IFERROR(VLOOKUP(A777,'From Ilsy'!$A$2:$B$1406,2,FALSE),"") | D777: 2401 | E777: =IFERROR(VLOOKUP(A777,'From Ilsy'!$A$2:$D$1406,4,FALSE),999999) -> 999999 | F777: =IF(E777=999999,VLOOKUP(D777,'Manual by Vendor'!$A$2:$C$295,3,FALSE),E777) -> 999999 | G777: =VLOOKUP(A777,Query2[[00001]:[IMLT]],2,FALSE) -> 0 | I777: =IF(E777=999999,IF(F777=999999,G777,F777),E777) -> 0
...

Sheet Sheet1
A1: SKU | B1: LABEL
A2: RH112QOSNB-15 | B2: REGULAR UNFINISHED
A3: RH112QOSNB-24 | B3: REGULAR UNFINISHED
A4: RH112QRSNB-24 | B4: REGULAR UNFINISHED
A5: RH112SOSNB | B5: REGULAR UNFINISHED
A6: RH112SOSNB-15 | B6: REGULAR UNFINISHED
A7: RH112SOSNB-24 | B7: REGULAR UNFINISHED
A8: RH112SRSNB-15 | B8: REGULAR UNFINISHED
A9: RH112SRSNB-24 | B9: REGULAR UNFINISHED
A10: RH21OSNB | B10: REGULAR UNFINISHED
A11: RH21RS | B11: REGULAR UNFINISHED
A12: RH2QOSNB | B12: REGULAR UNFINISHED
... A46: RT2SRSNB-24 | B46: REGULAR UNFINISHED

Sheet From Ilsy
A1: IMXITM | B1: IMCOLLECT | C1: IMDESC | D1: Lead Time
A2: GCBSWH38 | B2: GARRISON DELUXE | C2: 1/2" BASESHOE NATURAL | D2: 999999
A3: GCBSHH38 | B3: GARRIOSON PLUS | C3: 1/2" BASESHOE NATURAL | D3: 999999
A4: GFALO7503 | B4: ALLORA | C4: EURO OAK 7.5" DOMA | D4: 120
A5: GFALO7501 | B5: ALLORA | C5: EURO OAK 7.5" ALTURA | D5: 120
A6: GFALO7502 | B6: ALLORA | C6: EURO OAK 7.5" ARIA | D6: 120
A7: GFALO7504 | B7: ALLORA | C7: EURO OAK 7.5" LUNA | D7: 120
A8: GFALO7506 | B8: ALLORA | C8: EURO OAK 7.5" STRADA | D8: 120
A9: GFALO7505 | B9: ALLORA | C9: EURO OAK 7.5" SELLA | D9: 120
A10: GFALO7507 | B10: ALLORA | C10: EURO OAK 7.5" VENTASSO | D10: 120
A11: GFALO7508 | B11: ALLORA | C11: EURO OAK 7.5" VOLTO | D11: 120
A12: GFALO7503S | B12: ALLORA | C12: EURO OAK 7.5" DOMA SELECT | D12: 120
A13: GFALO7504S | B13: ALLORA | C13: EURO OAK 7.5" LUNA SELECT | D13: 120
... A1406: LAMCDN8713 | B1406: MEGACLIC | C1406: 10MM 9.37" X 60" DAWSON | D1406: 7

Sheet Manual by Vendor
A1: Vendor Number | B1: Vendor Name | C1: Lead Time
A2: 0 | C2: 999999
A3: 1 | C3: 999999
A4: 2 | C4: 999999
A5: 3 | C5: 14
A6: 31 | C6: 31
A7: 101 | C7: 7
A8: 112 | C8: 21
A9: 113 | C9: 999999
A10: 114 | C10: 999999
A11: 115 | C11: 999999
A12: 116 | C12: 7
A13: 119 | C13: 21
... A295: 10016 | C295: 999999

Sheet Gartman Default
A1: 00001 | B1: IMLT | C1: IMVEND
A2: ABBO1027 | B2: 14 | C2: 216
A3: ABBO1028 | B3: 36 | C3: 216
A4: ABGS88561 | B4: 0 | C4: 3
A5: ABGS88562 | B5: 7 | C5: 3
A6: ABGS88638 | B6: 21 | C6: 3
A7: ABGS88639 | B7: 18 | C7: 3
A8: ACBUP809 | B8: 25 | C8: 272
A9: ACBU13000U | B9: 0 | C9: 3
A10: ACBU16000U | B10: 0 | C10: 1677
A11: ACCVPBPVO7M | B11: 0 | C11: 0
A12: ACCVPBPVO8 | B12: 0 | C12: 0
A13: ACCV100713 | B13: 0 | C13: 608
... A16839: ADSI749711 | B16839: 0 | C16839: 422
