Workbook

Sheet Margins
A1: ITEM NUMBER | B1: SALE PRICE | C1: MARGIN
A2: RQ214SOSSP | B2: 4.99 | C2: 0.2096
A3: RQ214SRSSP | B3: 3.69 | C3: 0.25787966
A4: RQ314SOSSP | B4: 4.99 | C4: 0.23246493
A5: RQ314SRSSP | B5: 3.39 | C5: 0.27477476
A6: RH2SOSNB | B6: 5.09 | C6: 0.30157965
A7: RH2SOSNB-24 | B7: 4.39 | C7: 0.25968109
A8: RH2SRSNB | B8: 3.59 | C8: 0.36059678
A9: RH2SRS | B9: 3.59 | C9: 0.24739864
A10: RQ112SOSNB | B10: 6.69 | C10: 0.30179372
A11: RQ112SRSNB | B11: 5.09 | C11: 0.29842829
A12: RQ3SOB | B12: 5.89 | C12: 0.28539121
A13: RQ3SOS | B13: 5.89 | C13: 0.28287388
... A36: RQ5FMS | B36: 7.59 | C36: 0.25343222
A37: RQ5SOSD | B37: 0
A38: RQ5SRS | B38: 4.29 | C38: 0.3511043
A39: RQ314SDS | B39: 6.69 | C39: 0.25528663
A40: RT112SOS | B40: 5.49 | C40: 0.22586521
A41: RQ5SWS | B41: 9.69 | C41: 0.23511924
A42: RT112SRS | B42: 2.99 | C42: 0.21404682
A43: RT2SOSNB-24 | B43: 6.19 | C43: 0.26494346
A44: RT2SRSNB-24 | B44: 3.79 | C44: 0.22163588
A45: RH112QOSNB-15 | B45: 5.69 | C45: 0.036255557
A46: RH112QOSNB-24 | B46: 5.69 | C46: 0.30579965
A47: RH112QRSNB-15 | B47: 5.59
A48: RH112QRSNB-24 | B48: 5.59 | C48: 0.25760286
A49: RH112SOSNB | B49: 5.19 | C49: 0.21139554
A50: RH112SOSNB-15 | B50: 5.19 | C50: 0.30732177
A51: RH112SOSNB-24 | B51: 5.19 | C51: 0.37379576
A52: RH112SRSNB | B52: 4.09 | C52: 0.31246944
A53: RH112SRSNB-15 | B53: 4.09 | C53: 0.25794621
A54: RH112SRSNB-24 | B54: 4.09 | C54: 0.27139364
A55: RH2QOSNB | B55: 5.99 | C55: 0.55159882
A56: RH2QOSNB-20 | B56: 5.99 | C56: 0.21396772
A57: RH2QOSNB-24 | B57: 5.99 | C57: 0.28973503
A58: RH2QRSNB | B58: 4.89 | C58: 0.33231084
A59: RH2QRSNB-20 | B59: 4.89
A60: RH2QRSNB-24 | B60: 4.89 | C60: 0.28425358

Sheet Who Produces
A1: Item Number | B1: Description | C1: Thickness | D1: Width | E1: Species | F1: Grade/Cut | G1: Edge | H1: Bundles | I1: Indiana | J1: Dayspring | K1: Mullican | L1: Macon | M1: Anthony | N1: Orillia | O1: Lebanon | P1: Merrick | S1: FEED IN TOTALS
A2: DF512PI | B2: 1" X 6" IPE DECK FLOORING (RL) | C2: 1" | D2: 6" | E2: Ipe | H2: Random Length | J2: Dayspring | L2: Macon | M2: Anthony | S2: RH112QOSNB-15 | T2: ORILLIA
A3: DF512PIL | B3: 1" X 6" IPE DECK FLOORING (LL) | C3: 1" | D3: 6" | E3: Ipe | H3: Long Length | J3: Dayspring | L3: Macon | M3: Anthony | S3: RH112QOSNB-24 | T3: DAYSPRING
A4: RH112QOSNB-15 | B4: 1/2 x 1 1/2" R&Q W/O NESTED | C4: 1/2" | D4: 1-1/2" | E4: White Oak | F4: Rift & Quarter | H4: Nested | L4: Macon | N4: Orillia | S4: RH112QOSNB* | T4: TOTAL
A5: RH112QOSNB-24 | B5: 1/2 x 1 1/2" R&Q W/O NESTED | C5: 1/2" | D5: 1-1/2" | E5: White Oak | F5: Rift & Quarter | H5: Nested | J5: Dayspring | L5: Macon | S5: RH112QRSNB-15 | T5: ORILLIA
A6: RH112QRSNB-15 | B6: 1/2 x 1 1/2" R&Q R/O NESTED | C6: 1/2" | D6: 1-1/2" | E6: Red Oak | F6: Rift & Quarter | H6: Nested | L6: Macon | N6: Orillia | S6: RH112QRSNB-24 | T6: DAYSPRING
A7: RH112QRSNB-24 | B7: 1/2 x 1 1/2" R&Q R/O NESTED | C7: 1/2" | D7: 1-1/2" | E7: Red Oak | F7: Rift & Quarter | H7: Nested | J7: Dayspring | L7: Macon | S7: RH112QRSNB* | T7: TOTAL
A8: RH112SOSNB | B8: 1/2 x 1 1/2 SELECT W/O NESTED | C8: 1/2" | D8: 1-1/2" | E8: White Oak | F8: Select | H8: Nested | L8: Macon | O8: Lebanon | S8: RH2QOSNB | T8: LEBANON
A9: RH112SOSNB-15 | B9: 1/2 x 1-1/2" SELECT W/O NESTED | C9: 1/2" | D9: 1-1/2" | E9: White Oak | F9: Select | H9: Nested | L9: Macon | N9: Orillia | S9: RH2QOSNB-20 | T9: ORILLIA
A10: RH112SOSNB-24 | B10: 1/2 x 1 1/2" SELECT W/O NESTED | C10: 1/2" | D10: 1-1/2" | E10: White Oak | F10: Select | H10: Nested | J10: Dayspring | L10: Macon | S10: RH2QOSNB-24 | T10: DAYSPRING
A11: RH112SRSNB | B11: 1/2 x 1 1/2 SELECT R/O NESTED | C11: 1/2" | D11: 1-1/2" | E11: Red Oak | F11: Select | H11: Nested | L11: Macon | O11: Lebanon | S11: RH2QOSNB* | T11: TOTAL
A12: RH112SRSNB-15 | B12: 1/2 x 1-1/2" SELECT R/O NESTED | C12: 1/2" | D12: 1-1/2" | E12: Red Oak | F12: Select | H12: Nested | L12: Macon | N12: Orillia | S12: RH2QRSNB | T12: LEBANON
A13: RH112SRSNB-24 | B13: 1/2 x 1 1/2" SELECT R/O NESTED | C13: 1/2" | D13: 1-1/2" | E13: Red Oak | F13: Select | H13: Nested | J13: Dayspring | L13: Macon | S13: RH2QRSNB-20 | T13: ORILLIA
A14: RH2QOSNB | B14: 1/2 x 2" RIFT/OTR W/O NESTED | C14: 1/2" | D14: 2" | E14: White Oak | F14: Rift & Quarter | H14: Nested | L14: Macon | O14: Lebanon | S14: RH2QRSNB-24 | T14: DAYSPRING
A15: RH2QOSNB-20 | B15: 1/2 x 2" RIFT/OTR W/O NESTED | C15: 1/2" | D15: 2" | E15: White Oak | F15: Rift & Quarter | H15: Nested | L15: Macon | N15: Orillia | S15: RH2QRSNB* | T15: TOTAL
A16: RH2QOSNB-24 | B16: 1/2 x 2" RIFT/OTR W/O NESTED | C16: 1/2" | D16: 2" | E16: White Oak | F16: Rift & Quarter | H16: Nested | J16: Dayspring | L16: Macon
A17: RH2QRSNB | B17: 1/2 x 2" RIFT/QTR R/O NESTED | C17: 1/2" | D17: 2" | E17: Red Oak | F17: Rift & Quarter | H17: Nested | L17: Macon | O17: Lebanon
A18: RH2QRSNB-20 | B18: 1/2 x 2" RIFT/QTR R/O NESTED | C18: 1/2" | D18: 2" | E18: Red Oak | F18: Rift & Quarter | H18: Nested | L18: Macon | N18: Orillia
A19: RH2QRSNB-24 | B19: 1/2 x 2" RIFT/QTR R/O NESTED | C19: 1/2" | D19: 2" | E19: Red Oak | F19: Rift & Quarter | H19: Nested | J19: Dayspring | L19: Macon
A20: RH2SOSNB | B20: 1/2 x 2" SELECT W/O NESTED BND | C20: 1/2" | D20: 2" | E20: White Oak | F20: Select | H20: Nested | L20: Macon
A21: RH2SOSNB-20 | B21: 1/2 x 2" SELECT W/O NESTED | C21: 1/2" | D21: 2" | E21: White Oak | F21: Select | H21: Nested | L21: Macon
A22: RH2SOSNB-24 | B22: 1/2 x 2" SELECT W/O NESTED BND | C22: 1/2" | D22: 2" | E22: White Oak | F22: Select | H22: Nested | L22: Macon
A23: RH2SRS | B23: 1/2 x 2" SELECT R/O NESTED BND | C23: 1/2" | D23: 2" | E23: Red Oak | F23: Select | H23: Nested | L23: Macon
A24: RH2SRSNB | B24: 1/2 x 2" SELECT R/O NESTED BND | C24: 1/2" | D24: 2" | E24: Red Oak | F24: Select | H24: Nested | J24: Dayspring | L24: Macon | M24: Anthony
A25: RH2SRSNB-20 | B25: 1/2 x 2" SELECT R/O NESTED | C25: 1/2" | D25: 2" | E25: Red Oak | F25: Select | H25: Nested | L25: Macon
A26: RQ112SOSNB | B26: 3/4 x 1 1/2" SELECT W/O NESTED | C26: 3/4" | D26: 1-1/2" | E26: White Oak | F26: Select | H26: Nested | I26: 4.5 | L26: Macon
A27: RQ112SRSNB | B27: 3/4 x 1 1/2" SELECT R/O NESTED | C27: 3/4" | D27: 1-1/2" | E27: Red Oak | F27: Select | H27: Nested | I27: 3.5 | L27: Macon
A28: RQ214FMS | B28: 3/4 x 2-1/4 1ST/SEL.MAPLE UNF. | C28: 3/4" | D28: 2-1/4" | E28: Maple | F28: 1st/Select | I28: 4.3 | J28: Dayspring | K28: 3.89 | L28: Macon | M28: Anthony
A29: RQ214QOSSP | B29: 3/4 x 2-1/4" RIFT/QTR WHITE OA | C29: 3/4" | D29: 2-1/4" | E29: White Oak | F29: Rift & Quarter | I29: 5.1 | J29: Dayspring | K29: 3.99 | L29: Macon | M29: Anthony
A30: RQ214SOSSP | B30: 3/4 x 2-1/4 SEL/BTR WHITE OAK | C30: 3/4" | D30: 2-1/4" | E30: White Oak | F30: Select & Better | I30: 4.4 | K30: 3.65 | L30: Macon
A31: RQ214SRSSP | B31: 3/4 X 2-1/4 SELECT RED OAK | C31: 3/4" | D31: 2-1/4" | E31: Red Oak | F31: Select | I31: 3.5 | K31: 2.55 | L31: Macon
A32: RQ314FMS | B32: 3/4 X 3 1/4 1ST/SEL.MAPLE UNF. | C32: 3/4" | D32: 3-1/4" | E32: Maple | F32: 1st/Select | I32: 4.45 | J32: Dayspring | K32: 3.59 | L32: Macon | M32: Anthony
A33: RQ314QOSSP | B33: 3/4 X 3 1/4 RIFT/QTR W/O | C33: 3/4" | D33: 3-1/4" | E33: White Oak | F33: Rift & Quarter | I33: 5.45 | J33: Dayspring | K33: 4.19 | L33: Macon | M33: Anthony
A34: RQ314SDS | B34: 3/4 x 3 1/4 DOUGLAS FIR | C34: 3/4" | D34: 3-1/4" | E34: Douglas Fir | J34: Dayspring | L34: Macon
A35: RQ314SOSSP | B35: 3/4 x 3-1/4 SEL/BTR WHITE OAK | C35: 3/4" | D35: 3-1/4" | E35: White Oak | F35: Select & Better | I35: 4.65 | K35: 3.6 | L35: Macon
A36: RQ314SRSSP | B36: 3/4 x 3-1/4 SEL/BTR RED OAK | C36: 3/4" | D36: 3-1/4" | E36: Red Oak | F36: Select & Better | I36: 3.4 | K36: 2.45 | L36: Macon
A37: RQ3SOB | B37: 3/4 x 3 W/O BEVEL EDGE | C37: 3/4" | D37: 3" | E37: White Oak | G37: Bevel | I37: 4.45 | L37: Macon
A38: RQ3SOS | B38: 3/4 x 3 W/O SEL SQUARE EDGE | C38: 3/4" | D38: 3" | E38: White Oak | F38: Select | G38: Square | I38: 4.45 | L38: Macon
A39: RQ3SRB | B39: 3/4 x 3 R/O BEVEL EDGE | C39: 3/4" | D39: 3" | E39: Red Oak | G39: Bevel | I39: 3.4 | L39: Macon
A40: RQ3SRS | B40: 3/4 x 3 R/O SQUARE EDGE | C40: 3/4" | D40: 3" | E40: Red Oak | G40: Square | I40: 3.4 | L40: Macon
...

Sheet for email
A1: Vendor Name | C1: CONTACT EMAIL | D1: CONTACT PHONE | E1: WHAT THEY OFFER | F1: AVG LEAD TIME | G1: SHIPPING/FEES | H1: ADD.NOTES
A2: AEROSMITH | B2: ELKE | C2: ENICHOLSON@AEROSMITHFASTENING.COM
A3: ZHEJIANG YUHUA TIMBER | B3: ALICE | C3: 黄灵 <aliceh3520@163.com> | E3: OMP EXOTICS COLLECTION, AND DROPPED ZODIAC**10 coats of finish on all colors**
A4: APPALACHIAN | C4: SALES@APPALACHIANLUMBER.NET orders: order@appalachianflooring.com
A5: FRENCH-BROWN FLOORS | B5: KYLE | C5: kyle@french-brown.com | D5: 8323681614 | E5: UNFINISHED CUSTOM PATTERNS AND PLANKS, PARQUET, PATTERNS, LONG LENGTH , WIDE PLANKS, NO 5/16" PARQUET, DALLAS TX
A6: CENO | B6: SAMANTHA | C6: SALES@FLOORSANDING.COM
A7: CONEJO | B7: COREY | C7: COREY@CONEJOHARDWOODS.COM
A8: COUNTRYWOOD | B8: SHAN | C8: shan@countrywoodfloor.net OR info@countrywoodfloor.com | E8: PREF SOLID, NO BRAZILIAN CHERRY , NO MAPLE IN STOCK**msut call for pricing** | F8: 1 WEEK | G8: WE PICK UP | H8: WE ARE NOW COD
A9: DAYSPRING | B9: MIKE | C9: MIKE@DAYSPRINGINC.COM | E9: 1/2", 3/4", 5/16" SOLID UNF, NO MAPLE, NO ENGINEERED, NO CUMARU, NO SANTOS MAHOGANY, NO BRAZ.CHERRY, NO ASH | G9: no
A10: DECKINDEALS | B10: SCOTT | C10: HARDWOODDECKINGDEALS@YAHOO.COM
A11: ELEMENTAL/NOVA | B11: JOHN | C11: JOHN@EHWOODS.COM | E11: ALWAYS CC JOYCE@EHWOODS.COM all unfinished flooring is square-edge and all prefinished has a micro-bevel.Only unopened items may be returned with a 30% restock fee and we are responsible for freight
A12: GLC | B12: Garrison | C12: GARRISON@GLCMILLWORKS.COM | E12: NO PREF OR PARQUET, ONLY UNF, NO ROTARY PEEL, THINNEST ENGINEERED (1/2") NO UNIT BLOCK, max tread width to bullnose is about 13" otherwise it will be squared. | F12: 4-7 WEEKS/5-6 MONTHS | G12: YES
A13: GRAFBRO | B13: GLEN | C13: GLEN@GRAFBRO.COM | D13: 4167254964 | E13: ENGIN, R&Q, ONLY UNF THEY OFFER IS W/O
A14: HILL WOOD PRODUCTS (ASHAWA BAY HDWD FLRS) | B14: KRIS WILSON | C14: KRIS@HILLWOODPRODUCTS.COM | D14: OFFICE:218-666-5933 X3 DIRECT: 218-361-2802 | E14: UNFINISHED ENGINEERED IN 5/8", 3/4" & 1/2", STANDARD LENGTHS ARE 2-8' CUSTOM UP TO 10', THEY DON'T PRODUCE ANY MOULDINGS | F14: 5-7 WEEKS LEAD TIME | G14: YES
A15: INDIANA | B15: NANCY | C15: IHSFLOORS@GMAIL.COM | E15: 3/4" SOLID, RL 1' - 7', LL 2' - 10' HB MAX 24" NO CHEVRON, NO ENG. , NO SMOOTH, ONLY WIREBRUSHED TREATMENT | F15: 5-6 WEEKS | G15: ABOUT 35 CENTS PER SF FOR FREIGHT, EITHER ROAR OR LTL | H15: pick up hours: 8am to 3:30 pm EST
A16: JIM ZHANG | B16: JIM | C16: YIJIAMEIZHANG@163.COM | E16: VINYL/LAMINATE | G16: YES
A17: LEBANON | B17: RANDY | C17: rcmhardwoodfloors@gmail.com | D17: 530-515-3061 | E17: Orders: lebanonoakflooring@windstream.net | F17: stock of 1/2 x 2
A18: LEWIS | B18: LIBBY/TIM | C18: LLEWIS@LEWISMILLING.COM | D18: TELLRICH@LEWISMILLING.COM | E18: 2.25/3/4/5/6, RQ, UNF SOLID NO Walnut, no 1/2"sizes
A19: MACON | B19: JUSTIN/ TYLER | C19: JUSTIN@MACONHARDWOOD.COM tyler@maconhardwood.com EMAIL Kathy for tracking :kathy@maconhardwood.com | D19: 478-405-2293 | E19: UNF/PREF ENG | F19: 2-3/4-5 WEEKS | G19: YES
A20: MICHAEL D'ANGELO (MDI) | C20: OPERATIONS@MICHAELDANGELO.COM | E20: pattern flooring
A21: MULLICAN | B21: KEVIN | C21: KMURPHY@MULLICANFLOORING.COM | E21: 5/8" UNFIN ENG, DOESN'T CARRY WALNUT, NO HB, NO 7" MAPLE, RIFT/QTR IN 2-1/4" and 3-1/4" | G21: 35 CENTS/SF FREIGHT ON AVG
A22: MUSCANELL | B22: KYLE | C22: KYLE@MUSCANELL.COM | E22: 3" UNFINISHED, AMERICAN CHERRY, HICKORY, RED OAK, WALNUT, WHITE ASH, WHITE OAK, WHITE OAK QTR/RFT | G22: 2221/CONTAINER 17,000 SF/CONTAINER
A23: OASIS | C23: info@oasiswoodflooring.com | E23: PREF ENG, ONLY QUOTE FROM PRICELIST,
A24: ORILLIA | B24: JANE | C24: jstannus.oww@outlook.com | D24: 705-327-0700 | E24: fulll pallet of 1/2"X 2=1400 sf, 1/2" x 1-1/2=1350
A25: OSHKOSH | B25: TAMMY | C25: TDAVIS@OSHKOSHDESIGNS.COM
A26: PACIFIC | B26: JOSHUA | C26: JHERNANDEZ@PACIFICHARDWOOD.COM | E26: EXOTICS, HIGH PRICE FOR LOW VOLUME ORDERS 500SF+ FOR GOOD PRICE, ENG & SOLID, UNFI/PREFIN *W/NEED PICTURE AS A REFERENCE OF COLOR/FINISH, NO SQ EDGE ON PREFINISH, NO ACACIA, NO 3/8" THINNEST MATERIAL IS 7/16" WILL ALWAYS QUOTE 2'-10'/12' EVEN IF RL ///4mm will net 3.5, 6mm will net 5.2. HB is double end grooved with slip tongue included unless L&R pieces requested. Solid has lenghtwise grooves.MOQ to avoid set-up fee: 300 SF, relief cuts on engineered are lengthwise | F26: 6-8 weeks
A27: QUEENS | B27: ZAREH/ JANOS DOMINA | C27: INFO@QUEENSPARQUET.COM john.domina@yahoo.com | D27: 818-468-4302 | E27: SOLID/ ENGINEERED CUSTOM | F27: 4-5 WEEKS | G27: Per Janos , David is leaving the company, email address no longer valid. Janos Domina is also a customer, ok per Jim via text 10/14/25 to quote with him.
A28: ROBINSON | B28: JACQUELINE | C28: JACQUELINE@ROBLUMCO.COM | E28: UNF/PREF EXOTICS, $100 pallet breaking fee | F28: 3-4 WEEKS
A29: SAROYAN | B29: DOUG | C29: DT@SAROYANHARDWOODS.COM | E29: ENGINEERED, NO ROTARY PEEL, NO PREFINISHED | F29: 8-10 WEEKS | G29: SET UP CHARGE
A30: SHEOGA | B30: Michael Coates | C30: sheogaflooring@gmail.com or mike@sheogaflooring | D30: 916-778-7471 | E30: 3/4" solid and engineered unf/pref beech,cherry,hickory,maple, r/o,walnut,w/o, w/o live sawn, w/o qtr/rift ,5.25mm wl on eng. 6 textures available, HB and Chevron noings are RL 3-10', pcs depend on availability
A31: SWANER | C31: keith@swanerhardwood.com | E31: NO PINE
A32: TRADELINK | B32: RYAN | C32: RPACE@TRADELINK-GROUP.COM | E32: EXOTICS ; CLOSEST WAREHOUSE IS IN STOCKTON
A33: TROPICAL | C33: SALES@TROPICALFLOORING.NET | E33: NO CUSTOM, EXOTIC, PREFINISHED
A34: STEVE | B34: STEVE | D34: 909-261-0889 | E34: SHAUL'S CONTACT; NO ADDITIONAL INFO
A35: APPALACHIAN FLOORING | B35: KAROLYNE | C35: karolynec@appalachianflooring.com | D35: 450-266-3999 X 227
A36: PARR LUMBER | B36: Steve Daugherty | C36: sdaugherty@parrlumberchino.com | D36: 909-627-0953 x 218 | E36: MDF BACK BOARD FOR SAMPLES, ALLORA PALLET COMPONENTS
A37: INFINITY / AACER | B37: TOM BLAKEMAN | C37: tom@aacerflooring.com | D37: 414-349-5989 | E37: MAPLE, COURT SYSTEMS (NO RETURNS ON MATERIAL)
A38: Ashawa Bay | B38: Kris Wilson | C38: kris@hillwoodproducts.com | D38: 218-666-5933 x3 / 218-361-2802 | E38: ENGINEERED 5/8", 3/4" AND 1/2" ,CHEVRON & HB MATERIAL | F38: 4-6 WEEK ETA | G38: WE PAY FREIGHT

Sheet Strip SKU Combination
A1: INDEX | B1: Item Number | C1: Description | D1: Thickness | E1: Width | F1: Species | G1: Grade/Cut | H1: Edge | I1: Bundles
A2: 1 | B2: DF512PI | C2: 1" X 6" IPE DECK FLOORING (RL) | D2: 1" | E2: 6" | F2: Ipe | I2: Random Length
A3: 2 | B3: DF512PIL | C3: 1" X 6" IPE DECK FLOORING (LL) | D3: 1" | E3: 6" | F3: Ipe | I3: Long Length
A4: 5 | B4: RH112QOSNB-15 | C4: 1/2 x 1 1/2" R&Q W/O NESTED | D4: 1/2" | E4: 1-1/2" | F4: White Oak | G4: Rift & Quarter | I4: Nested
A5: 5 | B5: RH112QOSNB-24 | C5: 1/2 x 1 1/2" R&Q W/O NESTED | D5: 1/2" | E5: 1-1/2" | F5: White Oak | G5: Rift & Quarter | I5: Nested
A6: 3 | B6: RH112QRSNB-15 | C6: 1/2 x 1 1/2" R&Q R/O NESTED | D6: 1/2" | E6: 1-1/2" | F6: Red Oak | G6: Rift & Quarter | I6: Nested
A7: 3 | B7: RH112QRSNB-24 | C7: 1/2 x 1 1/2" R&Q R/O NESTED | D7: 1/2" | E7: 1-1/2" | F7: Red Oak | G7: Rift & Quarter | I7: Nested
A8: 6 | B8: RH112SOSNB | C8: 1/2 x 1 1/2 SELECT W/O NESTED | D8: 1/2" | E8: 1-1/2" | F8: White Oak | G8: Select | I8: Nested
A9: 6 | B9: RH112SOSNB-15 | C9: 1/2 x 1-1/2" SELECT W/O NESTED | D9: 1/2" | E9: 1-1/2" | F9: White Oak | G9: Select | I9: Nested
A10: 6 | B10: RH112SOSNB-24 | C10: 1/2 x 1 1/2" SELECT W/O NESTED | D10: 1/2" | E10: 1-1/2" | F10: White Oak | G10: Select | I10: Nested
A11: 4 | B11: RH112SRSNB | C11: 1/2 x 1 1/2 SELECT R/O NESTED | D11: 1/2" | E11: 1-1/2" | F11: Red Oak | G11: Select | I11: Nested
A12: 4 | B12: RH112SRSNB-15 | C12: 1/2 x 1-1/2" SELECT R/O NESTED | D12: 1/2" | E12: 1-1/2" | F12: Red Oak | G12: Select | I12: Nested
A13: 4 | B13: RH112SRSNB-24 | C13: 1/2 x 1 1/2" SELECT R/O NESTED | D13: 1/2" | E13: 1-1/2" | F13: Red Oak | G13: Select | I13: Nested
A14: 9 | B14: RH2QOSNB | C14: 1/2 x 2" RIFT/OTR W/O NESTED | D14: 1/2" | E14: 2" | F14: White Oak | G14: Rift & Quarter | I14: Nested
A15: 9 | B15: RH2QOSNB-20 | C15: 1/2 x 2" RIFT/OTR W/O NESTED | D15: 1/2" | E15: 2" | F15: White Oak | G15: Rift & Quarter | I15: Nested
... A27: 11 | B27: RQ112SRSNB | C27: 3/4 x 1 1/2" SELECT R/O NESTED | D27: 3/4" | E27: 1-1/2" | F27: Red Oak | G27: Select | I27: Nested
A28: 13 | B28: RQ214FMS | C28: 3/4 x 2-1/4 1ST/SEL.MAPLE UNF. | D28: 3/4" | E28: 2-1/4" | F28: Maple | G28: 1st/Select
A29: 15 | B29: RQ214QOSSP | C29: 3/4 x 2-1/4" RIFT/QTR WHITE OA | D29: 3/4" | E29: 2-1/4" | F29: White Oak | G29: Rift & Quarter
A30: 16 | B30: RQ214SOSSP | C30: 3/4 x 2-1/4 SEL/BTR WHITE OAK | D30: 3/4" | E30: 2-1/4" | F30: White Oak | G30: Select & Better
A31: 14 | B31: RQ214SRSSP | C31: 3/4 X 2-1/4 SELECT RED OAK | D31: 3/4" | E31: 2-1/4" | F31: Red Oak | G31: Select
A32: 22 | B32: RQ314FMS | C32: 3/4 X 3 1/4 1ST/SEL.MAPLE UNF. | D32: 3/4" | E32: 3-1/4" | F32: Maple | G32: 1st/Select
A33: 24 | B33: RQ314QOSSP | C33: 3/4 X 3 1/4 RIFT/QTR W/O | D33: 3/4" | E33: 3-1/4" | F33: White Oak | G33: Rift & Quarter
A34: 21 | B34: RQ314SDS | C34: 3/4 x 3 1/4 DOUGLAS FIR | D34: 3/4" | E34: 3-1/4" | F34: Douglas Fir
A35: 25 | B35: RQ314SOSSP | C35: 3/4 x 3-1/4 SEL/BTR WHITE OAK | D35: 3/4" | E35: 3-1/4" | F35: White Oak | G35: Select & Better
A36: 23 | B36: RQ314SRSSP | C36: 3/4 x 3-1/4 SEL/BTR RED OAK | D36: 3/4" | E36: 3-1/4" | F36: Red Oak | G36: Select & Better
A37: 20 | B37: RQ3SOB | C37: 3/4 x 3 W/O BEVEL EDGE | D37: 3/4" | E37: 3" | F37: White Oak | H37: Bevel
A38: 19 | B38: RQ3SOS | C38: 3/4 x 3 W/O SEL SQUARE EDGE | D38: 3/4" | E38: 3" | F38: White Oak | G38: Select | H38: Square
A39: 17 | B39: RQ3SRB | C39: 3/4 x 3 R/O BEVEL EDGE | D39: 3/4" | E39: 3" | F39: Red Oak | H39: Bevel
A40: 18 | B40: RQ3SRS | C40: 3/4 x 3 R/O SQUARE EDGE | D40: 3/4" | E40: 3" | F40: Red Oak | H40: Square
A41: 28 | B41: RQ4SOB | C41: 3/4 x 4 W/O BEVEL EDGE | D41: 3/4" | E41: 4" | F41: White Oak | H41: Bevel
A42: 29 | B42: RQ4SOS | C42: 3/4 x 4 W/O SQUARE EDGE | D42: 3/4" | E42: 4" | F42: White Oak | H42: Square
A43: 26 | B43: RQ4SRB | C43: 3/4 x 4 R/O BEVEL EDGE | D43: 3/4" | E43: 4" | F43: Red Oak | H43: Bevel
A44: 27 | B44: RQ4SRS | C44: 3/4 x 4 R/O SQUARE EDGE | D44: 3/4" | E44: 4" | F44: Red Oak | H44: Square
A45: 30 | B45: RQ5FMS | C45: 3/4 X 5 1ST MAPLE SE RL EM | D45: 3/4" | E45: 5" | F45: Maple | G45: 1st | H45: Square
A46: 36 | B46: RQ5SOB | C46: 3/4 x 5 W/O BEVEL EDGE | D46: 3/4" | E46: 5" | F46: White Oak | H46: Bevel
A47: 35 | B47: RQ5SOS | C47: 3/4 x 5 W/O SEL SQUARE EDGE | D47: 3/4" | E47: 5" | F47: White Oak | G47: Select | H47: Square
A48: 35 | B48: RQ5SOSD | C48: 3/4 x 5 W/O SEL SQUARE EDGE | D48: 3/4" | E48: 5" | F48: White Oak | G48: Select | H48: Square
A49: 31 | B49: RQ5SRB | C49: 3/4 x 5 R/O BEVEL EDGE | D49: 3/4" | E49: 5" | F49: Red Oak | H49: Bevel
A50: 32 | B50: RQ5SRS | C50: 3/4 x 5 R/O SQUARE EDGE | D50: 3/4" | E50: 5" | F50: Red Oak | H50: Square
A51: 32 | B51: RQ5SRSI | C51: 3/4 x 5 R/O SQUARE EDGE | D51: 3/4" | E51: 5" | F51: Red Oak | H51: Square
...

Sheet Sheet1
A1: Item Number | B1: Thickness | C1: Width | D1: Species | E1: Grade/Cut | F1: Edge | G1: Reorder Amount | H1: Amount in Stock/Additional Info
A2: DF512PI | B2: =VLOOKUP(A2,'Strip SKU Combination'!$B$2:$H$65,3,FALSE) | C2: =VLOOKUP(A2,'Strip SKU Combination'!$B$2:$H$65,4,FALSE) | D2: =VLOOKUP(A2,'Strip SKU Combination'!$B$2:$H$65,5,FALSE) | E2: =VLOOKUP(A2,'Strip SKU Combination'!$B$2:$H$65,6,FALSE) | F2: =VLOOKUP(A2,'Strip SKU Combination'!$B$2:$H$65,7,FALSE)
A3: DF512PIL | B3: =VLOOKUP(A3,'Strip SKU Combination'!$B$2:$H$65,3,FALSE) | C3: =VLOOKUP(A3,'Strip SKU Combination'!$B$2:$H$65,4,FALSE) | D3: =VLOOKUP(A3,'Strip SKU Combination'!$B$2:$H$65,5,FALSE) | E3: =VLOOKUP(A3,'Strip SKU Combination'!$B$2:$H$65,6,FALSE) | F3: =VLOOKUP(A3,'Strip SKU Combination'!$B$2:$H$65,7,FALSE)
A4: RH112QRSNB-15 | B4: =VLOOKUP(A4,'Strip SKU Combination'!$B$2:$H$65,3,FALSE) | C4: =VLOOKUP(A4,'Strip SKU Combination'!$B$2:$H$65,4,FALSE) | D4: =VLOOKUP(A4,'Strip SKU Combination'!$B$2:$H$65,5,FALSE) | E4: =VLOOKUP(A4,'Strip SKU Combination'!$B$2:$H$65,6,FALSE) | F4: =VLOOKUP(A4,'Strip SKU Combination'!$B$2:$H$65,7,FALSE)
A5: RH112QRSNB-24 | B5: =VLOOKUP(A5,'Strip SKU Combination'!$B$2:$H$65,3,FALSE) | C5: =VLOOKUP(A5,'Strip SKU Combination'!$B$2:$H$65,4,FALSE) | D5: =VLOOKUP(A5,'Strip SKU Combination'!$B$2:$H$65,5,FALSE) | E5: =VLOOKUP(A5,'Strip SKU Combination'!$B$2:$H$65,6,FALSE) | F5: =VLOOKUP(A5,'Strip SKU Combination'!$B$2:$H$65,7,FALSE)
A6: RH112SRSNB | B6: =VLOOKUP(A6,'Strip SKU Combination'!$B$2:$H$65,3,FALSE) | C6: =VLOOKUP(A6,'Strip SKU Combination'!$B$2:$H$65,4,FALSE) | D6: =VLOOKUP(A6,'Strip SKU Combination'!$B$2:$H$65,5,FALSE) | E6: =VLOOKUP(A6,'Strip SKU Combination'!$B$2:$H$65,6,FALSE) | F6: =VLOOKUP(A6,'Strip SKU Combination'!$B$2:$H$65,7,FALSE)
A7: RH112SRSNB-15 | B7: =VLOOKUP(A7,'Strip SKU Combination'!$B$2:$H$65,3,FALSE) | C7: =VLOOKUP(A7,'Strip SKU Combination'!$B$2:$H$65,4,FALSE) | D7: =VLOOKUP(A7,'Strip SKU Combination'!$B$2:$H$65,5,FALSE) | E7: =VLOOKUP(A7,'Strip SKU Combination'!$B$2:$H$65,6,FALSE) | F7: =VLOOKUP(A7,'Strip SKU Combination'!$B$2:$H$65,7,FALSE)
A8: RH112SRSNB-24 | B8: =VLOOKUP(A8,'Strip SKU Combination'!$B$2:$H$65,3,FALSE) | C8: =VLOOKUP(A8,'Strip SKU Combination'!$B$2:$H$65,4,FALSE) | D8: =VLOOKUP(A8,'Strip SKU Combination'!$B$2:$H$65,5,FALSE) | E8: =VLOOKUP(A8,'Strip SKU Combination'!$B$2:$H$65,6,FALSE) | F8: =VLOOKUP(A8,'Strip SKU Combination'!$B$2:$H$65,7,FALSE)
A9: RH112QOSNB-15 | B9: =VLOOKUP(A9,'Strip SKU Combination'!$B$2:$H$65,3,FALSE) | C9: =VLOOKUP(A9,'Strip SKU Combination'!$B$2:$H$65,4,FALSE) | D9: =VLOOKUP(A9,'Strip SKU Combination'!$B$2:$H$65,5,FALSE) | E9: =VLOOKUP(A9,'Strip SKU Combination'!$B$2:$H$65,6,FALSE) | F9: =VLOOKUP(A9,'Strip SKU Combination'!$B$2:$H$65,7,FALSE)
A10: RH112QOSNB-24 | B10: =VLOOKUP(A10,'Strip SKU Combination'!$B$2:$H$65,3,FALSE) | C10: =VLOOKUP(A10,'Strip SKU Combination'!$B$2:$H$65,4,FALSE) | D10: =VLOOKUP(A10,'Strip SKU Combination'!$B$2:$H$65,5,FALSE) | E10: =VLOOKUP(A10,'Strip SKU Combination'!$B$2:$H$65,6,FALSE) | F10: =VLOOKUP(A10,'Strip SKU Combination'!$B$2:$H$65,7,FALSE)
A11: RH112SOSNB | B11: =VLOOKUP(A11,'Strip SKU Combination'!$B$2:$H$65,3,FALSE) | C11: =VLOOKUP(A11,'Strip SKU Combination'!$B$2:$H$65,4,FALSE) | D11: =VLOOKUP(A11,'Strip SKU Combination'!$B$2:$H$65,5,FALSE) | E11: =VLOOKUP(A11,'Strip SKU Combination'!$B$2:$H$65,6,FALSE) | F11: =VLOOKUP(A11,'Strip SKU Combination'!$B$2:$H$65,7,FALSE)
A12: RH112SOSNB-15 | B12: =VLOOKUP(A12,'Strip SKU Combination'!$B$2:$H$65,3,FALSE) | C12: =VLOOKUP(A12,'Strip SKU Combination'!$B$2:$H$65,4,FALSE) | D12: =VLOOKUP(A12,'Strip SKU Combination'!$B$2:$H$65,5,FALSE) | E12: =VLOOKUP(A12,'Strip SKU Combination'!$B$2:$H$65,6,FALSE) | F12: =VLOOKUP(A12,'Strip SKU Combination'!$B$2:$H$65,7,FALSE)
A13: RH112SOSNB-24 | B13: =VLOOKUP(A13,'Strip SKU Combination'!$B$2:$H$65,3,FALSE) | C13: =VLOOKUP(A13,'Strip SKU Combination'!$B$2:$H$65,4,FALSE) | D13: =VLOOKUP(A13,'Strip SKU Combination'!$B$2:$H$65,5,FALSE) | E13: =VLOOKUP(A13,'Strip SKU Combination'!$B$2:$H$65,6,FALSE) | F13: =VLOOKUP(A13,'Strip SKU Combination'!$B$2:$H$65,7,FALSE)
... A65: RT2SOSNB-24 | B65: =VLOOKUP(A65,'Strip SKU Combination'!$B$2:$H$65,3,FALSE) | C65: =VLOOKUP(A65,'Strip SKU Combination'!$B$2:$H$65,4,FALSE) | D65: =VLOOKUP(A65,'Strip SKU Combination'!$B$2:$H$65,5,FALSE) | E65: =VLOOKUP(A65,'Strip SKU Combination'!$B$2:$H$65,6,FALSE) | F65: =VLOOKUP(A65,'Strip SKU Combination'!$B$2:$H$65,7,FALSE)
