Workbook

Sheet Current Pricing
A1: Item Number | B1: Thickness | C1: Width | D1: Species | E1: Grade/Cut | F1: Edge | G1: Appalachian | H1: Macon | I1: Indiana | J1: Lebanon | K1: Dayspring | L1: Merrick | M1: Merrick From Sheet | N1: Orillia | O1: Mullican
A2: RQ5SWB | B2: 3/4" | C2: 5" | D2: Walnut | E2: Select & Better | F2: Bevel | I2: 7.65
A3: DF512PI | B3: 1" | C3: 6" | D3: Ipe | E3: - | F3: - | M3: =VLOOKUP(A3,Merrick!$A$2:$G$46,7,FALSE) -> #N/A
A4: DF512PIL | B4: 1" | C4: 6" | D4: Ipe | E4: - | F4: - | M4: =VLOOKUP(A4,Merrick!$A$2:$G$46,7,FALSE) -> #N/A
A5: RH112QOSNB-15 | B5: 1/2" | C5: 1-1/2" | D5: White Oak | E5: Rift & Quarter | F5: - | M5: =VLOOKUP(A5,Merrick!$A$2:$G$46,7,FALSE) -> #N/A
A6: RH112QOSNB-15/ RH112QOSNB-24 | B6: 1/2" | C6: 1-1/2" | D6: White Oak | E6: Rift & Quarter | F6: -
A7: RH112QOSNB-24 | B7: 1/2" | C7: 1-1/2" | D7: White Oak | E7: Rift & Quarter | F7: - | M7: =VLOOKUP(A7,Merrick!$A$2:$G$46,7,FALSE) -> #N/A
A8: RH112QRSNB-15 | B8: 1/2" | C8: 1-1/2" | D8: Red Oak | E8: Rift & Quarter | F8: - | M8: =VLOOKUP(A8,Merrick!$A$2:$G$46,7,FALSE) -> #N/A
A9: RH112QRSNB-15/ RH112QRSNB-24 | B9: 1/2" | C9: 1-1/2" | D9: Red Oak | E9: Rift & Quarter | F9: -
A10: RH112QRSNB-24 | B10: 1/2" | C10: 1-1/2" | D10: Red Oak | E10: Rift & Quarter | F10: - | M10: =VLOOKUP(A10,Merrick!$A$2:$G$46,7,FALSE) -> #N/A
A11: RH112SOSNB | B11: 1/2" | C11: 1-1/2" | D11: White Oak | E11: Select | F11: - | M11: =VLOOKUP(A11,Merrick!$A$2:$G$46,7,FALSE) -> #N/A
A12: RH112SOSNB/ RH112SOSNB-15/ RH112SOSNB-24 | B12: 1/2" | C12: 1-1/2" | D12: White Oak | E12: Select | F12: -
A13: RH112SOSNB-15 | B13: 1/2" | C13: 1-1/2" | D13: White Oak | E13: Select | F13: - | M13: =VLOOKUP(A13,Merrick!$A$2:$G$46,7,FALSE) -> #N/A
A14: RH112SOSNB-24 | B14: 1/2" | C14: 1-1/2" | D14: White Oak | E14: Select | F14: - | K14: 3.95 | M14: =VLOOKUP(A14,Merrick!$A$2:$G$46,7,FALSE) -> #N/A
A15: RH112SRSNB | B15: 1/2" | C15: 1-1/2" | D15: Red Oak | E15: Select | F15: - | M15: =VLOOKUP(A15,Merrick!$A$2:$G$46,7,FALSE) -> #N/A
A16: RH112SRSNB/ RH112SRSNB-15/ RH112SRSNB-24 | B16: 1/2" | C16: 1-1/2" | D16: Red Oak | E16: Select | F16: - | K16: 2.95
A17: RH112SRSNB-15 | B17: 1/2" | C17: 1-1/2" | D17: Red Oak | E17: Select | F17: - | M17: =VLOOKUP(A17,Merrick!$A$2:$G$46,7,FALSE) -> #N/A
A18: RH112SRSNB-24 | B18: 1/2" | C18: 1-1/2" | D18: Red Oak | E18: Select | F18: - | K18: 2.95 | M18: =VLOOKUP(A18,Merrick!$A$2:$G$46,7,FALSE) -> #N/A
A19: RH2QOSNB | B19: 1/2" | C19: 2" | D19: White Oak | E19: Rift & Quarter | F19: - | K19: 3.98 | M19: =VLOOKUP(A19,Merrick!$A$2:$G$46,7,FALSE) -> #N/A
A20: RH2QOSNB/ RH2QOSNB-20/ RH2QOSNB-24 | B20: 1/2" | C20: 2" | D20: White Oak | E20: Rift & Quarter | F20: -
A21: RH2QOSNB-20 | B21: 1/2" | C21: 2" | D21: White Oak | E21: Rift & Quarter | F21: - | K21: 3.98 | M21: =VLOOKUP(A21,Merrick!$A$2:$G$46,7,FALSE) -> #N/A
A22: RH2QOSNB-24 | B22: 1/2" | C22: 2" | D22: White Oak | E22: Rift & Quarter | F22: - | K22: 3.98 | M22: =VLOOKUP(A22,Merrick!$A$2:$G$46,7,FALSE) -> #N/A
A23: RH2QRSNB | B23: 1/2" | C23: 2" | D23: Red Oak | E23: Rift & Quarter | F23: - | M23: =VLOOKUP(A23,Merrick!$A$2:$G$46,7,FALSE) -> #N/A
A24: RH2QRSNB/ RH2QRSNB-20/ RH2QRSNB-24 | B24: 1/2" | C24: 2" | D24: Red Oak | E24: Rift & Quarter | F24: -
A25: RH2QRSNB-20 | B25: 1/2" | C25: 2" | D25: Red Oak | E25: Rift & Quarter | F25: - | M25: =VLOOKUP(A25,Merrick!$A$2:$G$46,7,FALSE) -> #N/A
A26: RH2QRSNB-24 | B26: 1/2" | C26: 2" | D26: Red Oak | E26: Rift & Quarter | F26: - | M26: =VLOOKUP(A26,Merrick!$A$2:$G$46,7,FALSE) -> #N/A
A27: RH2SOSNB | B27: 1/2" | C27: 2" | D27: White Oak | E27: Select | F27: - | K27: 3.55 | M27: =VLOOKUP(A27,Merrick!$A$2:$G$46,7,FALSE) -> #N/A
A28: RH2SOSNB/ RH2SOSNB-20/ RH2SOSNB-24 | B28: 1/2" | C28: 2" | D28: White Oak | E28: Select | F28: -
A29: RH2SOSNB-20 | B29: 1/2" | C29: 2" | D29: White Oak | E29: Select | F29: - | M29: =VLOOKUP(A29,Merrick!$A$2:$G$46,7,FALSE) -> #N/A
A30: RH2SOSNB-24 | B30: 1/2" | C30: 2" | D30: White Oak | E30: Select | F30: - | M30: =VLOOKUP(A30,Merrick!$A$2:$G$46,7,FALSE) -> #N/A
A31: RH2SRS | B31: 1/2" | C31: 2" | D31: Red Oak | E31: Select | F31: - | M31: =VLOOKUP(A31,Merrick!$A$2:$G$46,7,FALSE) -> #N/A
A32: RH2SRS/ RH2SRSNB/ RH2SRSNB-20 | B32: 1/2" | C32: 2" | D32: Red Oak | E32: Select | F32: -
A33: RH2SRSNB | B33: 1/2" | C33: 2" | D33: Red Oak | E33: Select | F33: - | K33: 2.55 | M33: =VLOOKUP(A33,Merrick!$A$2:$G$46,7,FALSE) -> #N/A
A34: RH2SRSNB-20 | B34: 1/2" | C34: 2" | D34: Red Oak | E34: Select | F34: - | M34: =VLOOKUP(A34,Merrick!$A$2:$G$46,7,FALSE) -> #N/A
A35: RQ112SOSNB | B35: 3/4" | C35: 1-1/2" | D35: White Oak | E35: Select | F35: - | H35: 3.85 | I35: 4.5 | M35: =VLOOKUP(A35,Merrick!$A$2:$G$46,7,FALSE) -> #N/A
A36: RQ112SRSNB | B36: 3/4" | C36: 1-1/2" | D36: Red Oak | E36: Select | F36: - | H36: 3.4 | I36: 3.5 | M36: =VLOOKUP(A36,Merrick!$A$2:$G$46,7,FALSE) -> #N/A
A37: RQ214FMS | B37: 3/4" | C37: 2-1/4" | D37: Maple | E37: 1st/Select | F37: - | H37: 3.85 | L37: 4.25 | M37: =VLOOKUP(A37,Merrick!$A$2:$G$46,7,FALSE) -> 2.05
A38: RQ214QOSSP | B38: 3/4" | C38: 2-1/4" | D38: White Oak | E38: Rift & Quarter | F38: - | I38: 5.1 | M38: =VLOOKUP(A38,Merrick!$A$2:$G$46,7,FALSE) -> 3.5
A39: RQ214SOSSP | B39: 3/4" | C39: 2-1/4" | D39: White Oak | E39: Select & Better | F39: - | I39: 4.4 | M39: =VLOOKUP(A39,Merrick!$A$2:$G$46,7,FALSE) -> #N/A
A40: RQ214SRSSP | B40: 3/4" | C40: 2-1/4" | D40: Red Oak | E40: Select | F40: - | H40: 2.7 | I40: 3.5 | L40: 2.55 | M40: =VLOOKUP(A40,Merrick!$A$2:$G$46,7,FALSE) -> 2.68
...

Sheet Merrick
A1: OMP Item Number | B1: Species | C1: Category | D1: Merrick Item Number | E1: Grade | F1: Width | G1: Price | I1: Last Updated
A2: RQ214SRSSP | B2: Red Oak | C2: STRIP PRODUCTS | D2: ROSB214MH | E2: SEL/BTR | F2: 2 ¼" | G2: 2.68 | I2: 4.13.2026
A3: RQ214FMS | B3: Red Oak | C3: STRIP PRODUCTS | D3: RO1C214MH | E3: 1 COM | F3: 2 ¼" | G3: 2.05
A4: NONE | B4: Red Oak | C4: STRIP PRODUCTS | D4: RO2C214MH | E4: 2 COM | F4: 2 ¼" | G4: 1
A5: RQ314SRSSP | B5: Red Oak | C5: STRIP PRODUCTS | D5: ROSB314MH | E5: SEL/BTR | F5: 3 ¼" | G5: 2.45
A6: NONE | B6: Red Oak | C6: STRIP PRODUCTS | D6: RO1C314MH | E6: 1 COM | F6: 3 ¼" | G6: 1.9
A7: NONE | B7: Red Oak | C7: STRIP PRODUCTS | D7: RO2C314MH | E7: 2 COM | F7: 3 ¼" | G7: 1.13
A8: NONE | B8: Red Oak | C8: PLANK PRODUCTS | D8: Item | E8: Grade | F8: Width | G8: Price
A9: RQ4SRS | B9: Red Oak | C9: PLANK PRODUCTS | D9: ROSB4MH | E9: SEL/BTR | F9: 4" | G9: 2.45
A10: NONE | B10: Red Oak | C10: PLANK PRODUCTS | D10: RO1C4MH | E10: 1 COM | F10: 4" | G10: 2
A11: NONE | B11: Red Oak | C11: PLANK PRODUCTS | D11: RO2C4MH | E11: 2 COM | F11: 4" | G11: 1.2
A12: RQ5SRS | B12: Red Oak | C12: PLANK PRODUCTS | D12: ROSB5MH | E12: SEL/BTR | F12: 5" | G12: 2.65
A13: NONE | B13: Red Oak | C13: PLANK PRODUCTS | D13: RO1C5MH | E13: 1 COM | F13: 5" | G13: 2
A14: NONE | B14: Red Oak | C14: PLANK PRODUCTS | D14: RO2C5MH | E14: 2 COM | F14: 5" | G14: 1.4
A15: NONE | B15: White Oak | C15: STRIP PRODUCTS | D15: Item | E15: Grade | F15: Width | G15: Price
A16: RQ214QOSSP | B16: White Oak | C16: STRIP PRODUCTS | D16: WOSB214MH | E16: SEL/BTR | F16: 2 ¼" | G16: 3.5
A17: NONE | B17: White Oak | C17: STRIP PRODUCTS | D17: WO1C214MH | E17: 1 COM | F17: 2 ¼" | G17: 2.05
A18: NONE | B18: White Oak | C18: STRIP PRODUCTS | D18: WO2C214MH | E18: 2 COM | F18: 2 ¼" | G18: 0.9
A19: NONE | B19: White Oak | C19: STRIP PRODUCTS
A20: NONE | B20: White Oak | C20: STRIP PRODUCTS | D20: WOSB314MH | E20: SEL/BTR | F20: 3 ¼" | G20: 3.4
A21: NONE | B21: White Oak | C21: STRIP PRODUCTS | D21: WO1C314MH | E21: 1 COM | F21: 3 ¼" | G21: 2.45
A22: NONE | B22: White Oak | C22: STRIP PRODUCTS | D22: WO2C314MH | E22: 2 COM | F22: 3 ¼" | G22: 1.4
A23: NONE | B23: White Oak | C23: STRIP PRODUCTS | D23: WOMR314N | E23: MILL RUN | F23: 3 ¼" | G23: 2
A24: NONE | B24: White Oak | C24: PLANK PRODUCTS | D24: Item | E24: Grade | F24: Width | G24: Price
A25: RQ4SOS | B25: White Oak | C25: PLANK PRODUCTS | D25: WOSB4MH | E25: SEL/BTR | F25: 4" | G25: 4.25
A26: NONE | B26: White Oak | C26: PLANK PRODUCTS | D26: WO1C4MH | E26: 1 COM | F26: 4" | G26: 2.8
A27: NONE | B27: White Oak | C27: PLANK PRODUCTS | D27: WO2C4MH | E27: 2 COM | F27: 4" | G27: 1.5
A28: NONE | B28: White Oak | C28: PLANK PRODUCTS | D28: WOMR4MH | E28: MILL RUN | F28: 4" | G28: 2.8
A29: RQ5SOS | B29: White Oak | C29: PLANK PRODUCTS | D29: WOSB5MH | E29: SEL/BTR | F29: 5" | G29: 4.65
A30: NONE | B30: White Oak | C30: PLANK PRODUCTS | D30: WO1C5MH | E30: 1 COM | F30: 5" | G30: 3.1
A31: NONE | B31: White Oak | C31: PLANK PRODUCTS | D31: WO2C5MH | E31: 2 COM | F31: 5" | G31: 1.9
A32: NONE | B32: White Oak | C32: PLANK PRODUCTS | D32: WOMR5MH | E32: MILL RUN | F32: 5" | G32: 3.1
A33: NONE | B33: Hard Maple | C33: 2 1/4" | D33: Item | E33: Grade | F33: Width | G33: Price
A34: RQ214FMS | B34: Hard Maple | C34: 2 1/4" | D34: HM1ST2SF | E34: 1ST | F34: 2 ¼" | G34: 4.25
A35: NONE | B35: Hard Maple | C35: 2 1/4" | D35: HM2B2SF | E35: 2ND & BTR | F35: 2 ¼" | G35: 3.75
A36: NONE | B36: Hard Maple | C36: 2 1/4" | D36: HM3D2SF | E36: 3RD | F36: 2 ¼" | G36: 2.1
A37: NONE | B37: Hard Maple | C37: 3 1/4" | D37: Item | E37: Grade | F37: Width | G37: Price
A38: RQ314FMS | B38: Hard Maple | C38: 3 1/4" | D38: HM1ST314SF | E38: 1ST | F38: 3 ¼" | G38: 4.25
A39: NONE | B39: Hard Maple | C39: 3 1/4" | D39: HM2B314SF | E39: 2ND & BTR | F39: 3 ¼" | G39: 2.75
A40: NONE | B40: Hard Maple | C40: 3 1/4" | D40: HM3D314SF | E40: 3RD | F40: 3 ¼" | G40: 1.8
...

Sheet Freight
A1: Vendor | B1: Origin | C1: ST | D1: Destination | E1: ST | F1: Size | G1: Rate
A2: Merrick | B2: Burnside | C2: KY | D2: Van Nuys | E2: CA | F2: 40 | G2: 3295
A3: Yesteryear | B3: Campbellsville | C3: KY | D3: Van Nuys | E3: CA | F3: 40 | G3: 3095
A4: Ashawa Bay | B4: Cook | C4: MN | D4: Van Nuys | E4: CA | F4: 40 | G4: 3195
B5: Hortonville | C5: WI | D5: Van Nuys | E5: CA | F5: 40 | G5: 2425
A6: Lebanon | B6: Lebanon | C6: KY | D6: Van Nuys | E6: CA | F6: 40 | G6: 3295
A7: Sheoga | B7: Middlefield | C7: OH | D7: Van Nuys | E7: CA | F7: 40 | G7: 2395
A8: Mullican | B8: Ronceverte | C8: WV | D8: Van Nuys | E8: CA | F8: 40 | G8: 3595
A9: Indiana | B9: Spencer | C9: IN | D9: Van Nuys | E9: CA | F9: 40 | G9: 2595
B10: Valparaiso | C10: IN | D10: Van Nuys | E10: CA | F10: 40 | G10: 2195
A11: Macon | D11: Van Nuys | E11: CA | F11: 40 | G11: 0
A12: Dayspring | D12: Van Nuys | E12: CA | F12: 40 | G12: 0
