Workbook

Sheet Current Pricing
A1: Item Number | B1: Thickness | C1: Width | D1: Species | E1: Grade/Cut | F1: Edge | G1: Appalachian | H1: Macon | I1: Indiana | J1: Lebanon | K1: Dayspring | L1: Merrick | M1: Merrick From Sheet | N1: Orillia | O1: Mullican | P1: Appalachian SF/Pallet | Q1: Macon SF/Pallet | R1: Indiana SF/Pallet | S1: Lebanon SF/Pallet | T1: Dayspring SF/Pallet | U1: Merrick SF/Pallet | V1: Merrick From Sheet SF/Pallet | W1: Orillia SF/Pallet | X1: Mullican SF/Pallet | Y1: Appalachian Pallets/Container | Z1: Macon Pallets/Container | AA1: Indiana Pallets/Container | AB1: Lebanon Pallets/Container | AC1: Dayspring Pallets/Container | AD1: Merrick Pallets/Container | AE1: Merrick From Sheet Pallets/Container | AF1: Orillia Pallets/Container | AG1: Mullican Pallets/Container
A2: DF512PI | B2: 1" | C2: 6" | D2: Ipe | E2: - | F2: - | M2: =VLOOKUP(A2,Merrick!$A$2:$G$46,7,FALSE) -> #N/A
A3: DF512PIL | B3: 1" | C3: 6" | D3: Ipe | E3: - | F3: - | M3: =VLOOKUP(A3,Merrick!$A$2:$G$46,7,FALSE) -> #N/A
A4: RH112QRSNB-15 | B4: 1/2" | C4: 1-1/2" | D4: Red Oak | E4: Rift & Quarter | F4: - | M4: =VLOOKUP(A4,Merrick!$A$2:$G$46,7,FALSE) -> #N/A | S4: 1050 | AB4: 22 | AD4: 18 | AE4: 18
A5: RH112QRSNB-24 | B5: 1/2" | C5: 1-1/2" | D5: Red Oak | E5: Rift & Quarter | F5: - | M5: =VLOOKUP(A5,Merrick!$A$2:$G$46,7,FALSE) -> #N/A | S5: 1050 | AB5: 22 | AD5: 18 | AE5: 18
A6: RH112QRSNB-15/ RH112QRSNB-24 | B6: 1/2" | C6: 1-1/2" | D6: Red Oak | E6: Rift & Quarter | F6: - | S6: 1050 | AB6: 22 | AD6: 18 | AE6: 18
A7: RH112SRSNB | B7: 1/2" | C7: 1-1/2" | D7: Red Oak | E7: Select | F7: - | M7: =VLOOKUP(A7,Merrick!$A$2:$G$46,7,FALSE) -> #N/A | S7: 1050 | AB7: 22 | AD7: 18 | AE7: 18
A8: RH112SRSNB-15 | B8: 1/2" | C8: 1-1/2" | D8: Red Oak | E8: Select | F8: - | M8: =VLOOKUP(A8,Merrick!$A$2:$G$46,7,FALSE) -> #N/A | S8: 1050 | AB8: 22 | AD8: 18 | AE8: 18
A9: RH112SRSNB-24 | B9: 1/2" | C9: 1-1/2" | D9: Red Oak | E9: Select | F9: - | J9: =VLOOKUP(A9,'[1]Current Pricing'!A$2:J$75,10,FALSE) -> 3.1 | K9: 2.95 | M9: =VLOOKUP(A9,Merrick!$A$2:$G$46,7,FALSE) -> #N/A | S9: 1050 | AB9: 22 | AD9: 18 | AE9: 18
A10: RH112SRSNB/ RH112SRSNB-15/ RH112SRSNB-24 | B10: 1/2" | C10: 1-1/2" | D10: Red Oak | E10: Select | F10: - | J10: =VLOOKUP(A10,'[1]Current Pricing'!A$2:J$75,10,FALSE) -> 3.1 | K10: 2.95 | N10: 3.1 | S10: 1050 | AB10: 22 | AD10: 18 | AE10: 18
A11: RH112QOSNB-15 | B11: 1/2" | C11: 1-1/2" | D11: White Oak | E11: Rift & Quarter | F11: - | M11: =VLOOKUP(A11,Merrick!$A$2:$G$46,7,FALSE) -> #N/A | N11: 5.15 | S11: 1050 | AB11: 22 | AD11: 18 | AE11: 18
A12: RH112QOSNB-24 | B12: 1/2" | C12: 1-1/2" | D12: White Oak | E12: Rift & Quarter | F12: - | M12: =VLOOKUP(A12,Merrick!$A$2:$G$46,7,FALSE) -> #N/A | S12: 1050 | AB12: 22 | AD12: 18 | AE12: 18
A13: RH112QOSNB-15/ RH112QOSNB-24 | B13: 1/2" | C13: 1-1/2" | D13: White Oak | E13: Rift & Quarter | F13: - | N13: 5.15 | S13: 1050 | AB13: 22 | AD13: 18 | AE13: 18
A14: RH112SOSNB | B14: 1/2" | C14: 1-1/2" | D14: White Oak | E14: Select | F14: - | J14: 5.27 | M14: =VLOOKUP(A14,Merrick!$A$2:$G$46,7,FALSE) -> #N/A | S14: 1050 | AB14: 22 | AD14: 18 | AE14: 18
A15: RH112SOSNB-15 | B15: 1/2" | C15: 1-1/2" | D15: White Oak | E15: Select | F15: - | M15: =VLOOKUP(A15,Merrick!$A$2:$G$46,7,FALSE) -> #N/A | S15: 1050 | AB15: 22 | AD15: 18 | AE15: 18
A16: RH112SOSNB-24 | B16: 1/2" | C16: 1-1/2" | D16: White Oak | E16: Select | F16: - | K16: 3.95 | M16: =VLOOKUP(A16,Merrick!$A$2:$G$46,7,FALSE) -> #N/A | S16: 1050 | AB16: 22 | AD16: 18 | AE16: 18
A17: RH112SOSNB/ RH112SOSNB-15/ RH112SOSNB-24 | B17: 1/2" | C17: 1-1/2" | D17: White Oak | E17: Select | F17: - | J17: 5.27 | K17: 3.95 | N17: 3.52 | S17: 1050 | AB17: 22 | AD17: 18 | AE17: 18
A18: RH2QRSNB | B18: 1/2" | C18: 2" | D18: Red Oak | E18: Rift & Quarter | F18: - | M18: =VLOOKUP(A18,Merrick!$A$2:$G$46,7,FALSE) -> #N/A | S18: 1050 | AB18: 22 | AD18: 18 | AE18: 18
A19: RH2QRSNB-20 | B19: 1/2" | C19: 2" | D19: Red Oak | E19: Rift & Quarter | F19: - | M19: =VLOOKUP(A19,Merrick!$A$2:$G$46,7,FALSE) -> #N/A | S19: 1050 | AB19: 22 | AD19: 18 | AE19: 18
A20: RH2QRSNB-24 | B20: 1/2" | C20: 2" | D20: Red Oak | E20: Rift & Quarter | F20: - | M20: =VLOOKUP(A20,Merrick!$A$2:$G$46,7,FALSE) -> #N/A | S20: 1050 | AB20: 22 | AD20: 18 | AE20: 18
A21: RH2QRSNB/ RH2QRSNB-20/ RH2QRSNB-24 | B21: 1/2" | C21: 2" | D21: Red Oak | E21: Rift & Quarter | F21: - | S21: 1050 | AB21: 22 | AD21: 18 | AE21: 18
A22: RH2SRS | B22: 1/2" | C22: 2" | D22: Red Oak | E22: Select | F22: - | K22: 2.55 | M22: =VLOOKUP(A22,Merrick!$A$2:$G$46,7,FALSE) -> #N/A | S22: 1050 | AB22: 22 | AD22: 18 | AE22: 18
A23: RH2SRSNB | B23: 1/2" | C23: 2" | D23: Red Oak | E23: Select | F23: - | J23: =VLOOKUP(A23,'[1]Current Pricing'!A$2:J$75,10,FALSE) -> 2.4 | M23: =VLOOKUP(A23,Merrick!$A$2:$G$46,7,FALSE) -> #N/A | S23: 1050 | AB23: 22 | AD23: 18 | AE23: 18
A24: RH2SRSNB-20 | B24: 1/2" | C24: 2" | D24: Red Oak | E24: Select | F24: - | M24: =VLOOKUP(A24,Merrick!$A$2:$G$46,7,FALSE) -> #N/A | N24: 2.98 | S24: 1050 | AB24: 22 | AD24: 18 | AE24: 18
A25: RH2SRS/ RH2SRSNB/ RH2SRSNB-20 | B25: 1/2" | C25: 2" | D25: Red Oak | E25: Select | F25: - | J25: =VLOOKUP(A25,'[1]Current Pricing'!A$2:J$75,10,FALSE) -> 2.4 | K25: 2.55 | N25: 2.98 | S25: 1050 | AB25: 22 | AD25: 18 | AE25: 18
A26: RH2QOSNB | B26: 1/2" | C26: 2" | D26: White Oak | E26: Rift & Quarter | F26: - | M26: =VLOOKUP(A26,Merrick!$A$2:$G$46,7,FALSE) -> #N/A | S26: 1050 | AB26: 22 | AD26: 18 | AE26: 18
A27: RH2QOSNB-20 | B27: 1/2" | C27: 2" | D27: White Oak | E27: Rift & Quarter | F27: - | M27: =VLOOKUP(A27,Merrick!$A$2:$G$46,7,FALSE) -> #N/A | S27: 1050 | AB27: 22 | AD27: 18 | AE27: 18
A28: RH2QOSNB-24 | B28: 1/2" | C28: 2" | D28: White Oak | E28: Rift & Quarter | F28: - | K28: 3.98 | M28: =VLOOKUP(A28,Merrick!$A$2:$G$46,7,FALSE) -> #N/A | S28: 1050 | AB28: 22 | AD28: 18 | AE28: 18
A29: RH2QOSNB/ RH2QOSNB-20/ RH2QOSNB-24 | B29: 1/2" | C29: 2" | D29: White Oak | E29: Rift & Quarter | F29: - | J29: 5.69 | K29: 3.98 | N29: 4.95 | S29: 1050 | AB29: 22 | AD29: 18 | AE29: 18
A30: RH2SOSNB | B30: 1/2" | C30: 2" | D30: White Oak | E30: Select | F30: - | J30: =VLOOKUP(A30,'[1]Current Pricing'!A$2:J$75,10,FALSE) -> 3.65 | M30: =VLOOKUP(A30,Merrick!$A$2:$G$46,7,FALSE) -> #N/A | S30: 1050 | AB30: 22 | AD30: 18 | AE30: 18
A31: RH2SOSNB-20 | B31: 1/2" | C31: 2" | D31: White Oak | E31: Select | F31: - | M31: =VLOOKUP(A31,Merrick!$A$2:$G$46,7,FALSE) -> #N/A | S31: 1050 | AB31: 22 | AD31: 18 | AE31: 18
A32: RH2SOSNB-24 | B32: 1/2" | C32: 2" | D32: White Oak | E32: Select | F32: - | K32: 3.55 | M32: =VLOOKUP(A32,Merrick!$A$2:$G$46,7,FALSE) -> #N/A | S32: 1050 | AB32: 22 | AD32: 18 | AE32: 18
A33: RH2SOSNB/ RH2SOSNB-20/ RH2SOSNB-24 | B33: 1/2" | C33: 2" | D33: White Oak | E33: Select | F33: - | J33: =VLOOKUP(A33,'[1]Current Pricing'!A$2:J$75,10,FALSE) -> 3.65 | K33: 3.55 | N33: 3.49 | S33: 1050 | AB33: 22 | AD33: 18 | AE33: 18
A34: RQ112SRSNB | B34: 3/4" | C34: 1-1/2" | D34: Red Oak | E34: Select | F34: - | H34: 3.4 | I34: 3.5 | J34: =VLOOKUP(A34,'[1]Current Pricing'!A$2:J$75,10,FALSE) -> 3.3 | M34: =VLOOKUP(A34,Merrick!$A$2:$G$46,7,FALSE) -> #N/A | S34: 1012.8 | AA34: 16 | AB34: 22 | AD34: 18 | AE34: 18 | AG34: 17
A35: RQ112SOSNB | B35: 3/4" | C35: 1-1/2" | D35: White Oak | E35: Select | F35: - | H35: 3.85 | I35: 4.5 | J35: =VLOOKUP(A35,'[1]Current Pricing'!A$2:J$75,10,FALSE) -> 4.3 | M35: =VLOOKUP(A35,Merrick!$A$2:$G$46,7,FALSE) -> #N/A | S35: 1012.8 | AA35: 16 | AB35: 22 | AD35: 18 | AE35: 18 | AG35: 17
A36: RQ214FMS | B36: 3/4" | C36: 2-1/4" | D36: Maple | E36: 1st/Select | F36: - | H36: 4.05 | L36: =M36 -> 2.05 | M36: =VLOOKUP(A36,Merrick!$A$2:$G$46,7,FALSE) -> 2.05 | R36: 864 | S36: 1012.8 | U36: 840 | V36: 840 | X36: 945.12 | AA36: 16 | AB36: 22 | AD36: 18 | AE36: 18 | AG36: 17
A37: RQ214SRSSP | B37: 3/4" | C37: 2-1/4" | D37: Red Oak | E37: Select | F37: - | H37: 2.7 | I37: 3.5 | J37: =VLOOKUP(A37,'[1]Current Pricing'!A$2:J$75,10,FALSE) -> 2.75 | L37: =M37 -> 2.68 | M37: =VLOOKUP(A37,Merrick!$A$2:$G$46,7,FALSE) -> 2.68 | O37: 2.9 | R37: 864 | S37: 1012.8 | U37: 840 | V37: 840 | X37: 945.12 | AA37: 16 | AB37: 22 | AD37: 18 | AE37: 18 | AG37: 17
A38: RQ214QOSSP | B38: 3/4" | C38: 2-1/4" | D38: White Oak | E38: Rift & Quarter | F38: - | H38: 4.7 | I38: 5.1 | J38: =VLOOKUP(A38,'[1]Current Pricing'!A$2:J$75,10,FALSE) -> 3.62 | L38: =M38 -> 3.45 | M38: =VLOOKUP(A38,Merrick!$A$2:$G$46,7,FALSE) -> 3.45 | O38: 2.9 | R38: 864 | S38: 1012.8 | U38: 840 | V38: 840 | X38: 945.12 | AA38: 16 | AB38: 22 | AD38: 18 | AE38: 18 | AG38: 17
A39: RQ214SOSSP | B39: 3/4" | C39: 2-1/4" | D39: White Oak | E39: Select & Better | F39: - | I39: 4.4 | M39: =VLOOKUP(A39,Merrick!$A$2:$G$46,7,FALSE) -> #N/A | R39: 864 | S39: 1012.8 | X39: 945.12 | AA39: 16 | AB39: 22 | AD39: 18 | AE39: 18 | AG39: 17
A40: RQ3SRB | B40: 3/4" | C40: 3" | D40: Red Oak | E40: - | F40: Bevel | I40: 3.4 | M40: =VLOOKUP(A40,Merrick!$A$2:$G$46,7,FALSE) -> #N/A | R40: 840 | S40: 1012.8 | AA40: 16 | AB40: 22 | AD40: 18 | AE40: 18 | AG40: 17
...

Sheet Stats

Sheet Merrick
A1: OMP Item Number | B1: Species | C1: Category | D1: Merrick Item Number | E1: Grade | F1: Width | G1: Price | I1: Last Updated | L1: ROSB214MH | M1: 2.68
A2: RQ214SRSSP | B2: Red Oak | C2: STRIP PRODUCTS | D2: ROSB214MH | E2: SEL/BTR | F2: 2 ¼" | G2: =VLOOKUP(D2,$L$1:$M$36,2,FALSE) -> 2.68 | I2: 5.1.2026 | L2: RO1C214MH | M2: 2.05
A3: RQ214FMS | B3: Red Oak | C3: STRIP PRODUCTS | D3: RO1C214MH | E3: 1 COM | F3: 2 ¼" | G3: =VLOOKUP(D3,$L$1:$M$36,2,FALSE) -> 2.05 | L3: RO2C214MH | M3: 1
A4: NONE | B4: Red Oak | C4: STRIP PRODUCTS | D4: RO2C214MH | E4: 2 COM | F4: 2 ¼" | G4: =VLOOKUP(D4,$L$1:$M$36,2,FALSE) -> 1 | L4: ROSB314MH | M4: 2.45
A5: RQ314SRSSP | B5: Red Oak | C5: STRIP PRODUCTS | D5: ROSB314MH | E5: SEL/BTR | F5: 3 ¼" | G5: =VLOOKUP(D5,$L$1:$M$36,2,FALSE) -> 2.45 | L5: RO1C314MH | M5: 1.9
A6: NONE | B6: Red Oak | C6: STRIP PRODUCTS | D6: RO1C314MH | E6: 1 COM | F6: 3 ¼" | G6: =VLOOKUP(D6,$L$1:$M$36,2,FALSE) -> 1.9 | L6: RO2C314MH | M6: 1.13
A7: NONE | B7: Red Oak | C7: STRIP PRODUCTS | D7: RO2C314MH | E7: 2 COM | F7: 3 ¼" | G7: =VLOOKUP(D7,$L$1:$M$36,2,FALSE) -> 1.13 | L7: WOSB214MH | M7: 3.45
A8: NONE | B8: Red Oak | C8: PLANK PRODUCTS | D8: Item | E8: Grade | F8: Width | G8: Price | L8: WO1C214MH | M8: 2.05
A9: RQ4SRS | B9: Red Oak | C9: PLANK PRODUCTS | D9: ROSB4MH | E9: SEL/BTR | F9: 4" | G9: =VLOOKUP(D9,$L$1:$M$36,2,FALSE) -> 2.45 | L9: WO2C214MH | M9: 0.9
A10: NONE | B10: Red Oak | C10: PLANK PRODUCTS | D10: RO1C4MH | E10: 1 COM | F10: 4" | G10: =VLOOKUP(D10,$L$1:$M$36,2,FALSE) -> 2 | L10: WOSB314MH | M10: 3.35
A11: NONE | B11: Red Oak | C11: PLANK PRODUCTS | D11: RO2C4MH | E11: 2 COM | F11: 4" | G11: =VLOOKUP(D11,$L$1:$M$36,2,FALSE) -> 1.2 | L11: WO1C314MH | M11: 2.45
A12: RQ5SRS | B12: Red Oak | C12: PLANK PRODUCTS | D12: ROSB5MH | E12: SEL/BTR | F12: 5" | G12: =VLOOKUP(D12,$L$1:$M$36,2,FALSE) -> 2.65 | L12: WO2C314MH | M12: 1.4
A13: NONE | B13: Red Oak | C13: PLANK PRODUCTS | D13: RO1C5MH | E13: 1 COM | F13: 5" | G13: =VLOOKUP(D13,$L$1:$M$36,2,FALSE) -> 2 | L13: WOMR314N | M13: 2
A14: NONE | B14: Red Oak | C14: PLANK PRODUCTS | D14: RO2C5MH | E14: 2 COM | F14: 5" | G14: =VLOOKUP(D14,$L$1:$M$36,2,FALSE) -> 1.4 | L14: HM1ST2SF | M14: 4.25
A15: NONE | B15: White Oak | C15: STRIP PRODUCTS | D15: Item | E15: Grade | F15: Width | G15: Price | L15: HM2B2SF | M15: 3.75
A16: RQ214QOSSP | B16: White Oak | C16: STRIP PRODUCTS | D16: WOSB214MH | E16: SEL/BTR | F16: 2 ¼" | G16: =VLOOKUP(D16,$L$1:$M$36,2,FALSE) -> 3.45 | L16: HM3D2SF | M16: 2.1
A17: NONE | B17: White Oak | C17: STRIP PRODUCTS | D17: WO1C214MH | E17: 1 COM | F17: 2 ¼" | G17: =VLOOKUP(D17,$L$1:$M$36,2,FALSE) -> 2.05 | L17: HIMR2N | M17: 1.8
A18: NONE | B18: White Oak | C18: STRIP PRODUCTS | D18: WO2C214MH | E18: 2 COM | F18: 2 ¼" | G18: =VLOOKUP(D18,$L$1:$M$36,2,FALSE) -> 0.9 | L18: HIMR314MH | M18: 3.7
A19: NONE | B19: White Oak | C19: STRIP PRODUCTS | L19: ROSB4MH | M19: 2.45
A20: NONE | B20: White Oak | C20: STRIP PRODUCTS | D20: WOSB314MH | E20: SEL/BTR | F20: 3 ¼" | G20: =VLOOKUP(D20,$L$1:$M$36,2,FALSE) -> 3.35 | L20: RO1C4MH | M20: 2
A21: NONE | B21: White Oak | C21: STRIP PRODUCTS | D21: WO1C314MH | E21: 1 COM | F21: 3 ¼" | G21: =VLOOKUP(D21,$L$1:$M$36,2,FALSE) -> 2.45 | L21: RO2C4MH | M21: 1.2
A22: NONE | B22: White Oak | C22: STRIP PRODUCTS | D22: WO2C314MH | E22: 2 COM | F22: 3 ¼" | G22: =VLOOKUP(D22,$L$1:$M$36,2,FALSE) -> 1.4 | L22: ROSB5MH | M22: 2.65
A23: NONE | B23: White Oak | C23: STRIP PRODUCTS | D23: WOMR314N | E23: MILL RUN | F23: 3 ¼" | G23: =VLOOKUP(D23,$L$1:$M$36,2,FALSE) -> 2 | L23: RO1C5MH | M23: 2
A24: NONE | B24: White Oak | C24: PLANK PRODUCTS | D24: Item | E24: Grade | F24: Width | G24: Price | L24: RO2C5MH | M24: 1.4
A25: RQ4SOS | B25: White Oak | C25: PLANK PRODUCTS | D25: WOSB4MH | E25: SEL/BTR | F25: 4" | G25: =VLOOKUP(D25,$L$1:$M$36,2,FALSE) -> 4.25 | L25: WOSB4MH | M25: 4.25
A26: NONE | B26: White Oak | C26: PLANK PRODUCTS | D26: WO1C4MH | E26: 1 COM | F26: 4" | G26: =VLOOKUP(D26,$L$1:$M$36,2,FALSE) -> 2.75 | L26: WO1C4MH | M26: 2.75
A27: NONE | B27: White Oak | C27: PLANK PRODUCTS | D27: WO2C4MH | E27: 2 COM | F27: 4" | G27: =VLOOKUP(D27,$L$1:$M$36,2,FALSE) -> 1.5 | L27: WO2C4MH | M27: 1.5
A28: NONE | B28: White Oak | C28: PLANK PRODUCTS | D28: WOMR4MH | E28: MILL RUN | F28: 4" | G28: =VLOOKUP(D28,$L$1:$M$36,2,FALSE) -> 2.8 | L28: WOMR4MH | M28: 2.8
A29: RQ5SOS | B29: White Oak | C29: PLANK PRODUCTS | D29: WOSB5MH | E29: SEL/BTR | F29: 5" | G29: =VLOOKUP(D29,$L$1:$M$36,2,FALSE) -> 4.65 | L29: WOSB5MH | M29: 4.65
A30: NONE | B30: White Oak | C30: PLANK PRODUCTS | D30: WO1C5MH | E30: 1 COM | F30: 5" | G30: =VLOOKUP(D30,$L$1:$M$36,2,FALSE) -> 3.1 | L30: WO1C5MH | M30: 3.1
A31: NONE | B31: White Oak | C31: PLANK PRODUCTS | D31: WO2C5MH | E31: 2 COM | F31: 5" | G31: =VLOOKUP(D31,$L$1:$M$36,2,FALSE) -> 1.9 | L31: WO2C5MH | M31: 1.9
A32: NONE | B32: White Oak | C32: PLANK PRODUCTS | D32: WOMR5MH | E32: MILL RUN | F32: 5" | L32: HM1ST314SF | M32: 4.25
A33: NONE | B33: Hard Maple | C33: 2 1/4" | D33: Item | E33: Grade | F33: Width | G33: Price | L33: HM2B314SF | M33: 2.75
A34: RQ214FMS | B34: Hard Maple | C34: 2 1/4" | D34: HM1ST2SF | E34: 1ST | F34: 2 ¼" | G34: =VLOOKUP(D34,$L$1:$M$36,2,FALSE) -> 4.25 | L34: HM3D314SF | M34: 1.8
A35: NONE | B35: Hard Maple | C35: 2 1/4" | D35: HM2B2SF | E35: 2ND & BTR | F35: 2 ¼" | G35: =VLOOKUP(D35,$L$1:$M$36,2,FALSE) -> 3.75 | L35: HIMR4MH | M35: 3.45
A36: NONE | B36: Hard Maple | C36: 2 1/4" | D36: HM3D2SF | E36: 3RD | F36: 2 ¼" | G36: =VLOOKUP(D36,$L$1:$M$36,2,FALSE) -> 2.1 | L36: HIMR5MH | M36: 3.5
A37: NONE | B37: Hard Maple | C37: 3 1/4" | D37: Item | E37: Grade | F37: Width | G37: Price
A38: RQ314FMS | B38: Hard Maple | C38: 3 1/4" | D38: HM1ST314SF | E38: 1ST | F38: 3 ¼" | G38: =VLOOKUP(D38,$L$1:$M$36,2,FALSE) -> 4.25
A39: NONE | B39: Hard Maple | C39: 3 1/4" | D39: HM2B314SF | E39: 2ND & BTR | F39: 3 ¼" | G39: =VLOOKUP(D39,$L$1:$M$36,2,FALSE) -> 2.75
A40: NONE | B40: Hard Maple | C40: 3 1/4" | D40: HM3D314SF | E40: 3RD | F40: 3 ¼" | G40: =VLOOKUP(D40,$L$1:$M$36,2,FALSE) -> 1.8
...

Sheet Freight
A1: Vendor | B1: Origin | C1: ST | D1: Destination | E1: ST | F1: Size | G1: Rate | H1: Pallets per Container | I1: 46143
A2: Merrick | B2: Burnside | C2: KY | D2: Van Nuys | E2: CA | F2: 40 | G2: 3325
A3: Yesteryear | B3: Campbellsville | C3: KY | D3: Van Nuys | E3: CA | F3: 40 | G3: 3125
A4: Ashawa Bay | B4: Cook | C4: MN | D4: Van Nuys | E4: CA | F4: 40 | G4: 3295
B5: Hortonville | C5: WI | D5: Van Nuys | E5: CA | F5: 40 | G5: 2450
A6: Lebanon | B6: Lebanon | C6: KY | D6: Van Nuys | E6: CA | F6: 40 | G6: 3325 | H6: 23
A7: Sheoga | B7: Middlefield | C7: OH | D7: Van Nuys | E7: CA | F7: 40 | G7: 2425
A8: Mullican | B8: Ronceverte | C8: WV | D8: Van Nuys | E8: CA | F8: 40 | G8: 3625 | H8: 18
A9: Indiana | B9: Spencer | C9: IN | D9: Van Nuys | E9: CA | F9: 40 | G9: 2625 | H9: 17
B10: Valparaiso | C10: IN | D10: Van Nuys | E10: CA | F10: 40 | G10: 2225 | H10: 17
A11: Macon | D11: Van Nuys | E11: CA | F11: 40 | G11: 0
A12: Dayspring | D12: Van Nuys | E12: CA | F12: 40 | G12: 0
A13: Orillia | B13: 107 Commerce Rd | C13: ON | D13: Orillia | E13: Canada | F13: ON L3V 0Z2 | G13: 5000
