Workbook

Sheet DashBoard
A1: Item | B1: Description | C1: 3 | D1: 4 | E1: 5 | F1: 6 | G1: 8 | H1: 9 | I1: Transfering Total
A2: ADDO091488 | B2: DAP ALEX PLUS CAULK W/SILICONE | C2: =SUMIFS('x2'!$I:$I, 'x2'!$A:$A, $A2, 'x2'!$D:$D, C$1) -> 0 | D2: =SUMIFS('x2'!$I:$I, 'x2'!$A:$A, $A2, 'x2'!$D:$D, D$1) -> 0 | E2: =SUMIFS('x2'!$I:$I, 'x2'!$A:$A, $A2, 'x2'!$D:$D, E$1) -> 7 | F2: =SUMIFS('x2'!$I:$I, 'x2'!$A:$A, $A2, 'x2'!$D:$D, F$1) -> 0 | G2: =SUMIFS('x2'!$I:$I, 'x2'!$A:$A, $A2, 'x2'!$D:$D, G$1) -> 0 | H2: =SUMIFS('x2'!$I:$I, 'x2'!$A:$A, $A2, 'x2'!$D:$D, H$1) -> 0 | I2: =SUM(C2:H2) -> 7
A3: BRFB2 | B3: 2" FOAM BRUSH | C3: =SUMIFS('x2'!$I:$I, 'x2'!$A:$A, $A3, 'x2'!$D:$D, C$1) -> 0 | D3: =SUMIFS('x2'!$I:$I, 'x2'!$A:$A, $A3, 'x2'!$D:$D, D$1) -> 0 | E3: =SUMIFS('x2'!$I:$I, 'x2'!$A:$A, $A3, 'x2'!$D:$D, E$1) -> 0 | F3: =SUMIFS('x2'!$I:$I, 'x2'!$A:$A, $A3, 'x2'!$D:$D, F$1) -> 0 | G3: =SUMIFS('x2'!$I:$I, 'x2'!$A:$A, $A3, 'x2'!$D:$D, G$1) -> 0 | H3: =SUMIFS('x2'!$I:$I, 'x2'!$A:$A, $A3, 'x2'!$D:$D, H$1) -> 1 | I3: =SUM(C3:H3) -> 1
A4: BRTA2 | B4: 2" THROWAWAY BRUSH | C4: =SUMIFS('x2'!$I:$I, 'x2'!$A:$A, $A4, 'x2'!$D:$D, C$1) -> 3 | D4: =SUMIFS('x2'!$I:$I, 'x2'!$A:$A, $A4, 'x2'!$D:$D, D$1) -> 0 | E4: =SUMIFS('x2'!$I:$I, 'x2'!$A:$A, $A4, 'x2'!$D:$D, E$1) -> 0 | F4: =SUMIFS('x2'!$I:$I, 'x2'!$A:$A, $A4, 'x2'!$D:$D, F$1) -> 0 | G4: =SUMIFS('x2'!$I:$I, 'x2'!$A:$A, $A4, 'x2'!$D:$D, G$1) -> 0 | H4: =SUMIFS('x2'!$I:$I, 'x2'!$A:$A, $A4, 'x2'!$D:$D, H$1) -> 0 | I4: =SUM(C4:H4) -> 3
A5: BRTA3 | B5: 3" THROWAWAY BRUSH | C5: =SUMIFS('x2'!$I:$I, 'x2'!$A:$A, $A5, 'x2'!$D:$D, C$1) -> 0 | D5: =SUMIFS('x2'!$I:$I, 'x2'!$A:$A, $A5, 'x2'!$D:$D, D$1) -> 0 | E5: =SUMIFS('x2'!$I:$I, 'x2'!$A:$A, $A5, 'x2'!$D:$D, E$1) -> 0 | F5: =SUMIFS('x2'!$I:$I, 'x2'!$A:$A, $A5, 'x2'!$D:$D, F$1) -> 11 | G5: =SUMIFS('x2'!$I:$I, 'x2'!$A:$A, $A5, 'x2'!$D:$D, G$1) -> 0 | H5: =SUMIFS('x2'!$I:$I, 'x2'!$A:$A, $A5, 'x2'!$D:$D, H$1) -> 0 | I5: =SUM(C5:H5) -> 11
A6: BRTA4 | B6: 4" THROWAWAY BRUSH | C6: =SUMIFS('x2'!$I:$I, 'x2'!$A:$A, $A6, 'x2'!$D:$D, C$1) -> 11 | D6: =SUMIFS('x2'!$I:$I, 'x2'!$A:$A, $A6, 'x2'!$D:$D, D$1) -> 0 | E6: =SUMIFS('x2'!$I:$I, 'x2'!$A:$A, $A6, 'x2'!$D:$D, E$1) -> 0 | F6: =SUMIFS('x2'!$I:$I, 'x2'!$A:$A, $A6, 'x2'!$D:$D, F$1) -> 0 | G6: =SUMIFS('x2'!$I:$I, 'x2'!$A:$A, $A6, 'x2'!$D:$D, G$1) -> 0 | H6: =SUMIFS('x2'!$I:$I, 'x2'!$A:$A, $A6, 'x2'!$D:$D, H$1) -> 0 | I6: =SUM(C6:H6) -> 11
A7: DAPCG537043 | B7: DAP CAULKING GUN SKELETON 9" | C7: =SUMIFS('x2'!$I:$I, 'x2'!$A:$A, $A7, 'x2'!$D:$D, C$1) -> 0 | D7: =SUMIFS('x2'!$I:$I, 'x2'!$A:$A, $A7, 'x2'!$D:$D, D$1) -> 0 | E7: =SUMIFS('x2'!$I:$I, 'x2'!$A:$A, $A7, 'x2'!$D:$D, E$1) -> 1 | F7: =SUMIFS('x2'!$I:$I, 'x2'!$A:$A, $A7, 'x2'!$D:$D, F$1) -> 0 | G7: =SUMIFS('x2'!$I:$I, 'x2'!$A:$A, $A7, 'x2'!$D:$D, G$1) -> 0 | H7: =SUMIFS('x2'!$I:$I, 'x2'!$A:$A, $A7, 'x2'!$D:$D, H$1) -> 0 | I7: =SUM(C7:H7) -> 1
A8: WPCA20096M | B8: 6' WOOD POLE METAL TIP | C8: =SUMIFS('x2'!$I:$I, 'x2'!$A:$A, $A8, 'x2'!$D:$D, C$1) -> 2 | D8: =SUMIFS('x2'!$I:$I, 'x2'!$A:$A, $A8, 'x2'!$D:$D, D$1) -> 0 | E8: =SUMIFS('x2'!$I:$I, 'x2'!$A:$A, $A8, 'x2'!$D:$D, E$1) -> 0 | F8: =SUMIFS('x2'!$I:$I, 'x2'!$A:$A, $A8, 'x2'!$D:$D, F$1) -> 0 | G8: =SUMIFS('x2'!$I:$I, 'x2'!$A:$A, $A8, 'x2'!$D:$D, G$1) -> 0 | H8: =SUMIFS('x2'!$I:$I, 'x2'!$A:$A, $A8, 'x2'!$D:$D, H$1) -> 0 | I8: =SUM(C8:H8) -> 2
A9: FIWT63281 | B9: WATCO SPRAY CLEAR SATIN | C9: =SUMIFS('x2'!$I:$I, 'x2'!$A:$A, $A9, 'x2'!$D:$D, C$1) -> 0 | D9: =SUMIFS('x2'!$I:$I, 'x2'!$A:$A, $A9, 'x2'!$D:$D, D$1) -> 4 | E9: =SUMIFS('x2'!$I:$I, 'x2'!$A:$A, $A9, 'x2'!$D:$D, E$1) -> 0 | F9: =SUMIFS('x2'!$I:$I, 'x2'!$A:$A, $A9, 'x2'!$D:$D, F$1) -> 0 | G9: =SUMIFS('x2'!$I:$I, 'x2'!$A:$A, $A9, 'x2'!$D:$D, G$1) -> 0 | H9: =SUMIFS('x2'!$I:$I, 'x2'!$A:$A, $A9, 'x2'!$D:$D, H$1) -> 0 | I9: =SUM(C9:H9) -> 4
A10: ARPU350769 | B10: PURDY 9" WHITE DOVE 3/8" NAP | C10: =SUMIFS('x2'!$I:$I, 'x2'!$A:$A, $A10, 'x2'!$D:$D, C$1) -> 0 | D10: =SUMIFS('x2'!$I:$I, 'x2'!$A:$A, $A10, 'x2'!$D:$D, D$1) -> 0 | E10: =SUMIFS('x2'!$I:$I, 'x2'!$A:$A, $A10, 'x2'!$D:$D, E$1) -> 5 | F10: =SUMIFS('x2'!$I:$I, 'x2'!$A:$A, $A10, 'x2'!$D:$D, F$1) -> 0 | G10: =SUMIFS('x2'!$I:$I, 'x2'!$A:$A, $A10, 'x2'!$D:$D, G$1) -> 0 | H10: =SUMIFS('x2'!$I:$I, 'x2'!$A:$A, $A10, 'x2'!$D:$D, H$1) -> 0 | I10: =SUM(C10:H10) -> 5
C11: =SUMIFS('x2'!$I:$I, 'x2'!$A:$A, $A11, 'x2'!$D:$D, C$1) -> 0 | D11: =SUMIFS('x2'!$I:$I, 'x2'!$A:$A, $A11, 'x2'!$D:$D, D$1) -> 0 | E11: =SUMIFS('x2'!$I:$I, 'x2'!$A:$A, $A11, 'x2'!$D:$D, E$1) -> 0 | F11: =SUMIFS('x2'!$I:$I, 'x2'!$A:$A, $A11, 'x2'!$D:$D, F$1) -> 0 | G11: =SUMIFS('x2'!$I:$I, 'x2'!$A:$A, $A11, 'x2'!$D:$D, G$1) -> 0 | H11: =SUMIFS('x2'!$I:$I, 'x2'!$A:$A, $A11, 'x2'!$D:$D, H$1) -> 0 | I11: =SUM(C11:H11) -> 0
C12: =SUMIFS('x2'!$I:$I, 'x2'!$A:$A, $A12, 'x2'!$D:$D, C$1) -> 0 | D12: =SUMIFS('x2'!$I:$I, 'x2'!$A:$A, $A12, 'x2'!$D:$D, D$1) -> 0 | E12: =SUMIFS('x2'!$I:$I, 'x2'!$A:$A, $A12, 'x2'!$D:$D, E$1) -> 0 | F12: =SUMIFS('x2'!$I:$I, 'x2'!$A:$A, $A12, 'x2'!$D:$D, F$1) -> 0 | G12: =SUMIFS('x2'!$I:$I, 'x2'!$A:$A, $A12, 'x2'!$D:$D, G$1) -> 0 | H12: =SUMIFS('x2'!$I:$I, 'x2'!$A:$A, $A12, 'x2'!$D:$D, H$1) -> 0 | I12: =SUM(C12:H12) -> 0
C13: =SUMIFS('x2'!$I:$I, 'x2'!$A:$A, $A13, 'x2'!$D:$D, C$1) -> 0 | D13: =SUMIFS('x2'!$I:$I, 'x2'!$A:$A, $A13, 'x2'!$D:$D, D$1) -> 0 | E13: =SUMIFS('x2'!$I:$I, 'x2'!$A:$A, $A13, 'x2'!$D:$D, E$1) -> 0 | F13: =SUMIFS('x2'!$I:$I, 'x2'!$A:$A, $A13, 'x2'!$D:$D, F$1) -> 0 | G13: =SUMIFS('x2'!$I:$I, 'x2'!$A:$A, $A13, 'x2'!$D:$D, G$1) -> 0 | H13: =SUMIFS('x2'!$I:$I, 'x2'!$A:$A, $A13, 'x2'!$D:$D, H$1) -> 0 | I13: =SUM(C13:H13) -> 0
I14: =SUM(C14:H14) -> 0
I15: =SUM(C15:H15) -> 0
I16: =SUM(C16:H16) -> 0
I17: =SUM(C17:H17) -> 0
I18: =SUM(C18:H18) -> 0
I19: =SUM(C19:H19) -> 0
I20: =SUM(C20:H20) -> 0
I21: =SUM(C21:H21) -> 0
I22: =SUM(C22:H22) -> 0
I23: =SUM(C23:H23) -> 0
I24: =SUM(C24:H24) -> 0
I25: =SUM(C25:H25) -> 0
... I157: =SUM(C157:H157) -> 0

Sheet Robertson
A1: =IF(B1<>"","1","") -> 1 | B1: From 01 to 03 | C1: Roberson | D1: ST3
A2: =IF(B2<>"","1","") | B2: =IF(DashBoard!C2<>0,DashBoard!A2,"") | C2: =IF(DashBoard!C2<>0,DashBoard!B2,"") | D2: =IF(DashBoard!C2<>0,DashBoard!C2,"")
A3: =IF(B3<>"","1","") | B3: =IF(DashBoard!C3<>0,DashBoard!A3,"") | C3: =IF(DashBoard!C3<>0,DashBoard!B3,"") | D3: =IF(DashBoard!C3<>0,DashBoard!C3,"")
A4: =IF(B4<>"","1","") -> 1 | B4: =IF(DashBoard!C4<>0,DashBoard!A4,"") -> BRTA2 | C4: =IF(DashBoard!C4<>0,DashBoard!B4,"") -> 2" THROWAWAY BRUSH | D4: =IF(DashBoard!C4<>0,DashBoard!C4,"") -> 3
A5: =IF(B5<>"","1","") | B5: =IF(DashBoard!C5<>0,DashBoard!A5,"") | C5: =IF(DashBoard!C5<>0,DashBoard!B5,"") | D5: =IF(DashBoard!C5<>0,DashBoard!C5,"")
A6: =IF(B6<>"","1","") -> 1 | B6: =IF(DashBoard!C6<>0,DashBoard!A6,"") -> BRTA4 | C6: =IF(DashBoard!C6<>0,DashBoard!B6,"") -> 4" THROWAWAY BRUSH | D6: =IF(DashBoard!C6<>0,DashBoard!C6,"") -> 11
A7: =IF(B7<>"","1","") | B7: =IF(DashBoard!C7<>0,DashBoard!A7,"") | C7: =IF(DashBoard!C7<>0,DashBoard!B7,"") | D7: =IF(DashBoard!C7<>0,DashBoard!C7,"")
A8: =IF(B8<>"","1","") -> 1 | B8: =IF(DashBoard!C8<>0,DashBoard!A8,"") -> WPCA20096M | C8: =IF(DashBoard!C8<>0,DashBoard!B8,"") -> 6' WOOD POLE METAL TIP | D8: =IF(DashBoard!C8<>0,DashBoard!C8,"") -> 2
A9: =IF(B9<>"","1","") | B9: =IF(DashBoard!C9<>0,DashBoard!A9,"") | C9: =IF(DashBoard!C9<>0,DashBoard!B9,"") | D9: =IF(DashBoard!C9<>0,DashBoard!C9,"")
A10: =IF(B10<>"","1","") | B10: =IF(DashBoard!C10<>0,DashBoard!A10,"") | C10: =IF(DashBoard!C10<>0,DashBoard!B10,"") | D10: =IF(DashBoard!C10<>0,DashBoard!C10,"")
A11: =IF(B11<>"","1","") | B11: =IF(DashBoard!C11<>0,DashBoard!A11,"") | C11: =IF(DashBoard!C11<>0,DashBoard!B11,"") | D11: =IF(DashBoard!C11<>0,DashBoard!C11,"")
A12: =IF(B12<>"","1","") | B12: =IF(DashBoard!C12<>0,DashBoard!A12,"") | C12: =IF(DashBoard!C12<>0,DashBoard!B12,"") | D12: =IF(DashBoard!C12<>0,DashBoard!C12,"")
A13: =IF(B13<>"","1","") | B13: =IF(DashBoard!C13<>0,DashBoard!A13,"") | C13: =IF(DashBoard!C13<>0,DashBoard!B13,"") | D13: =IF(DashBoard!C13<>0,DashBoard!C13,"")
... A48: =IF(B48<>"","1","") | B48: =IF(DashBoard!C48<>0,DashBoard!A48,"") | C48: =IF(DashBoard!C48<>0,DashBoard!B48,"") | D48: =IF(DashBoard!C48<>0,DashBoard!C48,"")
A49: =IF(B49<>"","1","") | C49: =IF(DashBoard!C49<>0,DashBoard!B49,"") | D49: =IF(DashBoard!C49<>0,DashBoard!C49,"")
A50: =IF(B50<>"","1","") | C50: =IF(DashBoard!C50<>0,DashBoard!B50,"") | D50: =IF(DashBoard!C50<>0,DashBoard!C50,"")
A51: =IF(B51<>"","1","") | B51: =IF(DashBoard!C51<>0,DashBoard!A51,"") | C51: =IF(DashBoard!C51<>0,DashBoard!B51,"") | D51: =IF(DashBoard!C51<>0,DashBoard!C51,"")
A52: =IF(B52<>"","1","") | B52: =IF(DashBoard!C52<>0,DashBoard!A52,"") | C52: =IF(DashBoard!C52<>0,DashBoard!B52,"") | D52: =IF(DashBoard!C52<>0,DashBoard!C52,"")
A53: =IF(B53<>"","1","") | B53: =IF(DashBoard!C53<>0,DashBoard!A53,"") | C53: =IF(DashBoard!C53<>0,DashBoard!B53,"") | D53: =IF(DashBoard!C53<>0,DashBoard!C53,"")
A54: =IF(B54<>"","1","") | B54: =IF(DashBoard!C54<>0,DashBoard!A54,"") | C54: =IF(DashBoard!C54<>0,DashBoard!B54,"") | D54: =IF(DashBoard!C54<>0,DashBoard!C54,"")
A55: =IF(B55<>"","1","") | B55: =IF(DashBoard!C55<>0,DashBoard!A55,"") | C55: =IF(DashBoard!C55<>0,DashBoard!B55,"") | D55: =IF(DashBoard!C55<>0,DashBoard!C55,"")
A56: =IF(B56<>"","1","") | B56: =IF(DashBoard!C56<>0,DashBoard!A56,"") | C56: =IF(DashBoard!C56<>0,DashBoard!B56,"") | D56: =IF(DashBoard!C56<>0,DashBoard!C56,"")
A57: =IF(B57<>"","1","") | B57: =IF(DashBoard!C57<>0,DashBoard!A57,"") | C57: =IF(DashBoard!C57<>0,DashBoard!B57,"") | D57: =IF(DashBoard!C57<>0,DashBoard!C57,"")
A58: =IF(B58<>"","1","") | B58: =IF(DashBoard!C58<>0,DashBoard!A58,"") | C58: =IF(DashBoard!C58<>0,DashBoard!B58,"") | D58: =IF(DashBoard!C58<>0,DashBoard!C58,"")
A59: =IF(B59<>"","1","") | B59: =IF(DashBoard!C59<>0,DashBoard!A59,"") | C59: =IF(DashBoard!C59<>0,DashBoard!B59,"") | D59: =IF(DashBoard!C59<>0,DashBoard!C59,"")
A60: =IF(B60<>"","1","") | B60: =IF(DashBoard!C60<>0,DashBoard!A60,"") | C60: =IF(DashBoard!C60<>0,DashBoard!B60,"") | D60: =IF(DashBoard!C60<>0,DashBoard!C60,"")
A61: =IF(B61<>"","1","") | B61: =IF(DashBoard!C61<>0,DashBoard!A61,"") | C61: =IF(DashBoard!C61<>0,DashBoard!B61,"") | D61: =IF(DashBoard!C61<>0,DashBoard!C61,"")
A62: =IF(B62<>"","1","") | B62: =IF(DashBoard!C62<>0,DashBoard!A62,"") | C62: =IF(DashBoard!C62<>0,DashBoard!B62,"") | D62: =IF(DashBoard!C62<>0,DashBoard!C62,"")
... A165: =IF(B165<>"","1","") | B165: =IF(DashBoard!C165<>0,DashBoard!A165,"") | C165: =IF(DashBoard!C165<>0,DashBoard!B165,"") | D165: =IF(DashBoard!C165<>0,DashBoard!C165,"")
A166: =IF(B166<>"","1","") -> #REF! | B166: =IF(DashBoard!#REF!<>0,DashBoard!#REF!,"") -> #REF! | C166: =IF(DashBoard!#REF!<>0,DashBoard!#REF!,"") -> #REF! | D166: =IF(DashBoard!#REF!<>0,DashBoard!#REF!,"") -> #REF!
A167: =IF(B167<>"","1","") -> #REF! | B167: =IF(DashBoard!#REF!<>0,DashBoard!#REF!,"") -> #REF! | C167: =IF(DashBoard!#REF!<>0,DashBoard!#REF!,"") -> #REF! | D167: =IF(DashBoard!#REF!<>0,DashBoard!#REF!,"") -> #REF!
A168: =IF(B168<>"","1","") -> #REF! | B168: =IF(DashBoard!#REF!<>0,DashBoard!#REF!,"") -> #REF! | C168: =IF(DashBoard!#REF!<>0,DashBoard!#REF!,"") -> #REF! | D168: =IF(DashBoard!#REF!<>0,DashBoard!#REF!,"") -> #REF!
A169: =IF(B169<>"","1","") -> #REF! | B169: =IF(DashBoard!#REF!<>0,DashBoard!#REF!,"") -> #REF! | C169: =IF(DashBoard!#REF!<>0,DashBoard!#REF!,"") -> #REF! | D169: =IF(DashBoard!#REF!<>0,DashBoard!#REF!,"") -> #REF!
A170: =IF(B170<>"","1","") -> #REF! | B170: =IF(DashBoard!#REF!<>0,DashBoard!#REF!,"") -> #REF! | C170: =IF(DashBoard!#REF!<>0,DashBoard!#REF!,"") -> #REF! | D170: =IF(DashBoard!#REF!<>0,DashBoard!#REF!,"") -> #REF!
A171: =IF(B171<>"","1","") -> #REF! | B171: =IF(DashBoard!#REF!<>0,DashBoard!#REF!,"") -> #REF! | C171: =IF(DashBoard!#REF!<>0,DashBoard!#REF!,"") -> #REF! | D171: =IF(DashBoard!#REF!<>0,DashBoard!#REF!,"") -> #REF!
A172: =IF(B172<>"","1","") -> #REF! | B172: =IF(DashBoard!#REF!<>0,DashBoard!#REF!,"") -> #REF! | C172: =IF(DashBoard!#REF!<>0,DashBoard!#REF!,"") -> #REF! | D172: =IF(DashBoard!#REF!<>0,DashBoard!#REF!,"") -> #REF!
A173: =IF(B173<>"","1","") -> #REF! | B173: =IF(DashBoard!#REF!<>0,DashBoard!#REF!,"") -> #REF! | C173: =IF(DashBoard!#REF!<>0,DashBoard!#REF!,"") -> #REF! | D173: =IF(DashBoard!#REF!<>0,DashBoard!#REF!,"") -> #REF!
A174: =IF(B174<>"","1","") -> #REF! | B174: =IF(DashBoard!#REF!<>0,DashBoard!#REF!,"") -> #REF! | C174: =IF(DashBoard!#REF!<>0,DashBoard!#REF!,"") -> #REF! | D174: =IF(DashBoard!#REF!<>0,DashBoard!#REF!,"") -> #REF!
A175: =IF(B175<>"","1","") -> #REF! | B175: =IF(DashBoard!#REF!<>0,DashBoard!#REF!,"") -> #REF! | C175: =IF(DashBoard!#REF!<>0,DashBoard!#REF!,"") -> #REF! | D175: =IF(DashBoard!#REF!<>0,DashBoard!#REF!,"") -> #REF!
A176: =IF(B176<>"","1","") -> #REF! | B176: =IF(DashBoard!#REF!<>0,DashBoard!#REF!,"") -> #REF! | C176: =IF(DashBoard!#REF!<>0,DashBoard!#REF!,"") -> #REF! | D176: =IF(DashBoard!#REF!<>0,DashBoard!#REF!,"") -> #REF!
...

Sheet Gardena
A1: =IF(B1<>"","1","") -> 1 | B1: From 01 to 04 | C1: Gardena | D1: ST4
A2: =IF(B2<>"","1","") | B2: =IF(DashBoard!D2<>0,DashBoard!A2,"") | C2: =IF(DashBoard!D2<>0,DashBoard!B2,"") | D2: =IF(DashBoard!D2<>0,DashBoard!D2,"")
A3: =IF(B3<>"","1","") | B3: =IF(DashBoard!D3<>0,DashBoard!A3,"") | C3: =IF(DashBoard!D3<>0,DashBoard!B3,"") | D3: =IF(DashBoard!D3<>0,DashBoard!D3,"")
A4: =IF(B4<>"","1","") | B4: =IF(DashBoard!D4<>0,DashBoard!A4,"") | C4: =IF(DashBoard!D4<>0,DashBoard!B4,"") | D4: =IF(DashBoard!D4<>0,DashBoard!D4,"")
A5: =IF(B5<>"","1","") | B5: =IF(DashBoard!D5<>0,DashBoard!A5,"") | C5: =IF(DashBoard!D5<>0,DashBoard!B5,"") | D5: =IF(DashBoard!D5<>0,DashBoard!D5,"")
A6: =IF(B6<>"","1","") | B6: =IF(DashBoard!D6<>0,DashBoard!A6,"") | C6: =IF(DashBoard!D6<>0,DashBoard!B6,"") | D6: =IF(DashBoard!D6<>0,DashBoard!D6,"")
A7: =IF(B7<>"","1","") | B7: =IF(DashBoard!D7<>0,DashBoard!A7,"") | C7: =IF(DashBoard!D7<>0,DashBoard!B7,"") | D7: =IF(DashBoard!D7<>0,DashBoard!D7,"")
A8: =IF(B8<>"","1","") | B8: =IF(DashBoard!D8<>0,DashBoard!A8,"") | C8: =IF(DashBoard!D8<>0,DashBoard!B8,"") | D8: =IF(DashBoard!D8<>0,DashBoard!D8,"")
A9: =IF(B9<>"","1","") -> 1 | B9: =IF(DashBoard!D9<>0,DashBoard!A9,"") -> FIWT63281 | C9: =IF(DashBoard!D9<>0,DashBoard!B9,"") -> WATCO SPRAY CLEAR SATIN | D9: =IF(DashBoard!D9<>0,DashBoard!D9,"") -> 4
A10: =IF(B10<>"","1","") | B10: =IF(DashBoard!D10<>0,DashBoard!A10,"") | C10: =IF(DashBoard!D10<>0,DashBoard!B10,"") | D10: =IF(DashBoard!D10<>0,DashBoard!D10,"")
A11: =IF(B11<>"","1","") | B11: =IF(DashBoard!D11<>0,DashBoard!A11,"") | C11: =IF(DashBoard!D11<>0,DashBoard!B11,"") | D11: =IF(DashBoard!D11<>0,DashBoard!D11,"")
A12: =IF(B12<>"","1","") | B12: =IF(DashBoard!D12<>0,DashBoard!A12,"") | C12: =IF(DashBoard!D12<>0,DashBoard!B12,"") | D12: =IF(DashBoard!D12<>0,DashBoard!D12,"")
A13: =IF(B13<>"","1","") | B13: =IF(DashBoard!D13<>0,DashBoard!A13,"") | C13: =IF(DashBoard!D13<>0,DashBoard!B13,"") | D13: =IF(DashBoard!D13<>0,DashBoard!D13,"")
... A137: =IF(B137<>"","1","") | B137: =IF(DashBoard!D137<>0,DashBoard!A137,"") | C137: =IF(DashBoard!D137<>0,DashBoard!B137,"") | D137: =IF(DashBoard!D137<>0,DashBoard!D137,"")
B138: =IF(DashBoard!D138<>0,DashBoard!A138,"") | C138: =IF(DashBoard!D138<>0,DashBoard!B138,"") | D138: =IF(DashBoard!D138<>0,DashBoard!D138,"")
B139: =IF(DashBoard!D139<>0,DashBoard!A139,"") | C139: =IF(DashBoard!D139<>0,DashBoard!B139,"") | D139: =IF(DashBoard!D139<>0,DashBoard!D139,"")
B140: =IF(DashBoard!D140<>0,DashBoard!A140,"") | C140: =IF(DashBoard!D140<>0,DashBoard!B140,"") | D140: =IF(DashBoard!D140<>0,DashBoard!D140,"")
B141: =IF(DashBoard!D141<>0,DashBoard!A141,"") | C141: =IF(DashBoard!D141<>0,DashBoard!B141,"") | D141: =IF(DashBoard!D141<>0,DashBoard!D141,"")
B142: =IF(DashBoard!D142<>0,DashBoard!A142,"") | C142: =IF(DashBoard!D142<>0,DashBoard!B142,"") | D142: =IF(DashBoard!D142<>0,DashBoard!D142,"")
B143: =IF(DashBoard!D143<>0,DashBoard!A143,"") | C143: =IF(DashBoard!D143<>0,DashBoard!B143,"") | D143: =IF(DashBoard!D143<>0,DashBoard!D143,"")
B144: =IF(DashBoard!D144<>0,DashBoard!A144,"") | C144: =IF(DashBoard!D144<>0,DashBoard!B144,"") | D144: =IF(DashBoard!D144<>0,DashBoard!D144,"")
B145: =IF(DashBoard!D145<>0,DashBoard!A145,"") | C145: =IF(DashBoard!D145<>0,DashBoard!B145,"") | D145: =IF(DashBoard!D145<>0,DashBoard!D145,"")
B146: =IF(DashBoard!D146<>0,DashBoard!A146,"") | C146: =IF(DashBoard!D146<>0,DashBoard!B146,"") | D146: =IF(DashBoard!D146<>0,DashBoard!D146,"")
B147: =IF(DashBoard!D147<>0,DashBoard!A147,"") | C147: =IF(DashBoard!D147<>0,DashBoard!B147,"") | D147: =IF(DashBoard!D147<>0,DashBoard!D147,"")
B148: =IF(DashBoard!D148<>0,DashBoard!A148,"") | C148: =IF(DashBoard!D148<>0,DashBoard!B148,"") | D148: =IF(DashBoard!D148<>0,DashBoard!D148,"")
B149: =IF(DashBoard!D149<>0,DashBoard!A149,"") | C149: =IF(DashBoard!D149<>0,DashBoard!B149,"") | D149: =IF(DashBoard!D149<>0,DashBoard!D149,"")
... B165: =IF(DashBoard!D165<>0,DashBoard!A165,"") | C165: =IF(DashBoard!D165<>0,DashBoard!B165,"") | D165: =IF(DashBoard!D165<>0,DashBoard!D165,"")
B166: =IF(DashBoard!#REF!<>0,DashBoard!#REF!,"") -> #REF! | C166: =IF(DashBoard!#REF!<>0,DashBoard!#REF!,"") -> #REF! | D166: =IF(DashBoard!#REF!<>0,DashBoard!#REF!,"") -> #REF!
B167: =IF(DashBoard!#REF!<>0,DashBoard!#REF!,"") -> #REF! | C167: =IF(DashBoard!#REF!<>0,DashBoard!#REF!,"") -> #REF! | D167: =IF(DashBoard!#REF!<>0,DashBoard!#REF!,"") -> #REF!
B168: =IF(DashBoard!#REF!<>0,DashBoard!#REF!,"") -> #REF! | C168: =IF(DashBoard!#REF!<>0,DashBoard!#REF!,"") -> #REF! | D168: =IF(DashBoard!#REF!<>0,DashBoard!#REF!,"") -> #REF!
B169: =IF(DashBoard!#REF!<>0,DashBoard!#REF!,"") -> #REF! | C169: =IF(DashBoard!#REF!<>0,DashBoard!#REF!,"") -> #REF! | D169: =IF(DashBoard!#REF!<>0,DashBoard!#REF!,"") -> #REF!
B170: =IF(DashBoard!#REF!<>0,DashBoard!#REF!,"") -> #REF! | C170: =IF(DashBoard!#REF!<>0,DashBoard!#REF!,"") -> #REF! | D170: =IF(DashBoard!#REF!<>0,DashBoard!#REF!,"") -> #REF!
B171: =IF(DashBoard!#REF!<>0,DashBoard!#REF!,"") -> #REF! | C171: =IF(DashBoard!#REF!<>0,DashBoard!#REF!,"") -> #REF! | D171: =IF(DashBoard!#REF!<>0,DashBoard!#REF!,"") -> #REF!
B172: =IF(DashBoard!#REF!<>0,DashBoard!#REF!,"") -> #REF! | C172: =IF(DashBoard!#REF!<>0,DashBoard!#REF!,"") -> #REF! | D172: =IF(DashBoard!#REF!<>0,DashBoard!#REF!,"") -> #REF!
B173: =IF(DashBoard!#REF!<>0,DashBoard!#REF!,"") -> #REF! | C173: =IF(DashBoard!#REF!<>0,DashBoard!#REF!,"") -> #REF! | D173: =IF(DashBoard!#REF!<>0,DashBoard!#REF!,"") -> #REF!
B174: =IF(DashBoard!#REF!<>0,DashBoard!#REF!,"") -> #REF! | C174: =IF(DashBoard!#REF!<>0,DashBoard!#REF!,"") -> #REF! | D174: =IF(DashBoard!#REF!<>0,DashBoard!#REF!,"") -> #REF!
B175: =IF(DashBoard!#REF!<>0,DashBoard!#REF!,"") -> #REF! | C175: =IF(DashBoard!#REF!<>0,DashBoard!#REF!,"") -> #REF! | D175: =IF(DashBoard!#REF!<>0,DashBoard!#REF!,"") -> #REF!
B176: =IF(DashBoard!#REF!<>0,DashBoard!#REF!,"") -> #REF! | C176: =IF(DashBoard!#REF!<>0,DashBoard!#REF!,"") -> #REF! | D176: =IF(DashBoard!#REF!<>0,DashBoard!#REF!,"") -> #REF!
B177: =IF(DashBoard!#REF!<>0,DashBoard!#REF!,"") -> #REF! | C177: =IF(DashBoard!#REF!<>0,DashBoard!#REF!,"") -> #REF! | D177: =IF(DashBoard!#REF!<>0,DashBoard!#REF!,"") -> #REF!
... B248: =IF(DashBoard!#REF!<>0,DashBoard!#REF!,"") -> #REF! | C248: =IF(DashBoard!#REF!<>0,DashBoard!#REF!,"") -> #REF! | D248: =IF(DashBoard!#REF!<>0,DashBoard!#REF!,"") -> #REF!
...

Sheet San Diego
A1: =IF(B1<>"","1","") -> 1 | B1: From 01 to 05 | C1: San Diego | D1: ST5
A2: =IF(B2<>"","1","") -> 1 | B2: =IF(DashBoard!E2<>0,DashBoard!A2,"") -> ADDO091488 | C2: =IF(DashBoard!E2<>0,DashBoard!B2,"") -> DAP ALEX PLUS CAULK W/SILICONE | D2: =IF(DashBoard!E2<>0,DashBoard!E2,"") -> 7
A3: =IF(B3<>"","1","") | B3: =IF(DashBoard!E3<>0,DashBoard!A3,"") | C3: =IF(DashBoard!E3<>0,DashBoard!B3,"") | D3: =IF(DashBoard!E3<>0,DashBoard!E3,"")
A4: =IF(B4<>"","1","") | B4: =IF(DashBoard!E4<>0,DashBoard!A4,"") | C4: =IF(DashBoard!E4<>0,DashBoard!B4,"") | D4: =IF(DashBoard!E4<>0,DashBoard!E4,"")
A5: =IF(B5<>"","1","") | B5: =IF(DashBoard!E5<>0,DashBoard!A5,"") | C5: =IF(DashBoard!E5<>0,DashBoard!B5,"") | D5: =IF(DashBoard!E5<>0,DashBoard!E5,"")
A6: =IF(B6<>"","1","") | B6: =IF(DashBoard!E6<>0,DashBoard!A6,"") | C6: =IF(DashBoard!E6<>0,DashBoard!B6,"") | D6: =IF(DashBoard!E6<>0,DashBoard!E6,"")
A7: =IF(B7<>"","1","") -> 1 | B7: =IF(DashBoard!E7<>0,DashBoard!A7,"") -> DAPCG537043 | C7: =IF(DashBoard!E7<>0,DashBoard!B7,"") -> DAP CAULKING GUN SKELETON 9" | D7: =IF(DashBoard!E7<>0,DashBoard!E7,"") -> 1
A8: =IF(B8<>"","1","") | B8: =IF(DashBoard!E8<>0,DashBoard!A8,"") | C8: =IF(DashBoard!E8<>0,DashBoard!B8,"") | D8: =IF(DashBoard!E8<>0,DashBoard!E8,"")
A9: =IF(B9<>"","1","") | B9: =IF(DashBoard!E9<>0,DashBoard!A9,"") | C9: =IF(DashBoard!E9<>0,DashBoard!B9,"") | D9: =IF(DashBoard!E9<>0,DashBoard!E9,"")
A10: =IF(B10<>"","1","") -> 1 | B10: =IF(DashBoard!E10<>0,DashBoard!A10,"") -> ARPU350769 | C10: =IF(DashBoard!E10<>0,DashBoard!B10,"") -> PURDY 9" WHITE DOVE 3/8" NAP | D10: =IF(DashBoard!E10<>0,DashBoard!E10,"") -> 5
A11: =IF(B11<>"","1","") | B11: =IF(DashBoard!E11<>0,DashBoard!A11,"") | C11: =IF(DashBoard!E11<>0,DashBoard!B11,"") | D11: =IF(DashBoard!E11<>0,DashBoard!E11,"")
A12: =IF(B12<>"","1","") | B12: =IF(DashBoard!E12<>0,DashBoard!A12,"") | C12: =IF(DashBoard!E12<>0,DashBoard!B12,"") | D12: =IF(DashBoard!E12<>0,DashBoard!E12,"")
A13: =IF(B13<>"","1","") | B13: =IF(DashBoard!E13<>0,DashBoard!A13,"") | C13: =IF(DashBoard!E13<>0,DashBoard!B13,"") | D13: =IF(DashBoard!E13<>0,DashBoard!E13,"")
... A150: =IF(B150<>"","1","") | B150: =IF(DashBoard!E150<>0,DashBoard!A150,"") | C150: =IF(DashBoard!E150<>0,DashBoard!B150,"") | D150: =IF(DashBoard!E150<>0,DashBoard!E150,"")
B151: =IF(DashBoard!E151<>0,DashBoard!A151,"") | C151: =IF(DashBoard!E151<>0,DashBoard!B151,"") | D151: =IF(DashBoard!E151<>0,DashBoard!E151,"")
B152: =IF(DashBoard!E152<>0,DashBoard!A152,"") | C152: =IF(DashBoard!E152<>0,DashBoard!B152,"") | D152: =IF(DashBoard!E152<>0,DashBoard!E152,"")
B153: =IF(DashBoard!E153<>0,DashBoard!A153,"") | C153: =IF(DashBoard!E153<>0,DashBoard!B153,"") | D153: =IF(DashBoard!E153<>0,DashBoard!E153,"")
B154: =IF(DashBoard!E154<>0,DashBoard!A154,"") | C154: =IF(DashBoard!E154<>0,DashBoard!B154,"") | D154: =IF(DashBoard!E154<>0,DashBoard!E154,"")
B155: =IF(DashBoard!E155<>0,DashBoard!A155,"") | C155: =IF(DashBoard!E155<>0,DashBoard!B155,"") | D155: =IF(DashBoard!E155<>0,DashBoard!E155,"")
B156: =IF(DashBoard!E156<>0,DashBoard!A156,"") | C156: =IF(DashBoard!E156<>0,DashBoard!B156,"") | D156: =IF(DashBoard!E156<>0,DashBoard!E156,"")
B157: =IF(DashBoard!E157<>0,DashBoard!A157,"") | C157: =IF(DashBoard!E157<>0,DashBoard!B157,"") | D157: =IF(DashBoard!E157<>0,DashBoard!E157,"")
B158: =IF(DashBoard!E158<>0,DashBoard!A158,"") | C158: =IF(DashBoard!E158<>0,DashBoard!B158,"") | D158: =IF(DashBoard!E158<>0,DashBoard!E158,"")
B159: =IF(DashBoard!E159<>0,DashBoard!A159,"") | C159: =IF(DashBoard!E159<>0,DashBoard!B159,"") | D159: =IF(DashBoard!E159<>0,DashBoard!E159,"")
B160: =IF(DashBoard!E160<>0,DashBoard!A160,"") | C160: =IF(DashBoard!E160<>0,DashBoard!B160,"") | D160: =IF(DashBoard!E160<>0,DashBoard!E160,"")
B161: =IF(DashBoard!E161<>0,DashBoard!A161,"") | C161: =IF(DashBoard!E161<>0,DashBoard!B161,"") | D161: =IF(DashBoard!E161<>0,DashBoard!E161,"")
B162: =IF(DashBoard!E162<>0,DashBoard!A162,"") | C162: =IF(DashBoard!E162<>0,DashBoard!B162,"") | D162: =IF(DashBoard!E162<>0,DashBoard!E162,"")
... B165: =IF(DashBoard!E165<>0,DashBoard!A165,"") | C165: =IF(DashBoard!E165<>0,DashBoard!B165,"") | D165: =IF(DashBoard!E165<>0,DashBoard!E165,"")
B166: =IF(DashBoard!#REF!<>0,DashBoard!#REF!,"") -> #REF! | C166: =IF(DashBoard!#REF!<>0,DashBoard!#REF!,"") -> #REF! | D166: =IF(DashBoard!#REF!<>0,DashBoard!#REF!,"") -> #REF!
B167: =IF(DashBoard!#REF!<>0,DashBoard!#REF!,"") -> #REF! | C167: =IF(DashBoard!#REF!<>0,DashBoard!#REF!,"") -> #REF! | D167: =IF(DashBoard!#REF!<>0,DashBoard!#REF!,"") -> #REF!
B168: =IF(DashBoard!#REF!<>0,DashBoard!#REF!,"") -> #REF! | C168: =IF(DashBoard!#REF!<>0,DashBoard!#REF!,"") -> #REF! | D168: =IF(DashBoard!#REF!<>0,DashBoard!#REF!,"") -> #REF!
B169: =IF(DashBoard!#REF!<>0,DashBoard!#REF!,"") -> #REF! | C169: =IF(DashBoard!#REF!<>0,DashBoard!#REF!,"") -> #REF! | D169: =IF(DashBoard!#REF!<>0,DashBoard!#REF!,"") -> #REF!
B170: =IF(DashBoard!#REF!<>0,DashBoard!#REF!,"") -> #REF! | C170: =IF(DashBoard!#REF!<>0,DashBoard!#REF!,"") -> #REF! | D170: =IF(DashBoard!#REF!<>0,DashBoard!#REF!,"") -> #REF!
B171: =IF(DashBoard!#REF!<>0,DashBoard!#REF!,"") -> #REF! | C171: =IF(DashBoard!#REF!<>0,DashBoard!#REF!,"") -> #REF! | D171: =IF(DashBoard!#REF!<>0,DashBoard!#REF!,"") -> #REF!
B172: =IF(DashBoard!#REF!<>0,DashBoard!#REF!,"") -> #REF! | C172: =IF(DashBoard!#REF!<>0,DashBoard!#REF!,"") -> #REF! | D172: =IF(DashBoard!#REF!<>0,DashBoard!#REF!,"") -> #REF!
B173: =IF(DashBoard!#REF!<>0,DashBoard!#REF!,"") -> #REF! | C173: =IF(DashBoard!#REF!<>0,DashBoard!#REF!,"") -> #REF! | D173: =IF(DashBoard!#REF!<>0,DashBoard!#REF!,"") -> #REF!
B174: =IF(DashBoard!#REF!<>0,DashBoard!#REF!,"") -> #REF! | C174: =IF(DashBoard!#REF!<>0,DashBoard!#REF!,"") -> #REF! | D174: =IF(DashBoard!#REF!<>0,DashBoard!#REF!,"") -> #REF!
B175: =IF(DashBoard!#REF!<>0,DashBoard!#REF!,"") -> #REF! | C175: =IF(DashBoard!#REF!<>0,DashBoard!#REF!,"") -> #REF! | D175: =IF(DashBoard!#REF!<>0,DashBoard!#REF!,"") -> #REF!
B176: =IF(DashBoard!#REF!<>0,DashBoard!#REF!,"") -> #REF! | C176: =IF(DashBoard!#REF!<>0,DashBoard!#REF!,"") -> #REF! | D176: =IF(DashBoard!#REF!<>0,DashBoard!#REF!,"") -> #REF!
B177: =IF(DashBoard!#REF!<>0,DashBoard!#REF!,"") -> #REF! | C177: =IF(DashBoard!#REF!<>0,DashBoard!#REF!,"") -> #REF! | D177: =IF(DashBoard!#REF!<>0,DashBoard!#REF!,"") -> #REF!
... B248: =IF(DashBoard!#REF!<>0,DashBoard!#REF!,"") -> #REF! | C248: =IF(DashBoard!#REF!<>0,DashBoard!#REF!,"") -> #REF! | D248: =IF(DashBoard!#REF!<>0,DashBoard!#REF!,"") -> #REF!
...

Sheet Glendale
A1: =IF(B1<>"","1","") -> 1 | B1: From 01 to 06 | C1: Glendale | D1: ST6
A2: =IF(B2<>"","1","") | B2: =IF(DashBoard!F2<>0,DashBoard!A2,"") | C2: =IF(DashBoard!F2<>0,DashBoard!B2,"") | D2: =IF(DashBoard!F2<>0,DashBoard!F2,"")
A3: =IF(B3<>"","1","") | B3: =IF(DashBoard!F3<>0,DashBoard!A3,"") | C3: =IF(DashBoard!F3<>0,DashBoard!B3,"") | D3: =IF(DashBoard!F3<>0,DashBoard!F3,"")
A4: =IF(B4<>"","1","") | B4: =IF(DashBoard!F4<>0,DashBoard!A4,"") | C4: =IF(DashBoard!F4<>0,DashBoard!B4,"") | D4: =IF(DashBoard!F4<>0,DashBoard!F4,"")
A5: =IF(B5<>"","1","") -> 1 | B5: =IF(DashBoard!F5<>0,DashBoard!A5,"") -> BRTA3 | C5: =IF(DashBoard!F5<>0,DashBoard!B5,"") -> 3" THROWAWAY BRUSH | D5: =IF(DashBoard!F5<>0,DashBoard!F5,"") -> 11
A6: =IF(B6<>"","1","") | B6: =IF(DashBoard!F6<>0,DashBoard!A6,"") | C6: =IF(DashBoard!F6<>0,DashBoard!B6,"") | D6: =IF(DashBoard!F6<>0,DashBoard!F6,"")
A7: =IF(B7<>"","1","") | B7: =IF(DashBoard!F7<>0,DashBoard!A7,"") | C7: =IF(DashBoard!F7<>0,DashBoard!B7,"") | D7: =IF(DashBoard!F7<>0,DashBoard!F7,"")
A8: =IF(B8<>"","1","") | B8: =IF(DashBoard!F8<>0,DashBoard!A8,"") | C8: =IF(DashBoard!F8<>0,DashBoard!B8,"") | D8: =IF(DashBoard!F8<>0,DashBoard!F8,"")
A9: =IF(B9<>"","1","") | B9: =IF(DashBoard!F9<>0,DashBoard!A9,"") | C9: =IF(DashBoard!F9<>0,DashBoard!B9,"") | D9: =IF(DashBoard!F9<>0,DashBoard!F9,"")
A10: =IF(B10<>"","1","") | B10: =IF(DashBoard!F10<>0,DashBoard!A10,"") | C10: =IF(DashBoard!F10<>0,DashBoard!B10,"") | D10: =IF(DashBoard!F10<>0,DashBoard!F10,"")
A11: =IF(B11<>"","1","") | B11: =IF(DashBoard!F11<>0,DashBoard!A11,"") | C11: =IF(DashBoard!F11<>0,DashBoard!B11,"") | D11: =IF(DashBoard!F11<>0,DashBoard!F11,"")
A12: =IF(B12<>"","1","") | B12: =IF(DashBoard!F12<>0,DashBoard!A12,"") | C12: =IF(DashBoard!F12<>0,DashBoard!B12,"") | D12: =IF(DashBoard!F12<>0,DashBoard!F12,"")
A13: =IF(B13<>"","1","") | B13: =IF(DashBoard!F13<>0,DashBoard!A13,"") | C13: =IF(DashBoard!F13<>0,DashBoard!B13,"") | D13: =IF(DashBoard!F13<>0,DashBoard!F13,"")
... A150: =IF(B150<>"","1","") | B150: =IF(DashBoard!F150<>0,DashBoard!A150,"") | C150: =IF(DashBoard!F150<>0,DashBoard!B150,"") | D150: =IF(DashBoard!F150<>0,DashBoard!F150,"")
B151: =IF(DashBoard!F151<>0,DashBoard!A151,"") | C151: =IF(DashBoard!F151<>0,DashBoard!B151,"") | D151: =IF(DashBoard!F151<>0,DashBoard!F151,"")
B152: =IF(DashBoard!F152<>0,DashBoard!A152,"") | C152: =IF(DashBoard!F152<>0,DashBoard!B152,"") | D152: =IF(DashBoard!F152<>0,DashBoard!F152,"")
B153: =IF(DashBoard!F153<>0,DashBoard!A153,"") | C153: =IF(DashBoard!F153<>0,DashBoard!B153,"") | D153: =IF(DashBoard!F153<>0,DashBoard!F153,"")
B154: =IF(DashBoard!F154<>0,DashBoard!A154,"") | C154: =IF(DashBoard!F154<>0,DashBoard!B154,"") | D154: =IF(DashBoard!F154<>0,DashBoard!F154,"")
B155: =IF(DashBoard!F155<>0,DashBoard!A155,"") | C155: =IF(DashBoard!F155<>0,DashBoard!B155,"") | D155: =IF(DashBoard!F155<>0,DashBoard!F155,"")
B156: =IF(DashBoard!F156<>0,DashBoard!A156,"") | C156: =IF(DashBoard!F156<>0,DashBoard!B156,"") | D156: =IF(DashBoard!F156<>0,DashBoard!F156,"")
B157: =IF(DashBoard!F157<>0,DashBoard!A157,"") | C157: =IF(DashBoard!F157<>0,DashBoard!B157,"") | D157: =IF(DashBoard!F157<>0,DashBoard!F157,"")
B158: =IF(DashBoard!F158<>0,DashBoard!A158,"") | C158: =IF(DashBoard!F158<>0,DashBoard!B158,"") | D158: =IF(DashBoard!F158<>0,DashBoard!F158,"")
B159: =IF(DashBoard!F159<>0,DashBoard!A159,"") | C159: =IF(DashBoard!F159<>0,DashBoard!B159,"") | D159: =IF(DashBoard!F159<>0,DashBoard!F159,"")
B160: =IF(DashBoard!F160<>0,DashBoard!A160,"") | C160: =IF(DashBoard!F160<>0,DashBoard!B160,"") | D160: =IF(DashBoard!F160<>0,DashBoard!F160,"")
B161: =IF(DashBoard!F161<>0,DashBoard!A161,"") | C161: =IF(DashBoard!F161<>0,DashBoard!B161,"") | D161: =IF(DashBoard!F161<>0,DashBoard!F161,"")
B162: =IF(DashBoard!F162<>0,DashBoard!A162,"") | C162: =IF(DashBoard!F162<>0,DashBoard!B162,"") | D162: =IF(DashBoard!F162<>0,DashBoard!F162,"")
... B165: =IF(DashBoard!F165<>0,DashBoard!A165,"") | C165: =IF(DashBoard!F165<>0,DashBoard!B165,"") | D165: =IF(DashBoard!F165<>0,DashBoard!F165,"")
B166: =IF(DashBoard!#REF!<>0,DashBoard!#REF!,"") -> #REF! | C166: =IF(DashBoard!#REF!<>0,DashBoard!#REF!,"") -> #REF! | D166: =IF(DashBoard!#REF!<>0,DashBoard!#REF!,"") -> #REF!
B167: =IF(DashBoard!#REF!<>0,DashBoard!#REF!,"") -> #REF! | C167: =IF(DashBoard!#REF!<>0,DashBoard!#REF!,"") -> #REF! | D167: =IF(DashBoard!#REF!<>0,DashBoard!#REF!,"") -> #REF!
B168: =IF(DashBoard!#REF!<>0,DashBoard!#REF!,"") -> #REF! | C168: =IF(DashBoard!#REF!<>0,DashBoard!#REF!,"") -> #REF! | D168: =IF(DashBoard!#REF!<>0,DashBoard!#REF!,"") -> #REF!
B169: =IF(DashBoard!#REF!<>0,DashBoard!#REF!,"") -> #REF! | C169: =IF(DashBoard!#REF!<>0,DashBoard!#REF!,"") -> #REF! | D169: =IF(DashBoard!#REF!<>0,DashBoard!#REF!,"") -> #REF!
B170: =IF(DashBoard!#REF!<>0,DashBoard!#REF!,"") -> #REF! | C170: =IF(DashBoard!#REF!<>0,DashBoard!#REF!,"") -> #REF! | D170: =IF(DashBoard!#REF!<>0,DashBoard!#REF!,"") -> #REF!
B171: =IF(DashBoard!#REF!<>0,DashBoard!#REF!,"") -> #REF! | C171: =IF(DashBoard!#REF!<>0,DashBoard!#REF!,"") -> #REF! | D171: =IF(DashBoard!#REF!<>0,DashBoard!#REF!,"") -> #REF!
B172: =IF(DashBoard!#REF!<>0,DashBoard!#REF!,"") -> #REF! | C172: =IF(DashBoard!#REF!<>0,DashBoard!#REF!,"") -> #REF! | D172: =IF(DashBoard!#REF!<>0,DashBoard!#REF!,"") -> #REF!
B173: =IF(DashBoard!#REF!<>0,DashBoard!#REF!,"") -> #REF! | C173: =IF(DashBoard!#REF!<>0,DashBoard!#REF!,"") -> #REF! | D173: =IF(DashBoard!#REF!<>0,DashBoard!#REF!,"") -> #REF!
B174: =IF(DashBoard!#REF!<>0,DashBoard!#REF!,"") -> #REF! | C174: =IF(DashBoard!#REF!<>0,DashBoard!#REF!,"") -> #REF! | D174: =IF(DashBoard!#REF!<>0,DashBoard!#REF!,"") -> #REF!
B175: =IF(DashBoard!#REF!<>0,DashBoard!#REF!,"") -> #REF! | C175: =IF(DashBoard!#REF!<>0,DashBoard!#REF!,"") -> #REF! | D175: =IF(DashBoard!#REF!<>0,DashBoard!#REF!,"") -> #REF!
B176: =IF(DashBoard!#REF!<>0,DashBoard!#REF!,"") -> #REF! | C176: =IF(DashBoard!#REF!<>0,DashBoard!#REF!,"") -> #REF! | D176: =IF(DashBoard!#REF!<>0,DashBoard!#REF!,"") -> #REF!
B177: =IF(DashBoard!#REF!<>0,DashBoard!#REF!,"") -> #REF! | C177: =IF(DashBoard!#REF!<>0,DashBoard!#REF!,"") -> #REF! | D177: =IF(DashBoard!#REF!<>0,DashBoard!#REF!,"") -> #REF!
... B245: =IF(DashBoard!#REF!<>0,DashBoard!#REF!,"") -> #REF! | C245: =IF(DashBoard!#REF!<>0,DashBoard!#REF!,"") -> #REF! | D245: =IF(DashBoard!#REF!<>0,DashBoard!#REF!,"") -> #REF!

Sheet Vernon
A1: =IF(B1<>"","1","") -> 1 | B1: From 01 to 08 | C1: Vernon | D1: ST8
A2: =IF(B2<>"","1","") | B2: =IF(DashBoard!G2<>0,DashBoard!A2,"") | C2: =IF(DashBoard!G2<>0,DashBoard!B2,"") | D2: =IF(DashBoard!G2<>0,DashBoard!G2,"")
A3: =IF(B3<>"","1","") | B3: =IF(DashBoard!G3<>0,DashBoard!A3,"") | C3: =IF(DashBoard!G3<>0,DashBoard!B3,"") | D3: =IF(DashBoard!G3<>0,DashBoard!G3,"")
A4: =IF(B4<>"","1","") | B4: =IF(DashBoard!G4<>0,DashBoard!A4,"") | C4: =IF(DashBoard!G4<>0,DashBoard!B4,"") | D4: =IF(DashBoard!G4<>0,DashBoard!G4,"")
A5: =IF(B5<>"","1","") | B5: =IF(DashBoard!G5<>0,DashBoard!A5,"") | C5: =IF(DashBoard!G5<>0,DashBoard!B5,"") | D5: =IF(DashBoard!G5<>0,DashBoard!G5,"")
A6: =IF(B6<>"","1","") | B6: =IF(DashBoard!G6<>0,DashBoard!A6,"") | C6: =IF(DashBoard!G6<>0,DashBoard!B6,"") | D6: =IF(DashBoard!G6<>0,DashBoard!G6,"")
A7: =IF(B7<>"","1","") | B7: =IF(DashBoard!G7<>0,DashBoard!A7,"") | C7: =IF(DashBoard!G7<>0,DashBoard!B7,"") | D7: =IF(DashBoard!G7<>0,DashBoard!G7,"")
A8: =IF(B8<>"","1","") | B8: =IF(DashBoard!G8<>0,DashBoard!A8,"") | C8: =IF(DashBoard!G8<>0,DashBoard!B8,"") | D8: =IF(DashBoard!G8<>0,DashBoard!G8,"")
A9: =IF(B9<>"","1","") | B9: =IF(DashBoard!G9<>0,DashBoard!A9,"") | C9: =IF(DashBoard!G9<>0,DashBoard!B9,"") | D9: =IF(DashBoard!G9<>0,DashBoard!G9,"")
A10: =IF(B10<>"","1","") | B10: =IF(DashBoard!G10<>0,DashBoard!A10,"") | C10: =IF(DashBoard!G10<>0,DashBoard!B10,"") | D10: =IF(DashBoard!G10<>0,DashBoard!G10,"")
A11: =IF(B11<>"","1","") | B11: =IF(DashBoard!G11<>0,DashBoard!A11,"") | C11: =IF(DashBoard!G11<>0,DashBoard!B11,"") | D11: =IF(DashBoard!G11<>0,DashBoard!G11,"")
A12: =IF(B12<>"","1","") | B12: =IF(DashBoard!G12<>0,DashBoard!A12,"") | C12: =IF(DashBoard!G12<>0,DashBoard!B12,"") | D12: =IF(DashBoard!G12<>0,DashBoard!G12,"")
A13: =IF(B13<>"","1","") | B13: =IF(DashBoard!G13<>0,DashBoard!A13,"") | C13: =IF(DashBoard!G13<>0,DashBoard!B13,"") | D13: =IF(DashBoard!G13<>0,DashBoard!G13,"")
... A165: =IF(B165<>"","1","") | B165: =IF(DashBoard!G165<>0,DashBoard!A165,"") | C165: =IF(DashBoard!G165<>0,DashBoard!B165,"") | D165: =IF(DashBoard!G165<>0,DashBoard!G165,"")
A166: =IF(B166<>"","1","") -> #REF! | B166: =IF(DashBoard!#REF!<>0,DashBoard!#REF!,"") -> #REF! | C166: =IF(DashBoard!#REF!<>0,DashBoard!#REF!,"") -> #REF! | D166: =IF(DashBoard!#REF!<>0,DashBoard!#REF!,"") -> #REF!
A167: =IF(B167<>"","1","") -> #REF! | B167: =IF(DashBoard!#REF!<>0,DashBoard!#REF!,"") -> #REF! | C167: =IF(DashBoard!#REF!<>0,DashBoard!#REF!,"") -> #REF! | D167: =IF(DashBoard!#REF!<>0,DashBoard!#REF!,"") -> #REF!
A168: =IF(B168<>"","1","") -> #REF! | B168: =IF(DashBoard!#REF!<>0,DashBoard!#REF!,"") -> #REF! | C168: =IF(DashBoard!#REF!<>0,DashBoard!#REF!,"") -> #REF! | D168: =IF(DashBoard!#REF!<>0,DashBoard!#REF!,"") -> #REF!
A169: =IF(B169<>"","1","") -> #REF! | B169: =IF(DashBoard!#REF!<>0,DashBoard!#REF!,"") -> #REF! | C169: =IF(DashBoard!#REF!<>0,DashBoard!#REF!,"") -> #REF! | D169: =IF(DashBoard!#REF!<>0,DashBoard!#REF!,"") -> #REF!
A170: =IF(B170<>"","1","") -> #REF! | B170: =IF(DashBoard!#REF!<>0,DashBoard!#REF!,"") -> #REF! | C170: =IF(DashBoard!#REF!<>0,DashBoard!#REF!,"") -> #REF! | D170: =IF(DashBoard!#REF!<>0,DashBoard!#REF!,"") -> #REF!
A171: =IF(B171<>"","1","") -> #REF! | B171: =IF(DashBoard!#REF!<>0,DashBoard!#REF!,"") -> #REF! | C171: =IF(DashBoard!#REF!<>0,DashBoard!#REF!,"") -> #REF! | D171: =IF(DashBoard!#REF!<>0,DashBoard!#REF!,"") -> #REF!
A172: =IF(B172<>"","1","") -> #REF! | B172: =IF(DashBoard!#REF!<>0,DashBoard!#REF!,"") -> #REF! | C172: =IF(DashBoard!#REF!<>0,DashBoard!#REF!,"") -> #REF! | D172: =IF(DashBoard!#REF!<>0,DashBoard!#REF!,"") -> #REF!
A173: =IF(B173<>"","1","") -> #REF! | B173: =IF(DashBoard!#REF!<>0,DashBoard!#REF!,"") -> #REF! | C173: =IF(DashBoard!#REF!<>0,DashBoard!#REF!,"") -> #REF! | D173: =IF(DashBoard!#REF!<>0,DashBoard!#REF!,"") -> #REF!
A174: =IF(B174<>"","1","") -> #REF! | B174: =IF(DashBoard!#REF!<>0,DashBoard!#REF!,"") -> #REF! | C174: =IF(DashBoard!#REF!<>0,DashBoard!#REF!,"") -> #REF! | D174: =IF(DashBoard!#REF!<>0,DashBoard!#REF!,"") -> #REF!
A175: =IF(B175<>"","1","") -> #REF! | B175: =IF(DashBoard!#REF!<>0,DashBoard!#REF!,"") -> #REF! | C175: =IF(DashBoard!#REF!<>0,DashBoard!#REF!,"") -> #REF! | D175: =IF(DashBoard!#REF!<>0,DashBoard!#REF!,"") -> #REF!
A176: =IF(B176<>"","1","") -> #REF! | B176: =IF(DashBoard!#REF!<>0,DashBoard!#REF!,"") -> #REF! | C176: =IF(DashBoard!#REF!<>0,DashBoard!#REF!,"") -> #REF! | D176: =IF(DashBoard!#REF!<>0,DashBoard!#REF!,"") -> #REF!
A177: =IF(B177<>"","1","") -> #REF! | B177: =IF(DashBoard!#REF!<>0,DashBoard!#REF!,"") -> #REF! | C177: =IF(DashBoard!#REF!<>0,DashBoard!#REF!,"") -> #REF! | D177: =IF(DashBoard!#REF!<>0,DashBoard!#REF!,"") -> #REF!
... A248: =IF(B248<>"","1","") -> #REF! | B248: =IF(DashBoard!#REF!<>0,DashBoard!#REF!,"") -> #REF! | C248: =IF(DashBoard!#REF!<>0,DashBoard!#REF!,"") -> #REF! | D248: =IF(DashBoard!#REF!<>0,DashBoard!#REF!,"") -> #REF!
A249: =IF(B249<>"","1","") | B249: =IF(DashBoard!G166<>0,DashBoard!A166,"") | C249: =IF(DashBoard!G166<>0,DashBoard!B166,"") | D249: =IF(DashBoard!G166<>0,DashBoard!G166,"")
A250: =IF(B250<>"","1","") | B250: =IF(DashBoard!G167<>0,DashBoard!A167,"") | C250: =IF(DashBoard!G167<>0,DashBoard!B167,"") | D250: =IF(DashBoard!G167<>0,DashBoard!G167,"")
A251: =IF(B251<>"","1","") | B251: =IF(DashBoard!G168<>0,DashBoard!A168,"") | C251: =IF(DashBoard!G168<>0,DashBoard!B168,"") | D251: =IF(DashBoard!G168<>0,DashBoard!G168,"")
A252: =IF(B252<>"","1","") | B252: =IF(DashBoard!G169<>0,DashBoard!A169,"") | C252: =IF(DashBoard!G169<>0,DashBoard!B169,"") | D252: =IF(DashBoard!G169<>0,DashBoard!G169,"")
A253: =IF(B253<>"","1","") | B253: =IF(DashBoard!G170<>0,DashBoard!A170,"") | C253: =IF(DashBoard!G170<>0,DashBoard!B170,"") | D253: =IF(DashBoard!G170<>0,DashBoard!G170,"")
A254: =IF(B254<>"","1","") | B254: =IF(DashBoard!G171<>0,DashBoard!A171,"") | C254: =IF(DashBoard!G171<>0,DashBoard!B171,"") | D254: =IF(DashBoard!G171<>0,DashBoard!G171,"")
A255: =IF(B255<>"","1","") | B255: =IF(DashBoard!G172<>0,DashBoard!A172,"") | C255: =IF(DashBoard!G172<>0,DashBoard!B172,"") | D255: =IF(DashBoard!G172<>0,DashBoard!G172,"")
A256: =IF(B256<>"","1","") | B256: =IF(DashBoard!G173<>0,DashBoard!A173,"") | C256: =IF(DashBoard!G173<>0,DashBoard!B173,"") | D256: =IF(DashBoard!G173<>0,DashBoard!G173,"")
A257: =IF(B257<>"","1","") | B257: =IF(DashBoard!G174<>0,DashBoard!A174,"") | C257: =IF(DashBoard!G174<>0,DashBoard!B174,"") | D257: =IF(DashBoard!G174<>0,DashBoard!G174,"")
A258: =IF(B258<>"","1","") | B258: =IF(DashBoard!G175<>0,DashBoard!A175,"") | C258: =IF(DashBoard!G175<>0,DashBoard!B175,"") | D258: =IF(DashBoard!G175<>0,DashBoard!G175,"")
A259: =IF(B259<>"","1","") | B259: =IF(DashBoard!G176<>0,DashBoard!A176,"") | C259: =IF(DashBoard!G176<>0,DashBoard!B176,"") | D259: =IF(DashBoard!G176<>0,DashBoard!G176,"")
A260: =IF(B260<>"","1","") | B260: =IF(DashBoard!G177<>0,DashBoard!A177,"") | C260: =IF(DashBoard!G177<>0,DashBoard!B177,"") | D260: =IF(DashBoard!G177<>0,DashBoard!G177,"")
... A274: =IF(B274<>"","1","") | B274: =IF(DashBoard!G191<>0,DashBoard!A191,"") | C274: =IF(DashBoard!G191<>0,DashBoard!B191,"") | D274: =IF(DashBoard!G191<>0,DashBoard!G191,"")

Sheet Sta Ana
A1: =IF(B1<>"","1","") -> 1 | B1: From 01 to 09 | C1: Santa Ana | D1: ST9
A2: =IF(B2<>"","1","") | B2: =IF(DashBoard!H2<>0,DashBoard!A2,"") | C2: =IF(DashBoard!H2<>0,DashBoard!B2,"") | D2: =IF(DashBoard!H2<>0,DashBoard!H2,"")
A3: =IF(B3<>"","1","") -> 1 | B3: =IF(DashBoard!H3<>0,DashBoard!A3,"") -> BRFB2 | C3: =IF(DashBoard!H3<>0,DashBoard!B3,"") -> 2" FOAM BRUSH | D3: =IF(DashBoard!H3<>0,DashBoard!H3,"") -> 1
A4: =IF(B4<>"","1","") | B4: =IF(DashBoard!H4<>0,DashBoard!A4,"") | C4: =IF(DashBoard!H4<>0,DashBoard!B4,"") | D4: =IF(DashBoard!H4<>0,DashBoard!H4,"")
A5: =IF(B5<>"","1","") | B5: =IF(DashBoard!H5<>0,DashBoard!A5,"") | C5: =IF(DashBoard!H5<>0,DashBoard!B5,"") | D5: =IF(DashBoard!H5<>0,DashBoard!H5,"")
A6: =IF(B6<>"","1","") | B6: =IF(DashBoard!H6<>0,DashBoard!A6,"") | C6: =IF(DashBoard!H6<>0,DashBoard!B6,"") | D6: =IF(DashBoard!H6<>0,DashBoard!H6,"")
A7: =IF(B7<>"","1","") | B7: =IF(DashBoard!H7<>0,DashBoard!A7,"") | C7: =IF(DashBoard!H7<>0,DashBoard!B7,"") | D7: =IF(DashBoard!H7<>0,DashBoard!H7,"")
A8: =IF(B8<>"","1","") | B8: =IF(DashBoard!H8<>0,DashBoard!A8,"") | C8: =IF(DashBoard!H8<>0,DashBoard!B8,"") | D8: =IF(DashBoard!H8<>0,DashBoard!H8,"")
A9: =IF(B9<>"","1","") | B9: =IF(DashBoard!H9<>0,DashBoard!A9,"") | C9: =IF(DashBoard!H9<>0,DashBoard!B9,"") | D9: =IF(DashBoard!H9<>0,DashBoard!H9,"")
A10: =IF(B10<>"","1","") | B10: =IF(DashBoard!H10<>0,DashBoard!A10,"") | C10: =IF(DashBoard!H10<>0,DashBoard!B10,"") | D10: =IF(DashBoard!H10<>0,DashBoard!H10,"")
A11: =IF(B11<>"","1","") | B11: =IF(DashBoard!H11<>0,DashBoard!A11,"") | C11: =IF(DashBoard!H11<>0,DashBoard!B11,"") | D11: =IF(DashBoard!H11<>0,DashBoard!H11,"")
A12: =IF(B12<>"","1","") | B12: =IF(DashBoard!H12<>0,DashBoard!A12,"") | C12: =IF(DashBoard!H12<>0,DashBoard!B12,"") | D12: =IF(DashBoard!H12<>0,DashBoard!H12,"")
A13: =IF(B13<>"","1","") | B13: =IF(DashBoard!H13<>0,DashBoard!A13,"") | C13: =IF(DashBoard!H13<>0,DashBoard!B13,"") | D13: =IF(DashBoard!H13<>0,DashBoard!H13,"")
... A165: =IF(B165<>"","1","") | B165: =IF(DashBoard!H165<>0,DashBoard!A165,"") | C165: =IF(DashBoard!H165<>0,DashBoard!B165,"") | D165: =IF(DashBoard!H165<>0,DashBoard!H165,"")
A166: =IF(B166<>"","1","") -> #REF! | B166: =IF(DashBoard!#REF!<>0,DashBoard!#REF!,"") -> #REF! | C166: =IF(DashBoard!#REF!<>0,DashBoard!#REF!,"") -> #REF! | D166: =IF(DashBoard!#REF!<>0,DashBoard!#REF!,"") -> #REF!
A167: =IF(B167<>"","1","") -> #REF! | B167: =IF(DashBoard!#REF!<>0,DashBoard!#REF!,"") -> #REF! | C167: =IF(DashBoard!#REF!<>0,DashBoard!#REF!,"") -> #REF! | D167: =IF(DashBoard!#REF!<>0,DashBoard!#REF!,"") -> #REF!
A168: =IF(B168<>"","1","") -> #REF! | B168: =IF(DashBoard!#REF!<>0,DashBoard!#REF!,"") -> #REF! | C168: =IF(DashBoard!#REF!<>0,DashBoard!#REF!,"") -> #REF! | D168: =IF(DashBoard!#REF!<>0,DashBoard!#REF!,"") -> #REF!
A169: =IF(B169<>"","1","") -> #REF! | B169: =IF(DashBoard!#REF!<>0,DashBoard!#REF!,"") -> #REF! | C169: =IF(DashBoard!#REF!<>0,DashBoard!#REF!,"") -> #REF! | D169: =IF(DashBoard!#REF!<>0,DashBoard!#REF!,"") -> #REF!
A170: =IF(B170<>"","1","") -> #REF! | B170: =IF(DashBoard!#REF!<>0,DashBoard!#REF!,"") -> #REF! | C170: =IF(DashBoard!#REF!<>0,DashBoard!#REF!,"") -> #REF! | D170: =IF(DashBoard!#REF!<>0,DashBoard!#REF!,"") -> #REF!
A171: =IF(B171<>"","1","") -> #REF! | B171: =IF(DashBoard!#REF!<>0,DashBoard!#REF!,"") -> #REF! | C171: =IF(DashBoard!#REF!<>0,DashBoard!#REF!,"") -> #REF! | D171: =IF(DashBoard!#REF!<>0,DashBoard!#REF!,"") -> #REF!
A172: =IF(B172<>"","1","") -> #REF! | B172: =IF(DashBoard!#REF!<>0,DashBoard!#REF!,"") -> #REF! | C172: =IF(DashBoard!#REF!<>0,DashBoard!#REF!,"") -> #REF! | D172: =IF(DashBoard!#REF!<>0,DashBoard!#REF!,"") -> #REF!
A173: =IF(B173<>"","1","") -> #REF! | B173: =IF(DashBoard!#REF!<>0,DashBoard!#REF!,"") -> #REF! | C173: =IF(DashBoard!#REF!<>0,DashBoard!#REF!,"") -> #REF! | D173: =IF(DashBoard!#REF!<>0,DashBoard!#REF!,"") -> #REF!
A174: =IF(B174<>"","1","") -> #REF! | B174: =IF(DashBoard!#REF!<>0,DashBoard!#REF!,"") -> #REF! | C174: =IF(DashBoard!#REF!<>0,DashBoard!#REF!,"") -> #REF! | D174: =IF(DashBoard!#REF!<>0,DashBoard!#REF!,"") -> #REF!
A175: =IF(B175<>"","1","") -> #REF! | B175: =IF(DashBoard!#REF!<>0,DashBoard!#REF!,"") -> #REF! | C175: =IF(DashBoard!#REF!<>0,DashBoard!#REF!,"") -> #REF! | D175: =IF(DashBoard!#REF!<>0,DashBoard!#REF!,"") -> #REF!
A176: =IF(B176<>"","1","") -> #REF! | B176: =IF(DashBoard!#REF!<>0,DashBoard!#REF!,"") -> #REF! | C176: =IF(DashBoard!#REF!<>0,DashBoard!#REF!,"") -> #REF! | D176: =IF(DashBoard!#REF!<>0,DashBoard!#REF!,"") -> #REF!
A177: =IF(B177<>"","1","") -> #REF! | B177: =IF(DashBoard!#REF!<>0,DashBoard!#REF!,"") -> #REF! | C177: =IF(DashBoard!#REF!<>0,DashBoard!#REF!,"") -> #REF! | D177: =IF(DashBoard!#REF!<>0,DashBoard!#REF!,"") -> #REF!
... A248: =IF(B248<>"","1","") -> #REF! | B248: =IF(DashBoard!#REF!<>0,DashBoard!#REF!,"") -> #REF! | C248: =IF(DashBoard!#REF!<>0,DashBoard!#REF!,"") -> #REF! | D248: =IF(DashBoard!#REF!<>0,DashBoard!#REF!,"") -> #REF!
A249: =IF(B249<>"","1","") | B249: =IF(DashBoard!H166<>0,DashBoard!A166,"") | C249: =IF(DashBoard!H166<>0,DashBoard!B166,"") | D249: =IF(DashBoard!H166<>0,DashBoard!H166,"")
A250: =IF(B250<>"","1","") | B250: =IF(DashBoard!H167<>0,DashBoard!A167,"") | C250: =IF(DashBoard!H167<>0,DashBoard!B167,"") | D250: =IF(DashBoard!H167<>0,DashBoard!H167,"")
A251: =IF(B251<>"","1","") | B251: =IF(DashBoard!H168<>0,DashBoard!A168,"") | C251: =IF(DashBoard!H168<>0,DashBoard!B168,"") | D251: =IF(DashBoard!H168<>0,DashBoard!H168,"")
A252: =IF(B252<>"","1","") | B252: =IF(DashBoard!H169<>0,DashBoard!A169,"") | C252: =IF(DashBoard!H169<>0,DashBoard!B169,"") | D252: =IF(DashBoard!H169<>0,DashBoard!H169,"")
A253: =IF(B253<>"","1","") | B253: =IF(DashBoard!H170<>0,DashBoard!A170,"") | C253: =IF(DashBoard!H170<>0,DashBoard!B170,"") | D253: =IF(DashBoard!H170<>0,DashBoard!H170,"")
A254: =IF(B254<>"","1","") | B254: =IF(DashBoard!H171<>0,DashBoard!A171,"") | C254: =IF(DashBoard!H171<>0,DashBoard!B171,"") | D254: =IF(DashBoard!H171<>0,DashBoard!H171,"")
A255: =IF(B255<>"","1","") | B255: =IF(DashBoard!H172<>0,DashBoard!A172,"") | C255: =IF(DashBoard!H172<>0,DashBoard!B172,"") | D255: =IF(DashBoard!H172<>0,DashBoard!H172,"")
A256: =IF(B256<>"","1","") | B256: =IF(DashBoard!H173<>0,DashBoard!A173,"") | C256: =IF(DashBoard!H173<>0,DashBoard!B173,"") | D256: =IF(DashBoard!H173<>0,DashBoard!H173,"")
A257: =IF(B257<>"","1","") | B257: =IF(DashBoard!H174<>0,DashBoard!A174,"") | C257: =IF(DashBoard!H174<>0,DashBoard!B174,"") | D257: =IF(DashBoard!H174<>0,DashBoard!H174,"")
A258: =IF(B258<>"","1","") | B258: =IF(DashBoard!H175<>0,DashBoard!A175,"") | C258: =IF(DashBoard!H175<>0,DashBoard!B175,"") | D258: =IF(DashBoard!H175<>0,DashBoard!H175,"")
A259: =IF(B259<>"","1","") | B259: =IF(DashBoard!H176<>0,DashBoard!A176,"") | C259: =IF(DashBoard!H176<>0,DashBoard!B176,"") | D259: =IF(DashBoard!H176<>0,DashBoard!H176,"")
A260: =IF(B260<>"","1","") | B260: =IF(DashBoard!H177<>0,DashBoard!A177,"") | C260: =IF(DashBoard!H177<>0,DashBoard!B177,"") | D260: =IF(DashBoard!H177<>0,DashBoard!H177,"")
... A285: =IF(B285<>"","1","") | B285: =IF(DashBoard!H202<>0,DashBoard!A202,"") | C285: =IF(DashBoard!H202<>0,DashBoard!B202,"") | D285: =IF(DashBoard!H202<>0,DashBoard!H202,"")

Sheet Sumary 
A1: Factor | B1: Column1 | C1: Column2 | D1: Column3
A2: =Robertson!A1 -> 1 | B2: =Robertson!B1 -> From 01 to 03 | C2: =Robertson!C1 -> Roberson | D2: =Robertson!D1 -> ST3
A3: =Robertson!A2 | B3: =Robertson!B2 | C3: =Robertson!C2 | D3: =Robertson!D2
A4: =Robertson!A3 | B4: =Robertson!B3 | C4: =Robertson!C3 | D4: =Robertson!D3
A5: =Robertson!A4 -> 1 | B5: =Robertson!B4 -> BRTA2 | C5: =Robertson!C4 -> 2" THROWAWAY BRUSH | D5: =Robertson!D4 -> 3
A6: =Robertson!A5 | B6: =Robertson!B5 | C6: =Robertson!C5 | D6: =Robertson!D5
A7: =Robertson!A6 -> 1 | B7: =Robertson!B6 -> BRTA4 | C7: =Robertson!C6 -> 4" THROWAWAY BRUSH | D7: =Robertson!D6 -> 11
A8: =Robertson!A7 | B8: =Robertson!B7 | C8: =Robertson!C7 | D8: =Robertson!D7
A9: =Robertson!A8 -> 1 | B9: =Robertson!B8 -> WPCA20096M | C9: =Robertson!C8 -> 6' WOOD POLE METAL TIP | D9: =Robertson!D8 -> 2
A10: =Robertson!A9 | B10: =Robertson!B9 | C10: =Robertson!C9 | D10: =Robertson!D9
A11: =Robertson!A10 | B11: =Robertson!B10 | C11: =Robertson!C10 | D11: =Robertson!D10
A12: =Robertson!A11 | B12: =Robertson!B11 | C12: =Robertson!C11 | D12: =Robertson!D11
A13: =Robertson!A12 | B13: =Robertson!B12 | C13: =Robertson!C12 | D13: =Robertson!D12
... A149: =Robertson!A148 | B149: =Robertson!B148 | C149: =Robertson!C148 | D149: =Robertson!D148
A150: =Gardena!A1 -> 1 | B150: =Gardena!B1 -> From 01 to 04 | C150: =Gardena!C1 -> Gardena | D150: =Gardena!D1 -> ST4
A151: =Gardena!A2 | B151: =Gardena!B2 | C151: =Gardena!C2 | D151: =Gardena!D2
A152: =Gardena!A3 | B152: =Gardena!B3 | C152: =Gardena!C3 | D152: =Gardena!D3
A153: =Gardena!A4 | B153: =Gardena!B4 | C153: =Gardena!C4 | D153: =Gardena!D4
A154: =Gardena!A5 | B154: =Gardena!B5 | C154: =Gardena!C5 | D154: =Gardena!D5
A155: =Gardena!A6 | B155: =Gardena!B6 | C155: =Gardena!C6 | D155: =Gardena!D6
A156: =Gardena!A7 | B156: =Gardena!B7 | C156: =Gardena!C7 | D156: =Gardena!D7
A157: =Gardena!A8 | B157: =Gardena!B8 | C157: =Gardena!C8 | D157: =Gardena!D8
A158: =Gardena!A9 -> 1 | B158: =Gardena!B9 -> FIWT63281 | C158: =Gardena!C9 -> WATCO SPRAY CLEAR SATIN | D158: =Gardena!D9 -> 4
A159: =Gardena!A10 | B159: =Gardena!B10 | C159: =Gardena!C10 | D159: =Gardena!D10
A160: =Gardena!A11 | B160: =Gardena!B11 | C160: =Gardena!C11 | D160: =Gardena!D11
A161: =Gardena!A12 | B161: =Gardena!B12 | C161: =Gardena!C12 | D161: =Gardena!D12
... A300: =Gardena!A151 -> 0 | B300: =Gardena!B151 | C300: =Gardena!C151 | D300: =Gardena!D151
A301: ='San Diego'!A1 -> 1 | B301: ='San Diego'!B1 -> From 01 to 05 | C301: ='San Diego'!C1 -> San Diego | D301: ='San Diego'!D1 -> ST5
A302: ='San Diego'!A2 -> 1 | B302: ='San Diego'!B2 -> ADDO091488 | C302: ='San Diego'!C2 -> DAP ALEX PLUS CAULK W/SILICONE | D302: ='San Diego'!D2 -> 7
A303: ='San Diego'!A3 | B303: ='San Diego'!B3 | C303: ='San Diego'!C3 | D303: ='San Diego'!D3
A304: ='San Diego'!A4 | B304: ='San Diego'!B4 | C304: ='San Diego'!C4 | D304: ='San Diego'!D4
A305: ='San Diego'!A5 | B305: ='San Diego'!B5 | C305: ='San Diego'!C5 | D305: ='San Diego'!D5
A306: ='San Diego'!A6 | B306: ='San Diego'!B6 | C306: ='San Diego'!C6 | D306: ='San Diego'!D6
A307: ='San Diego'!A7 -> 1 | B307: ='San Diego'!B7 -> DAPCG537043 | C307: ='San Diego'!C7 -> DAP CAULKING GUN SKELETON 9" | D307: ='San Diego'!D7 -> 1
A308: ='San Diego'!A8 | B308: ='San Diego'!B8 | C308: ='San Diego'!C8 | D308: ='San Diego'!D8
A309: ='San Diego'!A9 | B309: ='San Diego'!B9 | C309: ='San Diego'!C9 | D309: ='San Diego'!D9
A310: ='San Diego'!A10 -> 1 | B310: ='San Diego'!B10 -> ARPU350769 | C310: ='San Diego'!C10 -> PURDY 9" WHITE DOVE 3/8" NAP | D310: ='San Diego'!D10 -> 5
A311: ='San Diego'!A11 | B311: ='San Diego'!B11 | C311: ='San Diego'!C11 | D311: ='San Diego'!D11
A312: ='San Diego'!A12 | B312: ='San Diego'!B12 | C312: ='San Diego'!C12 | D312: ='San Diego'!D12
... A450: ='San Diego'!A150 | B450: ='San Diego'!B150 | C450: ='San Diego'!C150 | D450: ='San Diego'!D150
...

Sheet x2
A1: ITEM | B1: IMDESC | C1: IMVEND | D1: LOC | E1: ONHAND | F1: AVAILABLE | G1: ONPO | H1: EMU | I1: Need to Send
A2: ADDO091488 | B2: DAP ALEX PLUS CAULK W/SILICONE | C2: 1204 | D2: 5 | E2: 82 | F2: 82 | G2: 0 | H2: 29.666667 | I2: 7
A3: BRFB2 | B3: 2" FOAM BRUSH | C3: 1204 | D3: 9 | E3: 11 | F3: 10 | G3: 0 | H3: 3.6666667 | I3: 1
A4: BRTA2 | B4: 2" THROWAWAY BRUSH | C4: 1204 | D4: 3 | E4: 23 | F4: 23 | G4: 0 | H4: 8.5 | I4: 3
A5: BRTA3 | B5: 3" THROWAWAY BRUSH | C5: 1204 | D5: 6 | E5: 19 | F5: 19 | G5: 0 | H5: 10 | I5: 11
A6: BRTA4 | B6: 4" THROWAWAY BRUSH | C6: 1204 | D6: 3 | E6: 21 | F6: 21 | G6: 0 | H6: 10.5 | I6: 11
A7: DAPCG537043 | B7: DAP CAULKING GUN SKELETON 9" | C7: 1204 | D7: 5 | E7: 3 | F7: 3 | G7: 0 | H7: 1.3333333 | I7: 1
A8: WPCA20096M | B8: 6' WOOD POLE METAL TIP | C8: 1204 | D8: 3 | E8: 3 | F8: 3 | G8: 0 | H8: 1.5 | I8: 2
A9: FIWT63281 | B9: WATCO SPRAY CLEAR SATIN | C9: 1204 | D9: 4 | E9: 1 | F9: 1 | G9: 0 | H9: 1.6666667 | I9: 4
A10: ARPU350769 | B10: PURDY 9" WHITE DOVE 3/8" NAP | C10: 1204 | D10: 5 | E10: 43 | F10: 43 | G10: 0 | H10: 15.833333 | I10: 5
